hostname sb006.cluster
ipconfig 1: lo: <LOOPBACK,UP,LOWER_UP> mtu 65536 qdisc noqueue state UNKNOWN group default qlen 1000 link/loopback 00:00:00:00:00:00 brd 00:00:00:00:00:00 inet 127.0.0.1/8 scope host lo valid_lft forever preferred_lft forever inet6 ::1/128 scope host valid_lft forever preferred_lft forever 2: enp4s0f0: <BROADCAST,MULTICAST,UP,LOWER_UP> mtu 9000 qdisc mq state UP group default qlen 1000 link/ether a0:8c:f8:61:07:9a brd ff:ff:ff:ff:ff:ff inet 10.3.81.86/22 brd 10.3.83.255 scope global enp4s0f0 valid_lft forever preferred_lft forever inet6 fe80::a28c:f8ff:fe61:79a/64 scope link valid_lft forever preferred_lft forever 3: enp4s0f1: <BROADCAST,MULTICAST> mtu 1500 qdisc noop state DOWN group default qlen 1000 link/ether a0:8c:f8:61:07:9b brd ff:ff:ff:ff:ff:ff 4: enp4s0f2: <BROADCAST,MULTICAST> mtu 1500 qdisc noop state DOWN group default qlen 1000 link/ether a0:8c:f8:61:07:9c brd ff:ff:ff:ff:ff:ff 5: enp4s0f3: <BROADCAST,MULTICAST> mtu 1500 qdisc noop state DOWN group default qlen 1000 link/ether a0:8c:f8:61:07:9d brd ff:ff:ff:ff:ff:ff 6: ib0: <BROADCAST,MULTICAST,UP,LOWER_UP> mtu 4092 qdisc pfifo_fast state UP group default qlen 256 link/infiniband 80:00:00:29:fe:80:00:00:00:00:00:00:88:66:39:03:00:23:be:91 brd 00:ff:ff:ff:ff:12:40:1b:ff:ff:00:00:00:00:00:00:ff:ff:ff:ff inet 10.3.89.86/22 brd 10.3.91.255 scope global ib0 valid_lft forever preferred_lft forever inet 10.3.97.86/22 brd 10.3.99.255 scope global ib0:1 valid_lft forever preferred_lft forever inet6 fe80::8a66:3903:23:be91/64 scope link valid_lft forever preferred_lft forever 7: ib1: <BROADCAST,MULTICAST> mtu 4092 qdisc noop state DOWN group default qlen 256 link/infiniband 80:00:00:29:fe:80:00:00:00:00:00:00:88:66:39:03:00:23:be:92 brd 00:ff:ff:ff:ff:12:40:1b:ff:ff:00:00:00:00:00:00:ff:ff:ff:ff
2024-01-16 11:48:21,241 - distributed.nanny - INFO -         Start Nanny at: 'tcp://10.3.89.86:36540'
2024-01-16 11:48:21,408 - distributed.nanny - INFO -         Start Nanny at: 'tcp://10.3.89.86:34396'
2024-01-16 11:49:30,469 - distributed.worker - INFO -       Start worker at:     tcp://10.3.89.86:32834
2024-01-16 11:49:30,469 - distributed.worker - INFO -       Start worker at:     tcp://10.3.89.86:34222
2024-01-16 11:49:30,471 - distributed.worker - INFO -          Listening to:     tcp://10.3.89.86:32834
2024-01-16 11:49:30,471 - distributed.worker - INFO -          Listening to:     tcp://10.3.89.86:34222
2024-01-16 11:49:30,471 - distributed.worker - INFO -           Worker name:          SLURMCluster-85-0
2024-01-16 11:49:30,471 - distributed.worker - INFO -           Worker name:          SLURMCluster-85-1
2024-01-16 11:49:30,471 - distributed.worker - INFO -          dashboard at:           10.3.89.86:41272
2024-01-16 11:49:30,471 - distributed.worker - INFO -          dashboard at:           10.3.89.86:35980
2024-01-16 11:49:30,471 - distributed.worker - INFO - Waiting to connect to:     tcp://10.3.88.12:37277
2024-01-16 11:49:30,471 - distributed.worker - INFO - Waiting to connect to:     tcp://10.3.88.12:37277
2024-01-16 11:49:30,471 - distributed.worker - INFO - -------------------------------------------------
2024-01-16 11:49:30,471 - distributed.worker - INFO - -------------------------------------------------
2024-01-16 11:49:30,471 - distributed.worker - INFO -               Threads:                          2
2024-01-16 11:49:30,471 - distributed.worker - INFO -               Threads:                          2
2024-01-16 11:49:30,471 - distributed.worker - INFO -                Memory:                  10.24 GiB
2024-01-16 11:49:30,471 - distributed.worker - INFO -                Memory:                  10.24 GiB
2024-01-16 11:49:30,472 - distributed.worker - INFO -       Local Directory: /scratch/dask-worker-space/worker-rolo1z71
2024-01-16 11:49:30,472 - distributed.worker - INFO -       Local Directory: /scratch/dask-worker-space/worker-xoj7f9v0
2024-01-16 11:49:30,472 - distributed.worker - INFO - -------------------------------------------------
2024-01-16 11:49:30,472 - distributed.worker - INFO - -------------------------------------------------
2024-01-16 11:49:30,785 - distributed.worker - INFO -         Registered to:     tcp://10.3.88.12:37277
2024-01-16 11:49:30,785 - distributed.worker - INFO - -------------------------------------------------
2024-01-16 11:49:30,786 - distributed.core - INFO - Starting established connection to tcp://10.3.88.12:37277
2024-01-16 11:49:30,797 - distributed.worker - INFO -         Registered to:     tcp://10.3.88.12:37277
2024-01-16 11:49:30,798 - distributed.worker - INFO - -------------------------------------------------
2024-01-16 11:49:30,798 - distributed.core - INFO - Starting established connection to tcp://10.3.88.12:37277
2024-01-16 11:50:12,409 - distributed.worker - ERROR - Worker stream died during communication: tcp://10.3.89.122:39675
Traceback (most recent call last):
  File "/mnt/storage/nobackup/nmb1063/mamba/envs/fegrow/lib/python3.9/site-packages/distributed/comm/tcp.py", line 225, in read
    frames_nbytes = await stream.read_bytes(fmt_size)
asyncio.exceptions.CancelledError

During handling of the above exception, another exception occurred:

Traceback (most recent call last):
  File "/mnt/storage/nobackup/nmb1063/mamba/envs/fegrow/lib/python3.9/asyncio/tasks.py", line 490, in wait_for
    return fut.result()
asyncio.exceptions.CancelledError

The above exception was the direct cause of the following exception:

Traceback (most recent call last):
  File "/mnt/storage/nobackup/nmb1063/mamba/envs/fegrow/lib/python3.9/site-packages/distributed/comm/core.py", line 328, in connect
    handshake = await asyncio.wait_for(comm.read(), time_left())
  File "/mnt/storage/nobackup/nmb1063/mamba/envs/fegrow/lib/python3.9/asyncio/tasks.py", line 492, in wait_for
    raise exceptions.TimeoutError() from exc
asyncio.exceptions.TimeoutError

The above exception was the direct cause of the following exception:

Traceback (most recent call last):
  File "/mnt/storage/nobackup/nmb1063/mamba/envs/fegrow/lib/python3.9/site-packages/distributed/worker.py", line 2081, in gather_dep
    response = await get_data_from_worker(
  File "/mnt/storage/nobackup/nmb1063/mamba/envs/fegrow/lib/python3.9/site-packages/distributed/worker.py", line 2900, in get_data_from_worker
    comm = await rpc.connect(worker)
  File "/mnt/storage/nobackup/nmb1063/mamba/envs/fegrow/lib/python3.9/site-packages/distributed/core.py", line 1468, in connect
    return await connect_attempt
  File "/mnt/storage/nobackup/nmb1063/mamba/envs/fegrow/lib/python3.9/site-packages/distributed/core.py", line 1389, in _connect
    comm = await connect(
  File "/mnt/storage/nobackup/nmb1063/mamba/envs/fegrow/lib/python3.9/site-packages/distributed/comm/core.py", line 333, in connect
    raise OSError(
OSError: Timed out during handshake while connecting to tcp://10.3.89.122:39675 after 30 s
2024-01-16 11:50:12,409 - distributed.worker - ERROR - Worker stream died during communication: tcp://10.3.89.122:39675
Traceback (most recent call last):
  File "/mnt/storage/nobackup/nmb1063/mamba/envs/fegrow/lib/python3.9/site-packages/distributed/comm/tcp.py", line 225, in read
    frames_nbytes = await stream.read_bytes(fmt_size)
asyncio.exceptions.CancelledError

During handling of the above exception, another exception occurred:

Traceback (most recent call last):
  File "/mnt/storage/nobackup/nmb1063/mamba/envs/fegrow/lib/python3.9/asyncio/tasks.py", line 490, in wait_for
    return fut.result()
asyncio.exceptions.CancelledError

The above exception was the direct cause of the following exception:

Traceback (most recent call last):
  File "/mnt/storage/nobackup/nmb1063/mamba/envs/fegrow/lib/python3.9/site-packages/distributed/comm/core.py", line 328, in connect
    handshake = await asyncio.wait_for(comm.read(), time_left())
  File "/mnt/storage/nobackup/nmb1063/mamba/envs/fegrow/lib/python3.9/asyncio/tasks.py", line 492, in wait_for
    raise exceptions.TimeoutError() from exc
asyncio.exceptions.TimeoutError

The above exception was the direct cause of the following exception:

Traceback (most recent call last):
  File "/mnt/storage/nobackup/nmb1063/mamba/envs/fegrow/lib/python3.9/site-packages/distributed/worker.py", line 2081, in gather_dep
    response = await get_data_from_worker(
  File "/mnt/storage/nobackup/nmb1063/mamba/envs/fegrow/lib/python3.9/site-packages/distributed/worker.py", line 2900, in get_data_from_worker
    comm = await rpc.connect(worker)
  File "/mnt/storage/nobackup/nmb1063/mamba/envs/fegrow/lib/python3.9/site-packages/distributed/core.py", line 1468, in connect
    return await connect_attempt
  File "/mnt/storage/nobackup/nmb1063/mamba/envs/fegrow/lib/python3.9/site-packages/distributed/core.py", line 1389, in _connect
    comm = await connect(
  File "/mnt/storage/nobackup/nmb1063/mamba/envs/fegrow/lib/python3.9/site-packages/distributed/comm/core.py", line 333, in connect
    raise OSError(
OSError: Timed out during handshake while connecting to tcp://10.3.89.122:39675 after 30 s
2024-01-16 11:50:42,791 - distributed.worker - ERROR - Worker stream died during communication: tcp://10.3.89.122:39675
Traceback (most recent call last):
  File "/mnt/storage/nobackup/nmb1063/mamba/envs/fegrow/lib/python3.9/site-packages/distributed/comm/tcp.py", line 225, in read
    frames_nbytes = await stream.read_bytes(fmt_size)
asyncio.exceptions.CancelledError

During handling of the above exception, another exception occurred:

Traceback (most recent call last):
  File "/mnt/storage/nobackup/nmb1063/mamba/envs/fegrow/lib/python3.9/asyncio/tasks.py", line 490, in wait_for
    return fut.result()
asyncio.exceptions.CancelledError

The above exception was the direct cause of the following exception:

Traceback (most recent call last):
  File "/mnt/storage/nobackup/nmb1063/mamba/envs/fegrow/lib/python3.9/site-packages/distributed/comm/core.py", line 328, in connect
    handshake = await asyncio.wait_for(comm.read(), time_left())
  File "/mnt/storage/nobackup/nmb1063/mamba/envs/fegrow/lib/python3.9/asyncio/tasks.py", line 492, in wait_for
    raise exceptions.TimeoutError() from exc
asyncio.exceptions.TimeoutError

The above exception was the direct cause of the following exception:

Traceback (most recent call last):
  File "/mnt/storage/nobackup/nmb1063/mamba/envs/fegrow/lib/python3.9/site-packages/distributed/worker.py", line 2081, in gather_dep
    response = await get_data_from_worker(
  File "/mnt/storage/nobackup/nmb1063/mamba/envs/fegrow/lib/python3.9/site-packages/distributed/worker.py", line 2900, in get_data_from_worker
    comm = await rpc.connect(worker)
  File "/mnt/storage/nobackup/nmb1063/mamba/envs/fegrow/lib/python3.9/site-packages/distributed/core.py", line 1468, in connect
    return await connect_attempt
  File "/mnt/storage/nobackup/nmb1063/mamba/envs/fegrow/lib/python3.9/site-packages/distributed/core.py", line 1389, in _connect
    comm = await connect(
  File "/mnt/storage/nobackup/nmb1063/mamba/envs/fegrow/lib/python3.9/site-packages/distributed/comm/core.py", line 333, in connect
    raise OSError(
OSError: Timed out during handshake while connecting to tcp://10.3.89.122:39675 after 30 s
2024-01-16 11:50:42,805 - distributed.worker - ERROR - Worker stream died during communication: tcp://10.3.89.122:39675
Traceback (most recent call last):
  File "/mnt/storage/nobackup/nmb1063/mamba/envs/fegrow/lib/python3.9/site-packages/distributed/comm/tcp.py", line 225, in read
    frames_nbytes = await stream.read_bytes(fmt_size)
asyncio.exceptions.CancelledError

During handling of the above exception, another exception occurred:

Traceback (most recent call last):
  File "/mnt/storage/nobackup/nmb1063/mamba/envs/fegrow/lib/python3.9/asyncio/tasks.py", line 490, in wait_for
    return fut.result()
asyncio.exceptions.CancelledError

The above exception was the direct cause of the following exception:

Traceback (most recent call last):
  File "/mnt/storage/nobackup/nmb1063/mamba/envs/fegrow/lib/python3.9/site-packages/distributed/comm/core.py", line 328, in connect
    handshake = await asyncio.wait_for(comm.read(), time_left())
  File "/mnt/storage/nobackup/nmb1063/mamba/envs/fegrow/lib/python3.9/asyncio/tasks.py", line 492, in wait_for
    raise exceptions.TimeoutError() from exc
asyncio.exceptions.TimeoutError

The above exception was the direct cause of the following exception:

Traceback (most recent call last):
  File "/mnt/storage/nobackup/nmb1063/mamba/envs/fegrow/lib/python3.9/site-packages/distributed/worker.py", line 2081, in gather_dep
    response = await get_data_from_worker(
  File "/mnt/storage/nobackup/nmb1063/mamba/envs/fegrow/lib/python3.9/site-packages/distributed/worker.py", line 2900, in get_data_from_worker
    comm = await rpc.connect(worker)
  File "/mnt/storage/nobackup/nmb1063/mamba/envs/fegrow/lib/python3.9/site-packages/distributed/core.py", line 1468, in connect
    return await connect_attempt
  File "/mnt/storage/nobackup/nmb1063/mamba/envs/fegrow/lib/python3.9/site-packages/distributed/core.py", line 1389, in _connect
    comm = await connect(
  File "/mnt/storage/nobackup/nmb1063/mamba/envs/fegrow/lib/python3.9/site-packages/distributed/comm/core.py", line 333, in connect
    raise OSError(
OSError: Timed out during handshake while connecting to tcp://10.3.89.122:39675 after 30 s
2024-01-16 11:51:13,791 - distributed.worker - ERROR - Worker stream died during communication: tcp://10.3.89.122:39675
Traceback (most recent call last):
  File "/mnt/storage/nobackup/nmb1063/mamba/envs/fegrow/lib/python3.9/site-packages/distributed/comm/tcp.py", line 225, in read
    frames_nbytes = await stream.read_bytes(fmt_size)
asyncio.exceptions.CancelledError

During handling of the above exception, another exception occurred:

Traceback (most recent call last):
  File "/mnt/storage/nobackup/nmb1063/mamba/envs/fegrow/lib/python3.9/asyncio/tasks.py", line 490, in wait_for
    return fut.result()
asyncio.exceptions.CancelledError

The above exception was the direct cause of the following exception:

Traceback (most recent call last):
  File "/mnt/storage/nobackup/nmb1063/mamba/envs/fegrow/lib/python3.9/site-packages/distributed/comm/core.py", line 328, in connect
    handshake = await asyncio.wait_for(comm.read(), time_left())
  File "/mnt/storage/nobackup/nmb1063/mamba/envs/fegrow/lib/python3.9/asyncio/tasks.py", line 492, in wait_for
    raise exceptions.TimeoutError() from exc
asyncio.exceptions.TimeoutError

The above exception was the direct cause of the following exception:

Traceback (most recent call last):
  File "/mnt/storage/nobackup/nmb1063/mamba/envs/fegrow/lib/python3.9/site-packages/distributed/worker.py", line 2081, in gather_dep
    response = await get_data_from_worker(
  File "/mnt/storage/nobackup/nmb1063/mamba/envs/fegrow/lib/python3.9/site-packages/distributed/worker.py", line 2900, in get_data_from_worker
    comm = await rpc.connect(worker)
  File "/mnt/storage/nobackup/nmb1063/mamba/envs/fegrow/lib/python3.9/site-packages/distributed/core.py", line 1468, in connect
    return await connect_attempt
  File "/mnt/storage/nobackup/nmb1063/mamba/envs/fegrow/lib/python3.9/site-packages/distributed/core.py", line 1389, in _connect
    comm = await connect(
  File "/mnt/storage/nobackup/nmb1063/mamba/envs/fegrow/lib/python3.9/site-packages/distributed/comm/core.py", line 333, in connect
    raise OSError(
OSError: Timed out during handshake while connecting to tcp://10.3.89.122:39675 after 30 s
2024-01-16 11:51:13,804 - distributed.worker - ERROR - Worker stream died during communication: tcp://10.3.89.122:39675
Traceback (most recent call last):
  File "/mnt/storage/nobackup/nmb1063/mamba/envs/fegrow/lib/python3.9/site-packages/distributed/comm/tcp.py", line 225, in read
    frames_nbytes = await stream.read_bytes(fmt_size)
asyncio.exceptions.CancelledError

During handling of the above exception, another exception occurred:

Traceback (most recent call last):
  File "/mnt/storage/nobackup/nmb1063/mamba/envs/fegrow/lib/python3.9/asyncio/tasks.py", line 490, in wait_for
    return fut.result()
asyncio.exceptions.CancelledError

The above exception was the direct cause of the following exception:

Traceback (most recent call last):
  File "/mnt/storage/nobackup/nmb1063/mamba/envs/fegrow/lib/python3.9/site-packages/distributed/comm/core.py", line 328, in connect
    handshake = await asyncio.wait_for(comm.read(), time_left())
  File "/mnt/storage/nobackup/nmb1063/mamba/envs/fegrow/lib/python3.9/asyncio/tasks.py", line 492, in wait_for
    raise exceptions.TimeoutError() from exc
asyncio.exceptions.TimeoutError

The above exception was the direct cause of the following exception:

Traceback (most recent call last):
  File "/mnt/storage/nobackup/nmb1063/mamba/envs/fegrow/lib/python3.9/site-packages/distributed/worker.py", line 2081, in gather_dep
    response = await get_data_from_worker(
  File "/mnt/storage/nobackup/nmb1063/mamba/envs/fegrow/lib/python3.9/site-packages/distributed/worker.py", line 2900, in get_data_from_worker
    comm = await rpc.connect(worker)
  File "/mnt/storage/nobackup/nmb1063/mamba/envs/fegrow/lib/python3.9/site-packages/distributed/core.py", line 1468, in connect
    return await connect_attempt
  File "/mnt/storage/nobackup/nmb1063/mamba/envs/fegrow/lib/python3.9/site-packages/distributed/core.py", line 1389, in _connect
    comm = await connect(
  File "/mnt/storage/nobackup/nmb1063/mamba/envs/fegrow/lib/python3.9/site-packages/distributed/comm/core.py", line 333, in connect
    raise OSError(
OSError: Timed out during handshake while connecting to tcp://10.3.89.122:39675 after 30 s
2024-01-16 11:51:44,792 - distributed.worker - ERROR - Worker stream died during communication: tcp://10.3.89.122:39675
Traceback (most recent call last):
  File "/mnt/storage/nobackup/nmb1063/mamba/envs/fegrow/lib/python3.9/site-packages/distributed/comm/tcp.py", line 225, in read
    frames_nbytes = await stream.read_bytes(fmt_size)
asyncio.exceptions.CancelledError

During handling of the above exception, another exception occurred:

Traceback (most recent call last):
  File "/mnt/storage/nobackup/nmb1063/mamba/envs/fegrow/lib/python3.9/asyncio/tasks.py", line 490, in wait_for
    return fut.result()
asyncio.exceptions.CancelledError

The above exception was the direct cause of the following exception:

Traceback (most recent call last):
  File "/mnt/storage/nobackup/nmb1063/mamba/envs/fegrow/lib/python3.9/site-packages/distributed/comm/core.py", line 328, in connect
    handshake = await asyncio.wait_for(comm.read(), time_left())
  File "/mnt/storage/nobackup/nmb1063/mamba/envs/fegrow/lib/python3.9/asyncio/tasks.py", line 492, in wait_for
    raise exceptions.TimeoutError() from exc
asyncio.exceptions.TimeoutError

The above exception was the direct cause of the following exception:

Traceback (most recent call last):
  File "/mnt/storage/nobackup/nmb1063/mamba/envs/fegrow/lib/python3.9/site-packages/distributed/worker.py", line 2081, in gather_dep
    response = await get_data_from_worker(
  File "/mnt/storage/nobackup/nmb1063/mamba/envs/fegrow/lib/python3.9/site-packages/distributed/worker.py", line 2900, in get_data_from_worker
    comm = await rpc.connect(worker)
  File "/mnt/storage/nobackup/nmb1063/mamba/envs/fegrow/lib/python3.9/site-packages/distributed/core.py", line 1468, in connect
    return await connect_attempt
  File "/mnt/storage/nobackup/nmb1063/mamba/envs/fegrow/lib/python3.9/site-packages/distributed/core.py", line 1389, in _connect
    comm = await connect(
  File "/mnt/storage/nobackup/nmb1063/mamba/envs/fegrow/lib/python3.9/site-packages/distributed/comm/core.py", line 333, in connect
    raise OSError(
OSError: Timed out during handshake while connecting to tcp://10.3.89.122:39675 after 30 s
2024-01-16 11:51:44,805 - distributed.worker - ERROR - Worker stream died during communication: tcp://10.3.89.122:39675
Traceback (most recent call last):
  File "/mnt/storage/nobackup/nmb1063/mamba/envs/fegrow/lib/python3.9/site-packages/distributed/comm/tcp.py", line 225, in read
    frames_nbytes = await stream.read_bytes(fmt_size)
asyncio.exceptions.CancelledError

During handling of the above exception, another exception occurred:

Traceback (most recent call last):
  File "/mnt/storage/nobackup/nmb1063/mamba/envs/fegrow/lib/python3.9/asyncio/tasks.py", line 490, in wait_for
    return fut.result()
asyncio.exceptions.CancelledError

The above exception was the direct cause of the following exception:

Traceback (most recent call last):
  File "/mnt/storage/nobackup/nmb1063/mamba/envs/fegrow/lib/python3.9/site-packages/distributed/comm/core.py", line 328, in connect
    handshake = await asyncio.wait_for(comm.read(), time_left())
  File "/mnt/storage/nobackup/nmb1063/mamba/envs/fegrow/lib/python3.9/asyncio/tasks.py", line 492, in wait_for
    raise exceptions.TimeoutError() from exc
asyncio.exceptions.TimeoutError

The above exception was the direct cause of the following exception:

Traceback (most recent call last):
  File "/mnt/storage/nobackup/nmb1063/mamba/envs/fegrow/lib/python3.9/site-packages/distributed/worker.py", line 2081, in gather_dep
    response = await get_data_from_worker(
  File "/mnt/storage/nobackup/nmb1063/mamba/envs/fegrow/lib/python3.9/site-packages/distributed/worker.py", line 2900, in get_data_from_worker
    comm = await rpc.connect(worker)
  File "/mnt/storage/nobackup/nmb1063/mamba/envs/fegrow/lib/python3.9/site-packages/distributed/core.py", line 1468, in connect
    return await connect_attempt
  File "/mnt/storage/nobackup/nmb1063/mamba/envs/fegrow/lib/python3.9/site-packages/distributed/core.py", line 1389, in _connect
    comm = await connect(
  File "/mnt/storage/nobackup/nmb1063/mamba/envs/fegrow/lib/python3.9/site-packages/distributed/comm/core.py", line 333, in connect
    raise OSError(
OSError: Timed out during handshake while connecting to tcp://10.3.89.122:39675 after 30 s
2024-01-16 11:52:15,792 - distributed.worker - ERROR - Worker stream died during communication: tcp://10.3.89.122:39675
Traceback (most recent call last):
  File "/mnt/storage/nobackup/nmb1063/mamba/envs/fegrow/lib/python3.9/site-packages/distributed/comm/tcp.py", line 225, in read
    frames_nbytes = await stream.read_bytes(fmt_size)
asyncio.exceptions.CancelledError

During handling of the above exception, another exception occurred:

Traceback (most recent call last):
  File "/mnt/storage/nobackup/nmb1063/mamba/envs/fegrow/lib/python3.9/asyncio/tasks.py", line 490, in wait_for
    return fut.result()
asyncio.exceptions.CancelledError

The above exception was the direct cause of the following exception:

Traceback (most recent call last):
  File "/mnt/storage/nobackup/nmb1063/mamba/envs/fegrow/lib/python3.9/site-packages/distributed/comm/core.py", line 328, in connect
    handshake = await asyncio.wait_for(comm.read(), time_left())
  File "/mnt/storage/nobackup/nmb1063/mamba/envs/fegrow/lib/python3.9/asyncio/tasks.py", line 492, in wait_for
    raise exceptions.TimeoutError() from exc
asyncio.exceptions.TimeoutError

The above exception was the direct cause of the following exception:

Traceback (most recent call last):
  File "/mnt/storage/nobackup/nmb1063/mamba/envs/fegrow/lib/python3.9/site-packages/distributed/worker.py", line 2081, in gather_dep
    response = await get_data_from_worker(
  File "/mnt/storage/nobackup/nmb1063/mamba/envs/fegrow/lib/python3.9/site-packages/distributed/worker.py", line 2900, in get_data_from_worker
    comm = await rpc.connect(worker)
  File "/mnt/storage/nobackup/nmb1063/mamba/envs/fegrow/lib/python3.9/site-packages/distributed/core.py", line 1468, in connect
    return await connect_attempt
  File "/mnt/storage/nobackup/nmb1063/mamba/envs/fegrow/lib/python3.9/site-packages/distributed/core.py", line 1389, in _connect
    comm = await connect(
  File "/mnt/storage/nobackup/nmb1063/mamba/envs/fegrow/lib/python3.9/site-packages/distributed/comm/core.py", line 333, in connect
    raise OSError(
OSError: Timed out during handshake while connecting to tcp://10.3.89.122:39675 after 30 s
2024-01-16 11:52:15,806 - distributed.worker - ERROR - Worker stream died during communication: tcp://10.3.89.122:39675
Traceback (most recent call last):
  File "/mnt/storage/nobackup/nmb1063/mamba/envs/fegrow/lib/python3.9/site-packages/distributed/comm/tcp.py", line 225, in read
    frames_nbytes = await stream.read_bytes(fmt_size)
asyncio.exceptions.CancelledError

During handling of the above exception, another exception occurred:

Traceback (most recent call last):
  File "/mnt/storage/nobackup/nmb1063/mamba/envs/fegrow/lib/python3.9/asyncio/tasks.py", line 490, in wait_for
    return fut.result()
asyncio.exceptions.CancelledError

The above exception was the direct cause of the following exception:

Traceback (most recent call last):
  File "/mnt/storage/nobackup/nmb1063/mamba/envs/fegrow/lib/python3.9/site-packages/distributed/comm/core.py", line 328, in connect
    handshake = await asyncio.wait_for(comm.read(), time_left())
  File "/mnt/storage/nobackup/nmb1063/mamba/envs/fegrow/lib/python3.9/asyncio/tasks.py", line 492, in wait_for
    raise exceptions.TimeoutError() from exc
asyncio.exceptions.TimeoutError

The above exception was the direct cause of the following exception:

Traceback (most recent call last):
  File "/mnt/storage/nobackup/nmb1063/mamba/envs/fegrow/lib/python3.9/site-packages/distributed/worker.py", line 2081, in gather_dep
    response = await get_data_from_worker(
  File "/mnt/storage/nobackup/nmb1063/mamba/envs/fegrow/lib/python3.9/site-packages/distributed/worker.py", line 2900, in get_data_from_worker
    comm = await rpc.connect(worker)
  File "/mnt/storage/nobackup/nmb1063/mamba/envs/fegrow/lib/python3.9/site-packages/distributed/core.py", line 1468, in connect
    return await connect_attempt
  File "/mnt/storage/nobackup/nmb1063/mamba/envs/fegrow/lib/python3.9/site-packages/distributed/core.py", line 1389, in _connect
    comm = await connect(
  File "/mnt/storage/nobackup/nmb1063/mamba/envs/fegrow/lib/python3.9/site-packages/distributed/comm/core.py", line 333, in connect
    raise OSError(
OSError: Timed out during handshake while connecting to tcp://10.3.89.122:39675 after 30 s
2024-01-16 11:52:46,793 - distributed.worker - ERROR - Worker stream died during communication: tcp://10.3.89.122:39675
Traceback (most recent call last):
  File "/mnt/storage/nobackup/nmb1063/mamba/envs/fegrow/lib/python3.9/site-packages/distributed/comm/tcp.py", line 225, in read
    frames_nbytes = await stream.read_bytes(fmt_size)
asyncio.exceptions.CancelledError

During handling of the above exception, another exception occurred:

Traceback (most recent call last):
  File "/mnt/storage/nobackup/nmb1063/mamba/envs/fegrow/lib/python3.9/asyncio/tasks.py", line 490, in wait_for
    return fut.result()
asyncio.exceptions.CancelledError

The above exception was the direct cause of the following exception:

Traceback (most recent call last):
  File "/mnt/storage/nobackup/nmb1063/mamba/envs/fegrow/lib/python3.9/site-packages/distributed/comm/core.py", line 328, in connect
    handshake = await asyncio.wait_for(comm.read(), time_left())
  File "/mnt/storage/nobackup/nmb1063/mamba/envs/fegrow/lib/python3.9/asyncio/tasks.py", line 492, in wait_for
    raise exceptions.TimeoutError() from exc
asyncio.exceptions.TimeoutError

The above exception was the direct cause of the following exception:

Traceback (most recent call last):
  File "/mnt/storage/nobackup/nmb1063/mamba/envs/fegrow/lib/python3.9/site-packages/distributed/worker.py", line 2081, in gather_dep
    response = await get_data_from_worker(
  File "/mnt/storage/nobackup/nmb1063/mamba/envs/fegrow/lib/python3.9/site-packages/distributed/worker.py", line 2900, in get_data_from_worker
    comm = await rpc.connect(worker)
  File "/mnt/storage/nobackup/nmb1063/mamba/envs/fegrow/lib/python3.9/site-packages/distributed/core.py", line 1468, in connect
    return await connect_attempt
  File "/mnt/storage/nobackup/nmb1063/mamba/envs/fegrow/lib/python3.9/site-packages/distributed/core.py", line 1389, in _connect
    comm = await connect(
  File "/mnt/storage/nobackup/nmb1063/mamba/envs/fegrow/lib/python3.9/site-packages/distributed/comm/core.py", line 333, in connect
    raise OSError(
OSError: Timed out during handshake while connecting to tcp://10.3.89.122:39675 after 30 s
2024-01-16 11:52:46,805 - distributed.worker - ERROR - Worker stream died during communication: tcp://10.3.89.122:39675
Traceback (most recent call last):
  File "/mnt/storage/nobackup/nmb1063/mamba/envs/fegrow/lib/python3.9/site-packages/distributed/comm/tcp.py", line 225, in read
    frames_nbytes = await stream.read_bytes(fmt_size)
asyncio.exceptions.CancelledError

During handling of the above exception, another exception occurred:

Traceback (most recent call last):
  File "/mnt/storage/nobackup/nmb1063/mamba/envs/fegrow/lib/python3.9/asyncio/tasks.py", line 490, in wait_for
    return fut.result()
asyncio.exceptions.CancelledError

The above exception was the direct cause of the following exception:

Traceback (most recent call last):
  File "/mnt/storage/nobackup/nmb1063/mamba/envs/fegrow/lib/python3.9/site-packages/distributed/comm/core.py", line 328, in connect
    handshake = await asyncio.wait_for(comm.read(), time_left())
  File "/mnt/storage/nobackup/nmb1063/mamba/envs/fegrow/lib/python3.9/asyncio/tasks.py", line 492, in wait_for
    raise exceptions.TimeoutError() from exc
asyncio.exceptions.TimeoutError

The above exception was the direct cause of the following exception:

Traceback (most recent call last):
  File "/mnt/storage/nobackup/nmb1063/mamba/envs/fegrow/lib/python3.9/site-packages/distributed/worker.py", line 2081, in gather_dep
    response = await get_data_from_worker(
  File "/mnt/storage/nobackup/nmb1063/mamba/envs/fegrow/lib/python3.9/site-packages/distributed/worker.py", line 2900, in get_data_from_worker
    comm = await rpc.connect(worker)
  File "/mnt/storage/nobackup/nmb1063/mamba/envs/fegrow/lib/python3.9/site-packages/distributed/core.py", line 1468, in connect
    return await connect_attempt
  File "/mnt/storage/nobackup/nmb1063/mamba/envs/fegrow/lib/python3.9/site-packages/distributed/core.py", line 1389, in _connect
    comm = await connect(
  File "/mnt/storage/nobackup/nmb1063/mamba/envs/fegrow/lib/python3.9/site-packages/distributed/comm/core.py", line 333, in connect
    raise OSError(
OSError: Timed out during handshake while connecting to tcp://10.3.89.122:39675 after 30 s
2024-01-16 11:53:17,793 - distributed.worker - ERROR - Worker stream died during communication: tcp://10.3.89.122:39675
Traceback (most recent call last):
  File "/mnt/storage/nobackup/nmb1063/mamba/envs/fegrow/lib/python3.9/site-packages/distributed/comm/tcp.py", line 225, in read
    frames_nbytes = await stream.read_bytes(fmt_size)
asyncio.exceptions.CancelledError

During handling of the above exception, another exception occurred:

Traceback (most recent call last):
  File "/mnt/storage/nobackup/nmb1063/mamba/envs/fegrow/lib/python3.9/asyncio/tasks.py", line 490, in wait_for
    return fut.result()
asyncio.exceptions.CancelledError

The above exception was the direct cause of the following exception:

Traceback (most recent call last):
  File "/mnt/storage/nobackup/nmb1063/mamba/envs/fegrow/lib/python3.9/site-packages/distributed/comm/core.py", line 328, in connect
    handshake = await asyncio.wait_for(comm.read(), time_left())
  File "/mnt/storage/nobackup/nmb1063/mamba/envs/fegrow/lib/python3.9/asyncio/tasks.py", line 492, in wait_for
    raise exceptions.TimeoutError() from exc
asyncio.exceptions.TimeoutError

The above exception was the direct cause of the following exception:

Traceback (most recent call last):
  File "/mnt/storage/nobackup/nmb1063/mamba/envs/fegrow/lib/python3.9/site-packages/distributed/worker.py", line 2081, in gather_dep
    response = await get_data_from_worker(
  File "/mnt/storage/nobackup/nmb1063/mamba/envs/fegrow/lib/python3.9/site-packages/distributed/worker.py", line 2900, in get_data_from_worker
    comm = await rpc.connect(worker)
  File "/mnt/storage/nobackup/nmb1063/mamba/envs/fegrow/lib/python3.9/site-packages/distributed/core.py", line 1468, in connect
    return await connect_attempt
  File "/mnt/storage/nobackup/nmb1063/mamba/envs/fegrow/lib/python3.9/site-packages/distributed/core.py", line 1389, in _connect
    comm = await connect(
  File "/mnt/storage/nobackup/nmb1063/mamba/envs/fegrow/lib/python3.9/site-packages/distributed/comm/core.py", line 333, in connect
    raise OSError(
OSError: Timed out during handshake while connecting to tcp://10.3.89.122:39675 after 30 s
2024-01-16 11:53:17,803 - distributed.worker - ERROR - Worker stream died during communication: tcp://10.3.89.122:39675
Traceback (most recent call last):
  File "/mnt/storage/nobackup/nmb1063/mamba/envs/fegrow/lib/python3.9/site-packages/distributed/comm/tcp.py", line 225, in read
    frames_nbytes = await stream.read_bytes(fmt_size)
asyncio.exceptions.CancelledError

During handling of the above exception, another exception occurred:

Traceback (most recent call last):
  File "/mnt/storage/nobackup/nmb1063/mamba/envs/fegrow/lib/python3.9/asyncio/tasks.py", line 490, in wait_for
    return fut.result()
asyncio.exceptions.CancelledError

The above exception was the direct cause of the following exception:

Traceback (most recent call last):
  File "/mnt/storage/nobackup/nmb1063/mamba/envs/fegrow/lib/python3.9/site-packages/distributed/comm/core.py", line 328, in connect
    handshake = await asyncio.wait_for(comm.read(), time_left())
  File "/mnt/storage/nobackup/nmb1063/mamba/envs/fegrow/lib/python3.9/asyncio/tasks.py", line 492, in wait_for
    raise exceptions.TimeoutError() from exc
asyncio.exceptions.TimeoutError

The above exception was the direct cause of the following exception:

Traceback (most recent call last):
  File "/mnt/storage/nobackup/nmb1063/mamba/envs/fegrow/lib/python3.9/site-packages/distributed/worker.py", line 2081, in gather_dep
    response = await get_data_from_worker(
  File "/mnt/storage/nobackup/nmb1063/mamba/envs/fegrow/lib/python3.9/site-packages/distributed/worker.py", line 2900, in get_data_from_worker
    comm = await rpc.connect(worker)
  File "/mnt/storage/nobackup/nmb1063/mamba/envs/fegrow/lib/python3.9/site-packages/distributed/core.py", line 1468, in connect
    return await connect_attempt
  File "/mnt/storage/nobackup/nmb1063/mamba/envs/fegrow/lib/python3.9/site-packages/distributed/core.py", line 1389, in _connect
    comm = await connect(
  File "/mnt/storage/nobackup/nmb1063/mamba/envs/fegrow/lib/python3.9/site-packages/distributed/comm/core.py", line 333, in connect
    raise OSError(
OSError: Timed out during handshake while connecting to tcp://10.3.89.122:39675 after 30 s
2024-01-16 11:53:48,791 - distributed.worker - ERROR - Worker stream died during communication: tcp://10.3.89.122:39675
Traceback (most recent call last):
  File "/mnt/storage/nobackup/nmb1063/mamba/envs/fegrow/lib/python3.9/site-packages/distributed/comm/tcp.py", line 225, in read
    frames_nbytes = await stream.read_bytes(fmt_size)
asyncio.exceptions.CancelledError

During handling of the above exception, another exception occurred:

Traceback (most recent call last):
  File "/mnt/storage/nobackup/nmb1063/mamba/envs/fegrow/lib/python3.9/asyncio/tasks.py", line 490, in wait_for
    return fut.result()
asyncio.exceptions.CancelledError

The above exception was the direct cause of the following exception:

Traceback (most recent call last):
  File "/mnt/storage/nobackup/nmb1063/mamba/envs/fegrow/lib/python3.9/site-packages/distributed/comm/core.py", line 328, in connect
    handshake = await asyncio.wait_for(comm.read(), time_left())
  File "/mnt/storage/nobackup/nmb1063/mamba/envs/fegrow/lib/python3.9/asyncio/tasks.py", line 492, in wait_for
    raise exceptions.TimeoutError() from exc
asyncio.exceptions.TimeoutError

The above exception was the direct cause of the following exception:

Traceback (most recent call last):
  File "/mnt/storage/nobackup/nmb1063/mamba/envs/fegrow/lib/python3.9/site-packages/distributed/worker.py", line 2081, in gather_dep
    response = await get_data_from_worker(
  File "/mnt/storage/nobackup/nmb1063/mamba/envs/fegrow/lib/python3.9/site-packages/distributed/worker.py", line 2900, in get_data_from_worker
    comm = await rpc.connect(worker)
  File "/mnt/storage/nobackup/nmb1063/mamba/envs/fegrow/lib/python3.9/site-packages/distributed/core.py", line 1468, in connect
    return await connect_attempt
  File "/mnt/storage/nobackup/nmb1063/mamba/envs/fegrow/lib/python3.9/site-packages/distributed/core.py", line 1389, in _connect
    comm = await connect(
  File "/mnt/storage/nobackup/nmb1063/mamba/envs/fegrow/lib/python3.9/site-packages/distributed/comm/core.py", line 333, in connect
    raise OSError(
OSError: Timed out during handshake while connecting to tcp://10.3.89.122:39675 after 30 s
2024-01-16 11:53:48,806 - distributed.worker - ERROR - Worker stream died during communication: tcp://10.3.89.122:39675
Traceback (most recent call last):
  File "/mnt/storage/nobackup/nmb1063/mamba/envs/fegrow/lib/python3.9/site-packages/distributed/comm/tcp.py", line 225, in read
    frames_nbytes = await stream.read_bytes(fmt_size)
asyncio.exceptions.CancelledError

During handling of the above exception, another exception occurred:

Traceback (most recent call last):
  File "/mnt/storage/nobackup/nmb1063/mamba/envs/fegrow/lib/python3.9/asyncio/tasks.py", line 490, in wait_for
    return fut.result()
asyncio.exceptions.CancelledError

The above exception was the direct cause of the following exception:

Traceback (most recent call last):
  File "/mnt/storage/nobackup/nmb1063/mamba/envs/fegrow/lib/python3.9/site-packages/distributed/comm/core.py", line 328, in connect
    handshake = await asyncio.wait_for(comm.read(), time_left())
  File "/mnt/storage/nobackup/nmb1063/mamba/envs/fegrow/lib/python3.9/asyncio/tasks.py", line 492, in wait_for
    raise exceptions.TimeoutError() from exc
asyncio.exceptions.TimeoutError

The above exception was the direct cause of the following exception:

Traceback (most recent call last):
  File "/mnt/storage/nobackup/nmb1063/mamba/envs/fegrow/lib/python3.9/site-packages/distributed/worker.py", line 2081, in gather_dep
    response = await get_data_from_worker(
  File "/mnt/storage/nobackup/nmb1063/mamba/envs/fegrow/lib/python3.9/site-packages/distributed/worker.py", line 2900, in get_data_from_worker
    comm = await rpc.connect(worker)
  File "/mnt/storage/nobackup/nmb1063/mamba/envs/fegrow/lib/python3.9/site-packages/distributed/core.py", line 1468, in connect
    return await connect_attempt
  File "/mnt/storage/nobackup/nmb1063/mamba/envs/fegrow/lib/python3.9/site-packages/distributed/core.py", line 1389, in _connect
    comm = await connect(
  File "/mnt/storage/nobackup/nmb1063/mamba/envs/fegrow/lib/python3.9/site-packages/distributed/comm/core.py", line 333, in connect
    raise OSError(
OSError: Timed out during handshake while connecting to tcp://10.3.89.122:39675 after 30 s
2024-01-16 11:54:19,792 - distributed.worker - ERROR - Worker stream died during communication: tcp://10.3.89.122:39675
Traceback (most recent call last):
  File "/mnt/storage/nobackup/nmb1063/mamba/envs/fegrow/lib/python3.9/site-packages/distributed/comm/tcp.py", line 225, in read
    frames_nbytes = await stream.read_bytes(fmt_size)
asyncio.exceptions.CancelledError

During handling of the above exception, another exception occurred:

Traceback (most recent call last):
  File "/mnt/storage/nobackup/nmb1063/mamba/envs/fegrow/lib/python3.9/asyncio/tasks.py", line 490, in wait_for
    return fut.result()
asyncio.exceptions.CancelledError

The above exception was the direct cause of the following exception:

Traceback (most recent call last):
  File "/mnt/storage/nobackup/nmb1063/mamba/envs/fegrow/lib/python3.9/site-packages/distributed/comm/core.py", line 328, in connect
    handshake = await asyncio.wait_for(comm.read(), time_left())
  File "/mnt/storage/nobackup/nmb1063/mamba/envs/fegrow/lib/python3.9/asyncio/tasks.py", line 492, in wait_for
    raise exceptions.TimeoutError() from exc
asyncio.exceptions.TimeoutError

The above exception was the direct cause of the following exception:

Traceback (most recent call last):
  File "/mnt/storage/nobackup/nmb1063/mamba/envs/fegrow/lib/python3.9/site-packages/distributed/worker.py", line 2081, in gather_dep
    response = await get_data_from_worker(
  File "/mnt/storage/nobackup/nmb1063/mamba/envs/fegrow/lib/python3.9/site-packages/distributed/worker.py", line 2900, in get_data_from_worker
    comm = await rpc.connect(worker)
  File "/mnt/storage/nobackup/nmb1063/mamba/envs/fegrow/lib/python3.9/site-packages/distributed/core.py", line 1468, in connect
    return await connect_attempt
  File "/mnt/storage/nobackup/nmb1063/mamba/envs/fegrow/lib/python3.9/site-packages/distributed/core.py", line 1389, in _connect
    comm = await connect(
  File "/mnt/storage/nobackup/nmb1063/mamba/envs/fegrow/lib/python3.9/site-packages/distributed/comm/core.py", line 333, in connect
    raise OSError(
OSError: Timed out during handshake while connecting to tcp://10.3.89.122:39675 after 30 s
2024-01-16 11:54:19,806 - distributed.worker - ERROR - Worker stream died during communication: tcp://10.3.89.122:39675
Traceback (most recent call last):
  File "/mnt/storage/nobackup/nmb1063/mamba/envs/fegrow/lib/python3.9/site-packages/distributed/comm/tcp.py", line 225, in read
    frames_nbytes = await stream.read_bytes(fmt_size)
asyncio.exceptions.CancelledError

During handling of the above exception, another exception occurred:

Traceback (most recent call last):
  File "/mnt/storage/nobackup/nmb1063/mamba/envs/fegrow/lib/python3.9/asyncio/tasks.py", line 490, in wait_for
    return fut.result()
asyncio.exceptions.CancelledError

The above exception was the direct cause of the following exception:

Traceback (most recent call last):
  File "/mnt/storage/nobackup/nmb1063/mamba/envs/fegrow/lib/python3.9/site-packages/distributed/comm/core.py", line 328, in connect
    handshake = await asyncio.wait_for(comm.read(), time_left())
  File "/mnt/storage/nobackup/nmb1063/mamba/envs/fegrow/lib/python3.9/asyncio/tasks.py", line 492, in wait_for
    raise exceptions.TimeoutError() from exc
asyncio.exceptions.TimeoutError

The above exception was the direct cause of the following exception:

Traceback (most recent call last):
  File "/mnt/storage/nobackup/nmb1063/mamba/envs/fegrow/lib/python3.9/site-packages/distributed/worker.py", line 2081, in gather_dep
    response = await get_data_from_worker(
  File "/mnt/storage/nobackup/nmb1063/mamba/envs/fegrow/lib/python3.9/site-packages/distributed/worker.py", line 2900, in get_data_from_worker
    comm = await rpc.connect(worker)
  File "/mnt/storage/nobackup/nmb1063/mamba/envs/fegrow/lib/python3.9/site-packages/distributed/core.py", line 1468, in connect
    return await connect_attempt
  File "/mnt/storage/nobackup/nmb1063/mamba/envs/fegrow/lib/python3.9/site-packages/distributed/core.py", line 1389, in _connect
    comm = await connect(
  File "/mnt/storage/nobackup/nmb1063/mamba/envs/fegrow/lib/python3.9/site-packages/distributed/comm/core.py", line 333, in connect
    raise OSError(
OSError: Timed out during handshake while connecting to tcp://10.3.89.122:39675 after 30 s
2024-01-16 11:59:13,064 - distributed.core - INFO - Event loop was unresponsive in Worker for 280.62s.  This is often caused by long-running GIL-holding functions or moving large chunks of data. This can cause timeouts and instability.
2024-01-16 11:59:13,167 - distributed.core - INFO - Event loop was unresponsive in Worker for 280.71s.  This is often caused by long-running GIL-holding functions or moving large chunks of data. This can cause timeouts and instability.
Warning (not error because allow_undefined_stereo=True): RDMol has unspecified stereochemistry. Bonds with undefined stereochemistry are:
 - Bond 8 (atoms 8-9 of element (C-N)

/mnt/storage/nobackup/nmb1063/mamba/envs/fegrow/lib/python3.9/site-packages/parmed/structure.py:1775: UnitStrippedWarning: The unit of the quantity is stripped when downcasting to ndarray.
  coords = np.array(value, dtype=np.float64, copy=False, subok=True)
/mnt/storage/nobackup/nmb1063/mamba/envs/fegrow/lib/python3.9/site-packages/parmed/structure.py:1775: UnitStrippedWarning: The unit of the quantity is stripped when downcasting to ndarray.
  coords = np.array(value, dtype=np.float64, copy=False, subok=True)
Warning (not error because allow_undefined_stereo=True): RDMol has unspecified stereochemistry. Bonds with undefined stereochemistry are:
 - Bond 1 (atoms 1-2 of element (C-C)

Warning (not error because allow_undefined_stereo=True): RDMol has unspecified stereochemistry. Bonds with undefined stereochemistry are:
 - Bond 1 (atoms 1-2 of element (C-C)

Warning (not error because allow_undefined_stereo=True): RDMol has unspecified stereochemistry. Bonds with undefined stereochemistry are:
 - Bond 1 (atoms 1-2 of element (C-C)

2024-01-16 11:59:24,660 - distributed.core - INFO - Event loop was unresponsive in Worker for 3.13s.  This is often caused by long-running GIL-holding functions or moving large chunks of data. This can cause timeouts and instability.
Warning (not error because allow_undefined_stereo=True): RDMol has unspecified stereochemistry. Bonds with undefined stereochemistry are:
 - Bond 1 (atoms 1-2 of element (C-C)

Warning (not error because allow_undefined_stereo=True): RDMol has unspecified stereochemistry. Bonds with undefined stereochemistry are:
 - Bond 8 (atoms 8-9 of element (C-N)

/mnt/storage/nobackup/nmb1063/mamba/envs/fegrow/lib/python3.9/site-packages/torchani/__init__.py:55: UserWarning: Dependency not satisfied, torchani.ase will not be available
  warnings.warn("Dependency not satisfied, torchani.ase will not be available")
/mnt/storage/nobackup/nmb1063/mamba/envs/fegrow/lib/python3.9/site-packages/torchani/__init__.py:55: UserWarning: Dependency not satisfied, torchani.ase will not be available
  warnings.warn("Dependency not satisfied, torchani.ase will not be available")
2024-01-16 12:00:50,021 - distributed.core - INFO - Event loop was unresponsive in Worker for 4.41s.  This is often caused by long-running GIL-holding functions or moving large chunks of data. This can cause timeouts and instability.
2024-01-16 12:00:50,022 - distributed.core - INFO - Event loop was unresponsive in Worker for 4.42s.  This is often caused by long-running GIL-holding functions or moving large chunks of data. This can cause timeouts and instability.
Warning: importing 'simtk.openmm' is deprecated.  Import 'openmm' instead.
Warning: importing 'simtk.openmm' is deprecated.  Import 'openmm' instead.
2024-01-16 12:01:43,670 - distributed.nanny - INFO - Worker process 15417 was killed by signal 11
2024-01-16 12:01:43,674 - distributed.nanny - WARNING - Restarting worker
2024-01-16 12:01:43,717 - distributed.worker - WARNING - Compute Failed
Key:       evaluate-2c2b0c72-8ecc-4dd9-9167-7b30be6c07f3
Function:  evaluate
args:      (<rdkit.Chem.rdchem.Mol object at 0x2b674bb0e900>, 6, '[H]c1nc([H])c(-c2c(C(=NN([H])C(=S)N([H])[H])C([H])([H])[H])nc([H])c([H])c2[H])c([H])c1[H]', '/mnt/storage/nobackup/nmb1063/code/gal/sars-cov-2-main-protease-al-study/rec_final.pdb', '/nobackup/nmb1063/sars-fegrow/gnina')
kwargs:    {}
Exception: 'RuntimeError("Can\'t redefine method: forward on class: __torch__.torchani.aev.AEVComputer (of Python compilation unit at: 0x2b681fbf11e0)")'

2024-01-16 12:01:46,384 - distributed.worker - WARNING - Compute Failed
Key:       evaluate-15754976-245b-41bc-a9bf-edb7c7bfe089
Function:  evaluate
args:      (<rdkit.Chem.rdchem.Mol object at 0x2b674bb0e900>, 6, '[H]c1nc(OC2([H])C([H])([H])C([H])([H])C([H])([H])C2([H])[H])nc(-c2c([H])nc([H])c([H])c2[H])c1[H]', '/mnt/storage/nobackup/nmb1063/code/gal/sars-cov-2-main-protease-al-study/rec_final.pdb', '/nobackup/nmb1063/sars-fegrow/gnina')
kwargs:    {}
Exception: "OpenMMException('PytorchStreamReader failed reading zip archive: failed finding central directory\\nException raised from valid at /home/conda/feedstock_root/build_artifacts/pytorch-recipe_1650965732461/work/caffe2/serialize/inline_container.cc:152 (most recent call first):\\nframe #0: c10::Error::Error(c10::SourceLocation, std::__cxx11::basic_string<char, std::char_traits<char>, std::allocator<char> >) + 0x68 (0x2b6754904a78 in /mnt/storage/nobackup/nmb1063/mamba/envs/fegrow/lib/python3.9/site-packages/torch/lib/libc10.so)\\nframe #1: c10::detail::torchCheckFail(char const*, char const*, unsigned int, std::__cxx11::basic_string<char, std::char_traits<char>, std::allocator<char> > const&) + 0xf3 (0x2b67548e1c23 in /mnt/storage/nobackup/nmb1063/mamba/envs/fegrow/lib/python3.9/site-packages/torch/lib/libc10.so)\\nframe #2: caffe2::serialize::PyTorchStreamReader::valid(char const*, char const*) + 0x343 (0x2b675756b133 in /mnt/storage/nobackup/nmb1063/mamba/envs/fegrow/lib/python3.9/site-packages/torch/lib/libtorch_cpu.so)\\nframe #3: caffe2::serialize::PyTorchStreamReader::init() + 0x98 (0x2b675756b608 in /mnt/storage/nobackup/nmb1063/mamba/envs/fegrow/lib/python3.9/site-packages/torch/lib/libtorch_cpu.so)\\nframe #4: caffe2::serialize::PyTorchStreamReader::PyTorchStreamReader(std::shared_ptr<caffe2::serialize::ReadAdapterInterface>) + 0x97 (0x2b675756c947 in /mnt/storage/nobackup/nmb1063/mamba/envs/fegrow/lib/python3.9/site-packages/torch/lib/libtorch_cpu.so)\\nframe #5: torch::jit::load(std::shared_ptr<caffe2::serialize::ReadAdapterInterface>, c10::optional<c10::Device>, std::unordered_map<std::__cxx11::basic_string<char, std::char_traits<char>, std::allocator<char> >, std::__cxx11::basic_string<char, std::char_traits<char>, std::allocator<char> >, std::hash<std::__cxx11::basic_string<char, std::char_traits<char>, std::allocator<char> > >, std::equal_to<std::__cxx11::basic_string<char, std::char_traits<char>, std::allocator<char> > >, std::allocator<std::pair<std::__cxx11::basic_string<char, std::char_traits<char>, std::allocator<char> > const, std::__cxx11::basic_string<char, std::char_traits<char>, std::allocator<char> > > > >&) + 0xc4 (0x2b6758074174 in /mnt/storage/nobackup/nmb1063/mamba/envs/fegrow/lib/python3.9/site-packages/torch/lib/libtorch_cpu.so)\\nframe #6: torch::jit::load(std::__cxx11::basic_string<char, std::char_traits<char>, std::allocator<char> > const&, c10::optional<c10::Device>, std::unordered_map<std::__cxx11::basic_string<char, std::char_traits<char>, std::allocator<char> >, std::__cxx11::basic_string<char, std::char_traits<char>, std::allocator<char> >, std::hash<std::__cxx11::basic_string<char, std::char_traits<char>, std::allocator<char> > >, std::equal_to<std::__cxx11::basic_string<char, std::char_traits<char>, std::allocator<char> > >, std::allocator<std::pair<std::__cxx11::basic_string<char, std::char_traits<char>, std::allocator<char> > const, std::__cxx11::basic_string<char, std::char_traits<char>, std::allocator<char> > > > >&) + 0xe1 (0x2b6758075591 in /mnt/storage/nobackup/nmb1063/mamba/envs/fegrow/lib/python3.9/site-packages/torch/lib/libtorch_cpu.so)\\nframe #7: torch::jit::load(std::__cxx11::basic_string<char, std::char_traits<char>, std::allocator<char> > const&, c10::optional<c10::Device>) + 0x8e (0x2b675807567e in /mnt/storage/nobackup/nmb1063/mamba/envs/fegrow/lib/python3.9/site-packages/torch/lib/libtorch_cpu.so)\\nframe #8: TorchPlugin::TorchForceImpl::initialize(OpenMM::ContextImpl&) + 0x67 (0x2b6753cfbd07 in /mnt/storage/nobackup/nmb1063/mamba/envs/fegrow/lib/plugins/../libOpenMMTorch.so)\\nframe #9: OpenMM::ContextImpl::initialize() + 0x487 (0x2b67542bf437 in /mnt/storage/nobackup/nmb1063/mamba/envs/fegrow/lib/python3.9/site-packages/openmm/../../../libOpenMM.so.8.0)\\nframe #10: OpenMM::Context::Context(OpenMM::System const&, OpenMM::Integrator&, OpenMM::Platform&) + 0x82 (0x2b67542b76f2 in /mnt/storage/nobackup/nmb1063/mamba/envs/fegrow/lib/python3.9/site-packages/openmm/../../../libOpenMM.so.8.0)\\nframe #11: <unknown function> + 0x17f64d (0x2b675406d64d in /mnt/storage/nobackup/nmb1063/mamba/envs/fegrow/lib/python3.9/site-packages/openmm/_openmm.cpython-39-x86_64-linux-gnu.so)\\nframe #12: <unknown function> + 0x14e568 (0x56057b99b568 in /mnt/storage/nobackup/nmb1063/mamba/envs/fegrow/bin/python)\\nframe #13: PyObject_Call + 0x15f (0x56057b99a0af in /mnt/storage/nobackup/nmb1063/mamba/envs/fegrow/bin/python)\\nframe #14: _PyEval_EvalFrameDefault + 0x58b4 (0x56057b9816e4 in /mnt/storage/nobackup/nmb1063/mamba/envs/fegrow/bin/python)\\nframe #15: <unknown function> + 0x12df94 (0x56057b97af94 in /mnt/storage/nobackup/nmb1063/mamba/envs/fegrow/bin/python)\\nframe #16: _PyObject_FastCallDictTstate + 0x142 (0x56057b983ee2 in /mnt/storage/nobackup/nmb1063/mamba/envs/fegrow/bin/python)\\nframe #17: <unknown function> + 0x14a0d9 (0x56057b9970d9 in /mnt/storage/nobackup/nmb1063/mamba/envs/fegrow/bin/python)\\nframe #18: _PyObject_MakeTpCall + 0x303 (0x56057b984693 in /mnt/storage/nobackup/nmb1063/mamba/envs/fegrow/bin/python)\\nframe #19: _PyEval_EvalFrameDefault + 0x4fa0 (0x56057b980dd0 in /mnt/storage/nobackup/nmb1063/mamba/envs/fegrow/bin/python)\\nframe #20: <unknown function> + 0x12df94 (0x56057b97af94 in /mnt/storage/nobackup/nmb1063/mamba/envs/fegrow/bin/python)\\nframe #21: _PyFunction_Vectorcall + 0xd9 (0x56057b98c3f9 in /mnt/storage/nobackup/nmb1063/mamba/envs/fegrow/bin/python)\\nframe #22: _PyObject_FastCallDictTstate + 0x1a5 (0x56057b983f45 in /mnt/storage/nobackup/nmb1063/mamba/envs/fegrow/bin/python)\\nframe #23: <unknown function> + 0x14a0d9 (0x56057b9970d9 in /mnt/storage/nobackup/nmb1063/mamba/envs/fegrow/bin/python)\\nframe #24: _PyObject_MakeTpCall + 0x303 (0x56057b984693 in /mnt/storage/nobackup/nmb1063/mamba/envs/fegrow/bin/python)\\nframe #25: _PyEval_EvalFrameDefault + 0x5156 (0x56057b980f86 in /mnt/storage/nobackup/nmb1063/mamba/envs/fegrow/bin/python)\\nframe #26: <unknown function> + 0x12df94 (0x56057b97af94 in /mnt/storage/nobackup/nmb1063/mamba/envs/fegrow/bin/python)\\nframe #27: _PyFunction_Vectorcall + 0xd9 (0x56057b98c3f9 in /mnt/storage/nobackup/nmb1063/mamba/envs/fegrow/bin/python)\\nframe #28: PyObject_Call + 0xbc (0x56057b99a00c in /mnt/storage/nobackup/nmb1063/mamba/envs/fegrow/bin/python)\\nframe #29: _PyEval_EvalFrameDefault + 0x45a6 (0x56057b9803d6 in /mnt/storage/nobackup/nmb1063/mamba/envs/fegrow/bin/python)\\nframe #30: <unknown function> + 0x12df94 (0x56057b97af94 in /mnt/storage/nobackup/nmb1063/mamba/envs/fegrow/bin/python)\\nframe #31: <unknown function> + 0x14c88b (0x56057b99988b in /mnt/storage/nobackup/nmb1063/mamba/envs/fegrow/bin/python)\\nframe #32: _PyEval_EvalFrameDefault + 0x11f2 (0x56057b97d022 in /mnt/storage/nobackup/nmb1063/mamba/envs/fegrow/bin/python)\\nframe #33: <unknown function> + 0x13f6a2 (0x56057b98c6a2 in /mnt/storage/nobackup/nmb1063/mamba/envs/fegrow/bin/python)\\nframe #34: _PyEval_EvalFrameDefault + 0x45a6 (0x56057b9803d6 in /mnt/storage/nobackup/nmb1063/mamba/envs/fegrow/bin/python)\\nframe #35: <unknown function> + 0x13f6a2 (0x56057b98c6a2 in /mnt/storage/nobackup/nmb1063/mamba/envs/fegrow/bin/python)\\nframe #36: _PyEval_EvalFrameDefault + 0x3e2 (0x56057b97c212 in /mnt/storage/nobackup/nmb1063/mamba/envs/fegrow/bin/python)\\nframe #37: <unknown function> + 0x13f6a2 (0x56057b98c6a2 in /mnt/storage/nobackup/nmb1063/mamba/envs/fegrow/bin/python)\\nframe #38: _PyEval_EvalFrameDefault + 0x45a6 (0x56057b9803d6 in /mnt/storage/nobackup/nmb1063/mamba/envs/fegrow/bin/python)\\nframe #39: <unknown function> + 0x13f6a2 (0x56057b98c6a2 in /mnt/storage/nobackup/nmb1063/mamba/envs/fegrow/bin/python)\\nframe #40: _PyEval_EvalFrameDefault + 0x696 (0x56057b97c4c6 in /mnt/storage/nobackup/nmb1063/mamba/envs/fegrow/bin/python)\\nframe #41: <unknown function> + 0x13f6a2 (0x56057b98c6a2 in /mnt/storage/nobackup/nmb1063/mamba/envs/fegrow/bin/python)\\nframe #42: _PyEval_EvalFrameDefault + 0x45a6 (0x56057b9803d6 in /mnt/storage/nobackup/nmb1063/mamba/envs/fegrow/bin/python)\\nframe #43: <unknown function> + 0x13f6a2 (0x56057b98c6a2 in /mnt/storage/nobackup/nmb1063/mamba/envs/fegrow/bin/python)\\nframe #44: _PyEval_EvalFrameDefault + 0x696 (0x56057b97c4c6 in /mnt/storage/nobackup/nmb1063/mamba/envs/fegrow/bin/python)\\nframe #45: <unknown function> + 0x13f6a2 (0x56057b98c6a2 in /mnt/storage/nobackup/nmb1063/mamba/envs/fegrow/bin/python)\\nframe #46: _PyEval_EvalFrameDefault + 0x696 (0x56057b97c4c6 in /mnt/storage/nobackup/nmb1063/mamba/envs/fegrow/bin/python)\\nframe #47: <unknown function> + 0x13f6a2 (0x56057b98c6a2 in /mnt/storage/nobackup/nmb1063/mamba/envs/fegrow/bin/python)\\nframe #48: <unknown function> + 0x14ca43 (0x56057b999a43 in /mnt/storage/nobackup/nmb1063/mamba/envs/fegrow/bin/python)\\nframe #49: <unknown function> + 0x2244b2 (0x56057ba714b2 in /mnt/storage/nobackup/nmb1063/mamba/envs/fegrow/bin/python)\\nframe #50: <unknown function> + 0x224464 (0x56057ba71464 in /mnt/storage/nobackup/nmb1063/mamba/envs/fegrow/bin/python)\\nframe #51: <unknown function> + 0x7ea5 (0x2b6722cdfea5 in /lib64/libpthread.so.0)\\nframe #52: clone + 0x6d (0x2b67236fbb0d in /lib64/libc.so.6)\\n')"

2024-01-16 12:01:47,166 - distributed.worker - INFO -       Start worker at:     tcp://10.3.89.86:41714
2024-01-16 12:01:47,166 - distributed.worker - INFO -          Listening to:     tcp://10.3.89.86:41714
2024-01-16 12:01:47,166 - distributed.worker - INFO -           Worker name:          SLURMCluster-85-0
2024-01-16 12:01:47,166 - distributed.worker - INFO -          dashboard at:           10.3.89.86:38074
2024-01-16 12:01:47,166 - distributed.worker - INFO - Waiting to connect to:     tcp://10.3.88.12:37277
2024-01-16 12:01:47,166 - distributed.worker - INFO - -------------------------------------------------
2024-01-16 12:01:47,167 - distributed.worker - INFO -               Threads:                          2
2024-01-16 12:01:47,167 - distributed.worker - INFO -                Memory:                  10.24 GiB
2024-01-16 12:01:47,167 - distributed.worker - INFO -       Local Directory: /scratch/dask-worker-space/worker-_d3red48
2024-01-16 12:01:47,167 - distributed.worker - INFO - -------------------------------------------------
2024-01-16 12:01:47,189 - distributed.worker - INFO -         Registered to:     tcp://10.3.88.12:37277
2024-01-16 12:01:47,189 - distributed.worker - INFO - -------------------------------------------------
2024-01-16 12:01:47,191 - distributed.core - INFO - Starting established connection to tcp://10.3.88.12:37277
2024-01-16 12:01:47,260 - distributed.utils_perf - INFO - full garbage collection released 25.96 MiB from 480537 reference cycles (threshold: 9.54 MiB)
/mnt/storage/nobackup/nmb1063/mamba/envs/fegrow/lib/python3.9/site-packages/parmed/structure.py:1775: UnitStrippedWarning: The unit of the quantity is stripped when downcasting to ndarray.
  coords = np.array(value, dtype=np.float64, copy=False, subok=True)
2024-01-16 12:01:50,956 - distributed.worker - WARNING - Compute Failed
Key:       evaluate-0c17ac68-8e2e-46a9-9dce-9335bb1a6dce
Function:  evaluate
args:      (<rdkit.Chem.rdchem.Mol object at 0x2b674bb0e900>, 6, '[H]OC([H])([H])C([H])([H])C([H])([H])N([H])c1sc(-c2c([H])nc([H])c([H])c2[H])c([H])c(=O)c1[H]', '/mnt/storage/nobackup/nmb1063/code/gal/sars-cov-2-main-protease-al-study/rec_final.pdb', '/nobackup/nmb1063/sars-fegrow/gnina')
kwargs:    {}
Exception: "JSONDecodeError('Invalid control character at: line 96 column 141406 (char 3619649)')"

2024-01-16 12:01:53,841 - distributed.worker - WARNING - Compute Failed
Key:       evaluate-0282e073-65fd-46ae-9cfe-97a2c0c886b3
Function:  evaluate
args:      (<rdkit.Chem.rdchem.Mol object at 0x2b674bb0e900>, 6, '[H]c1nc([H])c(-c2c([H])nc3sc(N([H])c4c([H])c([H])c(F)c([H])c4[H])nn23)c([H])c1[H]', '/mnt/storage/nobackup/nmb1063/code/gal/sars-cov-2-main-protease-al-study/rec_final.pdb', '/nobackup/nmb1063/sars-fegrow/gnina')
kwargs:    {}
Exception: "JSONDecodeError('Invalid control character at: line 96 column 141406 (char 3619649)')"

2024-01-16 12:01:54,099 - distributed.core - INFO - Event loop was unresponsive in Worker for 6.67s.  This is often caused by long-running GIL-holding functions or moving large chunks of data. This can cause timeouts and instability.
2024-01-16 12:01:58,803 - distributed.worker - WARNING - Compute Failed
Key:       evaluate-061a65d9-6f90-48d9-8af5-9fefce40923e
Function:  evaluate
args:      (<rdkit.Chem.rdchem.Mol object at 0x2b674bb0e900>, 6, '[H]c1nc([H])c(-c2snnc2-c2c([H])c([H])c(S(=O)(=O)N([H])[H])c([H])c2[H])c([H])c1[H]', '/mnt/storage/nobackup/nmb1063/code/gal/sars-cov-2-main-protease-al-study/rec_final.pdb', '/nobackup/nmb1063/sars-fegrow/gnina')
kwargs:    {}
Exception: "JSONDecodeError('Invalid control character at: line 96 column 141406 (char 3619649)')"

2024-01-16 12:02:02,173 - distributed.worker - WARNING - Compute Failed
Key:       evaluate-9cb7bf7a-ae92-4a80-8f83-73876c433ee1
Function:  evaluate
args:      (<rdkit.Chem.rdchem.Mol object at 0x2b674bb0e900>, 6, '[H]c1nc([H])c(-n2c(-c3c([H])c([H])c([H])c(C([H])([H])N([H])[H])c3[H])nc([H])c2[H])c([H])c1[H]', '/mnt/storage/nobackup/nmb1063/code/gal/sars-cov-2-main-protease-al-study/rec_final.pdb', '/nobackup/nmb1063/sars-fegrow/gnina')
kwargs:    {}
Exception: "JSONDecodeError('Invalid control character at: line 96 column 141406 (char 3619649)')"

/mnt/storage/nobackup/nmb1063/mamba/envs/fegrow/lib/python3.9/site-packages/parmed/structure.py:1775: UnitStrippedWarning: The unit of the quantity is stripped when downcasting to ndarray.
  coords = np.array(value, dtype=np.float64, copy=False, subok=True)
2024-01-16 12:02:03,339 - distributed.worker - WARNING - Compute Failed
Key:       evaluate-9526afb1-cdf0-4c88-a2bf-15e12b02a6c1
Function:  evaluate
args:      (<rdkit.Chem.rdchem.Mol object at 0x2b84446a5040>, 6, '[H]c1nc([H])c([C@]2([H])N([H])C(=O)O[C@@]2([H])C([H])([H])N([H])C(=O)c2c([H])c([H])c([H])c([H])c2[H])c([H])c1[H]', '/mnt/storage/nobackup/nmb1063/code/gal/sars-cov-2-main-protease-al-study/rec_final.pdb', '/nobackup/nmb1063/sars-fegrow/gnina')
kwargs:    {}
Exception: "JSONDecodeError('Invalid control character at: line 96 column 141406 (char 3619649)')"

2024-01-16 12:02:05,826 - distributed.worker - WARNING - Compute Failed
Key:       evaluate-95797210-ec20-473b-aca5-0bdb3e398ef3
Function:  evaluate
args:      (<rdkit.Chem.rdchem.Mol object at 0x2b84446a5040>, 6, '[H]O[C@](c1c([H])nc([H])c([H])c1[H])(C([H])([H])[H])C([H])([H])N1C([H])([H])C([H])([H])C([H])(OC([H])([H])[H])C([H])([H])C1([H])[H]', '/mnt/storage/nobackup/nmb1063/code/gal/sars-cov-2-main-protease-al-study/rec_final.pdb', '/nobackup/nmb1063/sars-fegrow/gnina')
kwargs:    {}
Exception: "JSONDecodeError('Invalid control character at: line 96 column 141406 (char 3619649)')"

2024-01-16 12:02:07,169 - distributed.worker - WARNING - Compute Failed
Key:       evaluate-a5db16bb-85f1-474c-9026-57a601675e19
Function:  evaluate
args:      (<rdkit.Chem.rdchem.Mol object at 0x2b674bb0e900>, 6, '[H]c1nc([H])c(N([H])C(=O)Oc2nc3c([H])c([H])c([H])c([H])c3c([H])c2[H])c([H])c1[H]', '/mnt/storage/nobackup/nmb1063/code/gal/sars-cov-2-main-protease-al-study/rec_final.pdb', '/nobackup/nmb1063/sars-fegrow/gnina')
kwargs:    {}
Exception: "JSONDecodeError('Invalid control character at: line 96 column 141406 (char 3619649)')"

2024-01-16 12:02:10,659 - distributed.worker - WARNING - Compute Failed
Key:       evaluate-97361bba-c65e-485d-9218-43ca2a1bb4b2
Function:  evaluate
args:      (<rdkit.Chem.rdchem.Mol object at 0x2b84446a5040>, 6, '[H]c1nc([H])c(-c2nn(C3=NC([H])([H])C([H])([H])N3[H])c([H])c([H])c2=O)c([H])c1[H]', '/mnt/storage/nobackup/nmb1063/code/gal/sars-cov-2-main-protease-al-study/rec_final.pdb', '/nobackup/nmb1063/sars-fegrow/gnina')
kwargs:    {}
Exception: "JSONDecodeError('Invalid control character at: line 96 column 141406 (char 3619649)')"

2024-01-16 12:02:14,606 - distributed.worker - WARNING - Compute Failed
Key:       evaluate-b1b0c426-5175-49f5-ad88-ebfc108a87fa
Function:  evaluate
args:      (<rdkit.Chem.rdchem.Mol object at 0x2b674bb0e900>, 6, '[H]c1nc([H])c(-c2nn3c(N([H])C(=O)C4([H])C([H])([H])C([H])([H])C([H])([H])C([H])([H])C4([H])[H])nnc3s2)c([H])c1[H]', '/mnt/storage/nobackup/nmb1063/code/gal/sars-cov-2-main-protease-al-study/rec_final.pdb', '/nobackup/nmb1063/sars-fegrow/gnina')
kwargs:    {}
Exception: "JSONDecodeError('Invalid control character at: line 96 column 141406 (char 3619649)')"

2024-01-16 12:02:15,873 - distributed.worker - WARNING - Compute Failed
Key:       evaluate-c884ef3b-86e8-4866-9ed6-63e662e16273
Function:  evaluate
args:      (<rdkit.Chem.rdchem.Mol object at 0x2b84446a5040>, 6, '[H]c1nc([H])c(-c2c([H])nc([H])n2C([H])([H])c2nn([H])c([H])c2[H])c([H])c1[H]', '/mnt/storage/nobackup/nmb1063/code/gal/sars-cov-2-main-protease-al-study/rec_final.pdb', '/nobackup/nmb1063/sars-fegrow/gnina')
kwargs:    {}
Exception: "JSONDecodeError('Invalid control character at: line 96 column 141406 (char 3619649)')"

2024-01-16 12:02:17,661 - distributed.worker - WARNING - Compute Failed
Key:       evaluate-b89bc84e-56c2-49aa-952a-ead35d7e0ef7
Function:  evaluate
args:      (<rdkit.Chem.rdchem.Mol object at 0x2b674bb0e900>, 6, '[H]c1nc([H])c(-n2c([H])c([H])c([H])c2C([H])([H])C([H])([H])N([H])C2([H])C([H])([H])C([H])([H])C([H])([H])C2([H])[H])c([H])c1[H]', '/mnt/storage/nobackup/nmb1063/code/gal/sars-cov-2-main-protease-al-study/rec_final.pdb', '/nobackup/nmb1063/sars-fegrow/gnina')
kwargs:    {}
Exception: "JSONDecodeError('Invalid control character at: line 96 column 141406 (char 3619649)')"

2024-01-16 12:02:19,377 - distributed.worker - WARNING - Compute Failed
Key:       evaluate-c27a2f84-bbd6-445c-90a8-1686c2542c4f
Function:  evaluate
args:      (<rdkit.Chem.rdchem.Mol object at 0x2b84446a5040>, 6, '[H]c1nc([H])c([C@]2(C([H])([H])c3c([H])c([H])c(OC([H])([H])[H])c([H])c3OC([H])([H])[H])C([H])([H])N([H])C([H])([H])C2([H])[H])c([H])c1[H]', '/mnt/storage/nobackup/nmb1063/code/gal/sars-cov-2-main-protease-al-study/rec_final.pdb', '/nobackup/nmb1063/sars-fegrow/gnina')
kwargs:    {}
Exception: "JSONDecodeError('Invalid control character at: line 96 column 141406 (char 3619649)')"

2024-01-16 12:02:22,151 - distributed.worker - WARNING - Compute Failed
Key:       evaluate-cfac4bcf-0975-4d6a-b604-a0e0b04dcdee
Function:  evaluate
args:      (<rdkit.Chem.rdchem.Mol object at 0x2b674bb0e900>, 6, '[H]c1nc([H])c(C([H])([H])S(=O)(=O)c2c([H])c(F)c([H])c(F)c2[H])c([H])c1[H]', '/mnt/storage/nobackup/nmb1063/code/gal/sars-cov-2-main-protease-al-study/rec_final.pdb', '/nobackup/nmb1063/sars-fegrow/gnina')
kwargs:    {}
Exception: "JSONDecodeError('Invalid control character at: line 96 column 141406 (char 3619649)')"

2024-01-16 12:02:24,589 - distributed.worker - WARNING - Compute Failed
Key:       evaluate-db3a0774-9d3a-48fe-966d-aa2fa7888cc5
Function:  evaluate
args:      (<rdkit.Chem.rdchem.Mol object at 0x2b84446a5040>, 6, '[H]c1nc([H])c([C@]([H])(Br)C([H])([H])C([H])([H])N([H])C([H])([H])c2c([H])c([H])c([H])c([H])c2[H])c([H])c1[H]', '/mnt/storage/nobackup/nmb1063/code/gal/sars-cov-2-main-protease-al-study/rec_final.pdb', '/nobackup/nmb1063/sars-fegrow/gnina')
kwargs:    {}
Exception: "JSONDecodeError('Invalid control character at: line 96 column 141406 (char 3619649)')"

2024-01-16 12:02:27,116 - distributed.worker - WARNING - Compute Failed
Key:       evaluate-f924786b-7095-4827-8270-8dee6b708518
Function:  evaluate
args:      (<rdkit.Chem.rdchem.Mol object at 0x2b84446a5040>, 6, '[H]C1=C(c2c([H])nc([H])c([H])c2[H])C([H])([H])C([H])([H])[C@]1([H])c1c([H])c([H])c2c(c1[H])c([H])c([H])n2[H]', '/mnt/storage/nobackup/nmb1063/code/gal/sars-cov-2-main-protease-al-study/rec_final.pdb', '/nobackup/nmb1063/sars-fegrow/gnina')
kwargs:    {}
Exception: "JSONDecodeError('Invalid control character at: line 96 column 141406 (char 3619649)')"

2024-01-16 12:02:27,929 - distributed.worker - WARNING - Compute Failed
Key:       evaluate-f580ec6c-86b6-4124-b89a-2c73607713f6
Function:  evaluate
args:      (<rdkit.Chem.rdchem.Mol object at 0x2b674bb0e900>, 6, '[H]c1nc([H])c(N([H])c2c([H])nn([H])c2N2C([H])([H])c3c([H])c([H])c([H])c([H])c3C([H])([H])C2([H])[H])c([H])c1[H]', '/mnt/storage/nobackup/nmb1063/code/gal/sars-cov-2-main-protease-al-study/rec_final.pdb', '/nobackup/nmb1063/sars-fegrow/gnina')
kwargs:    {}
Exception: "JSONDecodeError('Invalid control character at: line 96 column 141406 (char 3619649)')"

2024-01-16 12:02:29,613 - distributed.worker - WARNING - Compute Failed
Key:       evaluate-fdda6d47-bf6e-45c2-bdce-d5a07e72915f
Function:  evaluate
args:      (<rdkit.Chem.rdchem.Mol object at 0x2b674bb0e900>, 6, '[H]c1nc([H])c(-c2nnc(C3(c4nc5c([H])c(C(=O)N([H])[H])c([H])c([H])c5n4[H])C([H])([H])C3([H])[H])s2)c([H])c1[H]', '/mnt/storage/nobackup/nmb1063/code/gal/sars-cov-2-main-protease-al-study/rec_final.pdb', '/nobackup/nmb1063/sars-fegrow/gnina')
kwargs:    {}
Exception: "Exception('No Conformers')"

slurmstepd: error: *** JOB 19761822 ON sb006 CANCELLED AT 2024-01-16T12:18:12 ***
