hostname sb014.cluster
ipconfig 1: lo: <LOOPBACK,UP,LOWER_UP> mtu 65536 qdisc noqueue state UNKNOWN group default qlen 1000 link/loopback 00:00:00:00:00:00 brd 00:00:00:00:00:00 inet 127.0.0.1/8 scope host lo valid_lft forever preferred_lft forever inet6 ::1/128 scope host valid_lft forever preferred_lft forever 2: enp4s0f0: <BROADCAST,MULTICAST,UP,LOWER_UP> mtu 9000 qdisc mq state UP group default qlen 1000 link/ether a0:8c:f8:61:07:aa brd ff:ff:ff:ff:ff:ff inet 10.3.81.94/22 brd 10.3.83.255 scope global enp4s0f0 valid_lft forever preferred_lft forever inet6 fe80::a28c:f8ff:fe61:7aa/64 scope link valid_lft forever preferred_lft forever 3: enp4s0f1: <BROADCAST,MULTICAST> mtu 1500 qdisc noop state DOWN group default qlen 1000 link/ether a0:8c:f8:61:07:ab brd ff:ff:ff:ff:ff:ff 4: enp4s0f2: <BROADCAST,MULTICAST> mtu 1500 qdisc noop state DOWN group default qlen 1000 link/ether a0:8c:f8:61:07:ac brd ff:ff:ff:ff:ff:ff 5: enp4s0f3: <BROADCAST,MULTICAST> mtu 1500 qdisc noop state DOWN group default qlen 1000 link/ether a0:8c:f8:61:07:ad brd ff:ff:ff:ff:ff:ff 6: ib0: <BROADCAST,MULTICAST,UP,LOWER_UP> mtu 4092 qdisc pfifo_fast state UP group default qlen 256 link/infiniband 80:00:00:29:fe:80:00:00:00:00:00:00:38:bc:01:03:00:4c:f4:10 brd 00:ff:ff:ff:ff:12:40:1b:ff:ff:00:00:00:00:00:00:ff:ff:ff:ff inet 10.3.89.94/22 brd 10.3.91.255 scope global ib0 valid_lft forever preferred_lft forever inet 10.3.97.94/22 brd 10.3.99.255 scope global ib0:1 valid_lft forever preferred_lft forever inet6 fe80::3abc:103:4c:f410/64 scope link valid_lft forever preferred_lft forever 7: ib1: <BROADCAST,MULTICAST> mtu 4092 qdisc noop state DOWN group default qlen 256 link/infiniband 80:00:00:29:fe:80:00:00:00:00:00:00:38:bc:01:03:00:4c:f4:11 brd 00:ff:ff:ff:ff:12:40:1b:ff:ff:00:00:00:00:00:00:ff:ff:ff:ff
2024-01-16 11:48:21,239 - distributed.nanny - INFO -         Start Nanny at: 'tcp://10.3.89.94:33521'
2024-01-16 11:48:21,405 - distributed.nanny - INFO -         Start Nanny at: 'tcp://10.3.89.94:34331'
2024-01-16 11:49:30,469 - distributed.worker - INFO -       Start worker at:     tcp://10.3.89.94:35772
2024-01-16 11:49:30,469 - distributed.worker - INFO -       Start worker at:     tcp://10.3.89.94:38435
2024-01-16 11:49:30,470 - distributed.worker - INFO -          Listening to:     tcp://10.3.89.94:35772
2024-01-16 11:49:30,470 - distributed.worker - INFO -          Listening to:     tcp://10.3.89.94:38435
2024-01-16 11:49:30,470 - distributed.worker - INFO -           Worker name:          SLURMCluster-66-0
2024-01-16 11:49:30,470 - distributed.worker - INFO -           Worker name:          SLURMCluster-66-1
2024-01-16 11:49:30,470 - distributed.worker - INFO -          dashboard at:           10.3.89.94:37783
2024-01-16 11:49:30,470 - distributed.worker - INFO -          dashboard at:           10.3.89.94:45750
2024-01-16 11:49:30,470 - distributed.worker - INFO - Waiting to connect to:     tcp://10.3.88.12:37277
2024-01-16 11:49:30,471 - distributed.worker - INFO - Waiting to connect to:     tcp://10.3.88.12:37277
2024-01-16 11:49:30,471 - distributed.worker - INFO - -------------------------------------------------
2024-01-16 11:49:30,471 - distributed.worker - INFO - -------------------------------------------------
2024-01-16 11:49:30,471 - distributed.worker - INFO -               Threads:                          2
2024-01-16 11:49:30,471 - distributed.worker - INFO -               Threads:                          2
2024-01-16 11:49:30,471 - distributed.worker - INFO -                Memory:                  10.24 GiB
2024-01-16 11:49:30,471 - distributed.worker - INFO -                Memory:                  10.24 GiB
2024-01-16 11:49:30,471 - distributed.worker - INFO -       Local Directory: /scratch/dask-worker-space/worker-6fq65uio
2024-01-16 11:49:30,471 - distributed.worker - INFO -       Local Directory: /scratch/dask-worker-space/worker-l9nitwbk
2024-01-16 11:49:30,471 - distributed.worker - INFO - -------------------------------------------------
2024-01-16 11:49:30,471 - distributed.worker - INFO - -------------------------------------------------
2024-01-16 11:49:30,796 - distributed.worker - INFO -         Registered to:     tcp://10.3.88.12:37277
2024-01-16 11:49:30,796 - distributed.worker - INFO - -------------------------------------------------
2024-01-16 11:49:30,797 - distributed.core - INFO - Starting established connection to tcp://10.3.88.12:37277
2024-01-16 11:49:30,799 - distributed.worker - INFO -         Registered to:     tcp://10.3.88.12:37277
2024-01-16 11:49:30,800 - distributed.worker - INFO - -------------------------------------------------
2024-01-16 11:49:30,800 - distributed.core - INFO - Starting established connection to tcp://10.3.88.12:37277
2024-01-16 11:50:12,408 - distributed.worker - ERROR - Worker stream died during communication: tcp://10.3.89.122:39675
Traceback (most recent call last):
  File "/mnt/storage/nobackup/nmb1063/mamba/envs/fegrow/lib/python3.9/site-packages/distributed/comm/tcp.py", line 225, in read
    frames_nbytes = await stream.read_bytes(fmt_size)
asyncio.exceptions.CancelledError

During handling of the above exception, another exception occurred:

Traceback (most recent call last):
  File "/mnt/storage/nobackup/nmb1063/mamba/envs/fegrow/lib/python3.9/asyncio/tasks.py", line 490, in wait_for
    return fut.result()
asyncio.exceptions.CancelledError

The above exception was the direct cause of the following exception:

Traceback (most recent call last):
  File "/mnt/storage/nobackup/nmb1063/mamba/envs/fegrow/lib/python3.9/site-packages/distributed/comm/core.py", line 328, in connect
    handshake = await asyncio.wait_for(comm.read(), time_left())
  File "/mnt/storage/nobackup/nmb1063/mamba/envs/fegrow/lib/python3.9/asyncio/tasks.py", line 492, in wait_for
    raise exceptions.TimeoutError() from exc
asyncio.exceptions.TimeoutError

The above exception was the direct cause of the following exception:

Traceback (most recent call last):
  File "/mnt/storage/nobackup/nmb1063/mamba/envs/fegrow/lib/python3.9/site-packages/distributed/worker.py", line 2081, in gather_dep
    response = await get_data_from_worker(
  File "/mnt/storage/nobackup/nmb1063/mamba/envs/fegrow/lib/python3.9/site-packages/distributed/worker.py", line 2900, in get_data_from_worker
    comm = await rpc.connect(worker)
  File "/mnt/storage/nobackup/nmb1063/mamba/envs/fegrow/lib/python3.9/site-packages/distributed/core.py", line 1468, in connect
    return await connect_attempt
  File "/mnt/storage/nobackup/nmb1063/mamba/envs/fegrow/lib/python3.9/site-packages/distributed/core.py", line 1389, in _connect
    comm = await connect(
  File "/mnt/storage/nobackup/nmb1063/mamba/envs/fegrow/lib/python3.9/site-packages/distributed/comm/core.py", line 333, in connect
    raise OSError(
OSError: Timed out during handshake while connecting to tcp://10.3.89.122:39675 after 30 s
2024-01-16 11:50:12,409 - distributed.worker - ERROR - Worker stream died during communication: tcp://10.3.89.122:39675
Traceback (most recent call last):
  File "/mnt/storage/nobackup/nmb1063/mamba/envs/fegrow/lib/python3.9/site-packages/distributed/comm/tcp.py", line 225, in read
    frames_nbytes = await stream.read_bytes(fmt_size)
asyncio.exceptions.CancelledError

During handling of the above exception, another exception occurred:

Traceback (most recent call last):
  File "/mnt/storage/nobackup/nmb1063/mamba/envs/fegrow/lib/python3.9/asyncio/tasks.py", line 490, in wait_for
    return fut.result()
asyncio.exceptions.CancelledError

The above exception was the direct cause of the following exception:

Traceback (most recent call last):
  File "/mnt/storage/nobackup/nmb1063/mamba/envs/fegrow/lib/python3.9/site-packages/distributed/comm/core.py", line 328, in connect
    handshake = await asyncio.wait_for(comm.read(), time_left())
  File "/mnt/storage/nobackup/nmb1063/mamba/envs/fegrow/lib/python3.9/asyncio/tasks.py", line 492, in wait_for
    raise exceptions.TimeoutError() from exc
asyncio.exceptions.TimeoutError

The above exception was the direct cause of the following exception:

Traceback (most recent call last):
  File "/mnt/storage/nobackup/nmb1063/mamba/envs/fegrow/lib/python3.9/site-packages/distributed/worker.py", line 2081, in gather_dep
    response = await get_data_from_worker(
  File "/mnt/storage/nobackup/nmb1063/mamba/envs/fegrow/lib/python3.9/site-packages/distributed/worker.py", line 2900, in get_data_from_worker
    comm = await rpc.connect(worker)
  File "/mnt/storage/nobackup/nmb1063/mamba/envs/fegrow/lib/python3.9/site-packages/distributed/core.py", line 1468, in connect
    return await connect_attempt
  File "/mnt/storage/nobackup/nmb1063/mamba/envs/fegrow/lib/python3.9/site-packages/distributed/core.py", line 1389, in _connect
    comm = await connect(
  File "/mnt/storage/nobackup/nmb1063/mamba/envs/fegrow/lib/python3.9/site-packages/distributed/comm/core.py", line 333, in connect
    raise OSError(
OSError: Timed out during handshake while connecting to tcp://10.3.89.122:39675 after 30 s
2024-01-16 11:50:42,803 - distributed.worker - ERROR - Worker stream died during communication: tcp://10.3.89.122:39675
Traceback (most recent call last):
  File "/mnt/storage/nobackup/nmb1063/mamba/envs/fegrow/lib/python3.9/site-packages/distributed/comm/tcp.py", line 225, in read
    frames_nbytes = await stream.read_bytes(fmt_size)
asyncio.exceptions.CancelledError

During handling of the above exception, another exception occurred:

Traceback (most recent call last):
  File "/mnt/storage/nobackup/nmb1063/mamba/envs/fegrow/lib/python3.9/asyncio/tasks.py", line 490, in wait_for
    return fut.result()
asyncio.exceptions.CancelledError

The above exception was the direct cause of the following exception:

Traceback (most recent call last):
  File "/mnt/storage/nobackup/nmb1063/mamba/envs/fegrow/lib/python3.9/site-packages/distributed/comm/core.py", line 328, in connect
    handshake = await asyncio.wait_for(comm.read(), time_left())
  File "/mnt/storage/nobackup/nmb1063/mamba/envs/fegrow/lib/python3.9/asyncio/tasks.py", line 492, in wait_for
    raise exceptions.TimeoutError() from exc
asyncio.exceptions.TimeoutError

The above exception was the direct cause of the following exception:

Traceback (most recent call last):
  File "/mnt/storage/nobackup/nmb1063/mamba/envs/fegrow/lib/python3.9/site-packages/distributed/worker.py", line 2081, in gather_dep
    response = await get_data_from_worker(
  File "/mnt/storage/nobackup/nmb1063/mamba/envs/fegrow/lib/python3.9/site-packages/distributed/worker.py", line 2900, in get_data_from_worker
    comm = await rpc.connect(worker)
  File "/mnt/storage/nobackup/nmb1063/mamba/envs/fegrow/lib/python3.9/site-packages/distributed/core.py", line 1468, in connect
    return await connect_attempt
  File "/mnt/storage/nobackup/nmb1063/mamba/envs/fegrow/lib/python3.9/site-packages/distributed/core.py", line 1389, in _connect
    comm = await connect(
  File "/mnt/storage/nobackup/nmb1063/mamba/envs/fegrow/lib/python3.9/site-packages/distributed/comm/core.py", line 333, in connect
    raise OSError(
OSError: Timed out during handshake while connecting to tcp://10.3.89.122:39675 after 30 s
2024-01-16 11:50:42,806 - distributed.worker - ERROR - Worker stream died during communication: tcp://10.3.89.122:39675
Traceback (most recent call last):
  File "/mnt/storage/nobackup/nmb1063/mamba/envs/fegrow/lib/python3.9/site-packages/distributed/comm/tcp.py", line 225, in read
    frames_nbytes = await stream.read_bytes(fmt_size)
asyncio.exceptions.CancelledError

During handling of the above exception, another exception occurred:

Traceback (most recent call last):
  File "/mnt/storage/nobackup/nmb1063/mamba/envs/fegrow/lib/python3.9/asyncio/tasks.py", line 490, in wait_for
    return fut.result()
asyncio.exceptions.CancelledError

The above exception was the direct cause of the following exception:

Traceback (most recent call last):
  File "/mnt/storage/nobackup/nmb1063/mamba/envs/fegrow/lib/python3.9/site-packages/distributed/comm/core.py", line 328, in connect
    handshake = await asyncio.wait_for(comm.read(), time_left())
  File "/mnt/storage/nobackup/nmb1063/mamba/envs/fegrow/lib/python3.9/asyncio/tasks.py", line 492, in wait_for
    raise exceptions.TimeoutError() from exc
asyncio.exceptions.TimeoutError

The above exception was the direct cause of the following exception:

Traceback (most recent call last):
  File "/mnt/storage/nobackup/nmb1063/mamba/envs/fegrow/lib/python3.9/site-packages/distributed/worker.py", line 2081, in gather_dep
    response = await get_data_from_worker(
  File "/mnt/storage/nobackup/nmb1063/mamba/envs/fegrow/lib/python3.9/site-packages/distributed/worker.py", line 2900, in get_data_from_worker
    comm = await rpc.connect(worker)
  File "/mnt/storage/nobackup/nmb1063/mamba/envs/fegrow/lib/python3.9/site-packages/distributed/core.py", line 1468, in connect
    return await connect_attempt
  File "/mnt/storage/nobackup/nmb1063/mamba/envs/fegrow/lib/python3.9/site-packages/distributed/core.py", line 1389, in _connect
    comm = await connect(
  File "/mnt/storage/nobackup/nmb1063/mamba/envs/fegrow/lib/python3.9/site-packages/distributed/comm/core.py", line 333, in connect
    raise OSError(
OSError: Timed out during handshake while connecting to tcp://10.3.89.122:39675 after 30 s
2024-01-16 11:51:13,806 - distributed.worker - ERROR - Worker stream died during communication: tcp://10.3.89.122:39675
Traceback (most recent call last):
  File "/mnt/storage/nobackup/nmb1063/mamba/envs/fegrow/lib/python3.9/site-packages/distributed/comm/tcp.py", line 225, in read
    frames_nbytes = await stream.read_bytes(fmt_size)
asyncio.exceptions.CancelledError

During handling of the above exception, another exception occurred:

Traceback (most recent call last):
  File "/mnt/storage/nobackup/nmb1063/mamba/envs/fegrow/lib/python3.9/asyncio/tasks.py", line 490, in wait_for
    return fut.result()
asyncio.exceptions.CancelledError

The above exception was the direct cause of the following exception:

Traceback (most recent call last):
  File "/mnt/storage/nobackup/nmb1063/mamba/envs/fegrow/lib/python3.9/site-packages/distributed/comm/core.py", line 328, in connect
    handshake = await asyncio.wait_for(comm.read(), time_left())
  File "/mnt/storage/nobackup/nmb1063/mamba/envs/fegrow/lib/python3.9/asyncio/tasks.py", line 492, in wait_for
    raise exceptions.TimeoutError() from exc
asyncio.exceptions.TimeoutError

The above exception was the direct cause of the following exception:

Traceback (most recent call last):
  File "/mnt/storage/nobackup/nmb1063/mamba/envs/fegrow/lib/python3.9/site-packages/distributed/worker.py", line 2081, in gather_dep
    response = await get_data_from_worker(
  File "/mnt/storage/nobackup/nmb1063/mamba/envs/fegrow/lib/python3.9/site-packages/distributed/worker.py", line 2900, in get_data_from_worker
    comm = await rpc.connect(worker)
  File "/mnt/storage/nobackup/nmb1063/mamba/envs/fegrow/lib/python3.9/site-packages/distributed/core.py", line 1468, in connect
    return await connect_attempt
  File "/mnt/storage/nobackup/nmb1063/mamba/envs/fegrow/lib/python3.9/site-packages/distributed/core.py", line 1389, in _connect
    comm = await connect(
  File "/mnt/storage/nobackup/nmb1063/mamba/envs/fegrow/lib/python3.9/site-packages/distributed/comm/core.py", line 333, in connect
    raise OSError(
OSError: Timed out during handshake while connecting to tcp://10.3.89.122:39675 after 30 s
2024-01-16 11:51:13,803 - distributed.worker - ERROR - Worker stream died during communication: tcp://10.3.89.122:39675
Traceback (most recent call last):
  File "/mnt/storage/nobackup/nmb1063/mamba/envs/fegrow/lib/python3.9/site-packages/distributed/comm/tcp.py", line 225, in read
    frames_nbytes = await stream.read_bytes(fmt_size)
asyncio.exceptions.CancelledError

During handling of the above exception, another exception occurred:

Traceback (most recent call last):
  File "/mnt/storage/nobackup/nmb1063/mamba/envs/fegrow/lib/python3.9/asyncio/tasks.py", line 490, in wait_for
    return fut.result()
asyncio.exceptions.CancelledError

The above exception was the direct cause of the following exception:

Traceback (most recent call last):
  File "/mnt/storage/nobackup/nmb1063/mamba/envs/fegrow/lib/python3.9/site-packages/distributed/comm/core.py", line 328, in connect
    handshake = await asyncio.wait_for(comm.read(), time_left())
  File "/mnt/storage/nobackup/nmb1063/mamba/envs/fegrow/lib/python3.9/asyncio/tasks.py", line 492, in wait_for
    raise exceptions.TimeoutError() from exc
asyncio.exceptions.TimeoutError

The above exception was the direct cause of the following exception:

Traceback (most recent call last):
  File "/mnt/storage/nobackup/nmb1063/mamba/envs/fegrow/lib/python3.9/site-packages/distributed/worker.py", line 2081, in gather_dep
    response = await get_data_from_worker(
  File "/mnt/storage/nobackup/nmb1063/mamba/envs/fegrow/lib/python3.9/site-packages/distributed/worker.py", line 2900, in get_data_from_worker
    comm = await rpc.connect(worker)
  File "/mnt/storage/nobackup/nmb1063/mamba/envs/fegrow/lib/python3.9/site-packages/distributed/core.py", line 1468, in connect
    return await connect_attempt
  File "/mnt/storage/nobackup/nmb1063/mamba/envs/fegrow/lib/python3.9/site-packages/distributed/core.py", line 1389, in _connect
    comm = await connect(
  File "/mnt/storage/nobackup/nmb1063/mamba/envs/fegrow/lib/python3.9/site-packages/distributed/comm/core.py", line 333, in connect
    raise OSError(
OSError: Timed out during handshake while connecting to tcp://10.3.89.122:39675 after 30 s
2024-01-16 11:51:44,805 - distributed.worker - ERROR - Worker stream died during communication: tcp://10.3.89.122:39675
Traceback (most recent call last):
  File "/mnt/storage/nobackup/nmb1063/mamba/envs/fegrow/lib/python3.9/site-packages/distributed/comm/tcp.py", line 225, in read
    frames_nbytes = await stream.read_bytes(fmt_size)
asyncio.exceptions.CancelledError

During handling of the above exception, another exception occurred:

Traceback (most recent call last):
  File "/mnt/storage/nobackup/nmb1063/mamba/envs/fegrow/lib/python3.9/asyncio/tasks.py", line 490, in wait_for
    return fut.result()
asyncio.exceptions.CancelledError

The above exception was the direct cause of the following exception:

Traceback (most recent call last):
  File "/mnt/storage/nobackup/nmb1063/mamba/envs/fegrow/lib/python3.9/site-packages/distributed/comm/core.py", line 328, in connect
    handshake = await asyncio.wait_for(comm.read(), time_left())
  File "/mnt/storage/nobackup/nmb1063/mamba/envs/fegrow/lib/python3.9/asyncio/tasks.py", line 492, in wait_for
    raise exceptions.TimeoutError() from exc
asyncio.exceptions.TimeoutError

The above exception was the direct cause of the following exception:

Traceback (most recent call last):
  File "/mnt/storage/nobackup/nmb1063/mamba/envs/fegrow/lib/python3.9/site-packages/distributed/worker.py", line 2081, in gather_dep
    response = await get_data_from_worker(
  File "/mnt/storage/nobackup/nmb1063/mamba/envs/fegrow/lib/python3.9/site-packages/distributed/worker.py", line 2900, in get_data_from_worker
    comm = await rpc.connect(worker)
  File "/mnt/storage/nobackup/nmb1063/mamba/envs/fegrow/lib/python3.9/site-packages/distributed/core.py", line 1468, in connect
    return await connect_attempt
  File "/mnt/storage/nobackup/nmb1063/mamba/envs/fegrow/lib/python3.9/site-packages/distributed/core.py", line 1389, in _connect
    comm = await connect(
  File "/mnt/storage/nobackup/nmb1063/mamba/envs/fegrow/lib/python3.9/site-packages/distributed/comm/core.py", line 333, in connect
    raise OSError(
OSError: Timed out during handshake while connecting to tcp://10.3.89.122:39675 after 30 s
2024-01-16 11:51:44,801 - distributed.worker - ERROR - Worker stream died during communication: tcp://10.3.89.122:39675
Traceback (most recent call last):
  File "/mnt/storage/nobackup/nmb1063/mamba/envs/fegrow/lib/python3.9/site-packages/distributed/comm/tcp.py", line 225, in read
    frames_nbytes = await stream.read_bytes(fmt_size)
asyncio.exceptions.CancelledError

During handling of the above exception, another exception occurred:

Traceback (most recent call last):
  File "/mnt/storage/nobackup/nmb1063/mamba/envs/fegrow/lib/python3.9/asyncio/tasks.py", line 490, in wait_for
    return fut.result()
asyncio.exceptions.CancelledError

The above exception was the direct cause of the following exception:

Traceback (most recent call last):
  File "/mnt/storage/nobackup/nmb1063/mamba/envs/fegrow/lib/python3.9/site-packages/distributed/comm/core.py", line 328, in connect
    handshake = await asyncio.wait_for(comm.read(), time_left())
  File "/mnt/storage/nobackup/nmb1063/mamba/envs/fegrow/lib/python3.9/asyncio/tasks.py", line 492, in wait_for
    raise exceptions.TimeoutError() from exc
asyncio.exceptions.TimeoutError

The above exception was the direct cause of the following exception:

Traceback (most recent call last):
  File "/mnt/storage/nobackup/nmb1063/mamba/envs/fegrow/lib/python3.9/site-packages/distributed/worker.py", line 2081, in gather_dep
    response = await get_data_from_worker(
  File "/mnt/storage/nobackup/nmb1063/mamba/envs/fegrow/lib/python3.9/site-packages/distributed/worker.py", line 2900, in get_data_from_worker
    comm = await rpc.connect(worker)
  File "/mnt/storage/nobackup/nmb1063/mamba/envs/fegrow/lib/python3.9/site-packages/distributed/core.py", line 1468, in connect
    return await connect_attempt
  File "/mnt/storage/nobackup/nmb1063/mamba/envs/fegrow/lib/python3.9/site-packages/distributed/core.py", line 1389, in _connect
    comm = await connect(
  File "/mnt/storage/nobackup/nmb1063/mamba/envs/fegrow/lib/python3.9/site-packages/distributed/comm/core.py", line 333, in connect
    raise OSError(
OSError: Timed out during handshake while connecting to tcp://10.3.89.122:39675 after 30 s
2024-01-16 11:52:15,801 - distributed.worker - ERROR - Worker stream died during communication: tcp://10.3.89.122:39675
Traceback (most recent call last):
  File "/mnt/storage/nobackup/nmb1063/mamba/envs/fegrow/lib/python3.9/site-packages/distributed/comm/tcp.py", line 225, in read
    frames_nbytes = await stream.read_bytes(fmt_size)
asyncio.exceptions.CancelledError

During handling of the above exception, another exception occurred:

Traceback (most recent call last):
  File "/mnt/storage/nobackup/nmb1063/mamba/envs/fegrow/lib/python3.9/asyncio/tasks.py", line 490, in wait_for
    return fut.result()
asyncio.exceptions.CancelledError

The above exception was the direct cause of the following exception:

Traceback (most recent call last):
  File "/mnt/storage/nobackup/nmb1063/mamba/envs/fegrow/lib/python3.9/site-packages/distributed/comm/core.py", line 328, in connect
    handshake = await asyncio.wait_for(comm.read(), time_left())
  File "/mnt/storage/nobackup/nmb1063/mamba/envs/fegrow/lib/python3.9/asyncio/tasks.py", line 492, in wait_for
    raise exceptions.TimeoutError() from exc
asyncio.exceptions.TimeoutError

The above exception was the direct cause of the following exception:

Traceback (most recent call last):
  File "/mnt/storage/nobackup/nmb1063/mamba/envs/fegrow/lib/python3.9/site-packages/distributed/worker.py", line 2081, in gather_dep
    response = await get_data_from_worker(
  File "/mnt/storage/nobackup/nmb1063/mamba/envs/fegrow/lib/python3.9/site-packages/distributed/worker.py", line 2900, in get_data_from_worker
    comm = await rpc.connect(worker)
  File "/mnt/storage/nobackup/nmb1063/mamba/envs/fegrow/lib/python3.9/site-packages/distributed/core.py", line 1468, in connect
    return await connect_attempt
  File "/mnt/storage/nobackup/nmb1063/mamba/envs/fegrow/lib/python3.9/site-packages/distributed/core.py", line 1389, in _connect
    comm = await connect(
  File "/mnt/storage/nobackup/nmb1063/mamba/envs/fegrow/lib/python3.9/site-packages/distributed/comm/core.py", line 333, in connect
    raise OSError(
OSError: Timed out during handshake while connecting to tcp://10.3.89.122:39675 after 30 s
2024-01-16 11:52:15,806 - distributed.worker - ERROR - Worker stream died during communication: tcp://10.3.89.122:39675
Traceback (most recent call last):
  File "/mnt/storage/nobackup/nmb1063/mamba/envs/fegrow/lib/python3.9/site-packages/distributed/comm/tcp.py", line 225, in read
    frames_nbytes = await stream.read_bytes(fmt_size)
asyncio.exceptions.CancelledError

During handling of the above exception, another exception occurred:

Traceback (most recent call last):
  File "/mnt/storage/nobackup/nmb1063/mamba/envs/fegrow/lib/python3.9/asyncio/tasks.py", line 490, in wait_for
    return fut.result()
asyncio.exceptions.CancelledError

The above exception was the direct cause of the following exception:

Traceback (most recent call last):
  File "/mnt/storage/nobackup/nmb1063/mamba/envs/fegrow/lib/python3.9/site-packages/distributed/comm/core.py", line 328, in connect
    handshake = await asyncio.wait_for(comm.read(), time_left())
  File "/mnt/storage/nobackup/nmb1063/mamba/envs/fegrow/lib/python3.9/asyncio/tasks.py", line 492, in wait_for
    raise exceptions.TimeoutError() from exc
asyncio.exceptions.TimeoutError

The above exception was the direct cause of the following exception:

Traceback (most recent call last):
  File "/mnt/storage/nobackup/nmb1063/mamba/envs/fegrow/lib/python3.9/site-packages/distributed/worker.py", line 2081, in gather_dep
    response = await get_data_from_worker(
  File "/mnt/storage/nobackup/nmb1063/mamba/envs/fegrow/lib/python3.9/site-packages/distributed/worker.py", line 2900, in get_data_from_worker
    comm = await rpc.connect(worker)
  File "/mnt/storage/nobackup/nmb1063/mamba/envs/fegrow/lib/python3.9/site-packages/distributed/core.py", line 1468, in connect
    return await connect_attempt
  File "/mnt/storage/nobackup/nmb1063/mamba/envs/fegrow/lib/python3.9/site-packages/distributed/core.py", line 1389, in _connect
    comm = await connect(
  File "/mnt/storage/nobackup/nmb1063/mamba/envs/fegrow/lib/python3.9/site-packages/distributed/comm/core.py", line 333, in connect
    raise OSError(
OSError: Timed out during handshake while connecting to tcp://10.3.89.122:39675 after 30 s
2024-01-16 11:52:46,805 - distributed.worker - ERROR - Worker stream died during communication: tcp://10.3.89.122:39675
Traceback (most recent call last):
  File "/mnt/storage/nobackup/nmb1063/mamba/envs/fegrow/lib/python3.9/site-packages/distributed/comm/tcp.py", line 225, in read
    frames_nbytes = await stream.read_bytes(fmt_size)
asyncio.exceptions.CancelledError

During handling of the above exception, another exception occurred:

Traceback (most recent call last):
  File "/mnt/storage/nobackup/nmb1063/mamba/envs/fegrow/lib/python3.9/asyncio/tasks.py", line 490, in wait_for
    return fut.result()
asyncio.exceptions.CancelledError

The above exception was the direct cause of the following exception:

Traceback (most recent call last):
  File "/mnt/storage/nobackup/nmb1063/mamba/envs/fegrow/lib/python3.9/site-packages/distributed/comm/core.py", line 328, in connect
    handshake = await asyncio.wait_for(comm.read(), time_left())
  File "/mnt/storage/nobackup/nmb1063/mamba/envs/fegrow/lib/python3.9/asyncio/tasks.py", line 492, in wait_for
    raise exceptions.TimeoutError() from exc
asyncio.exceptions.TimeoutError

The above exception was the direct cause of the following exception:

Traceback (most recent call last):
  File "/mnt/storage/nobackup/nmb1063/mamba/envs/fegrow/lib/python3.9/site-packages/distributed/worker.py", line 2081, in gather_dep
    response = await get_data_from_worker(
  File "/mnt/storage/nobackup/nmb1063/mamba/envs/fegrow/lib/python3.9/site-packages/distributed/worker.py", line 2900, in get_data_from_worker
    comm = await rpc.connect(worker)
  File "/mnt/storage/nobackup/nmb1063/mamba/envs/fegrow/lib/python3.9/site-packages/distributed/core.py", line 1468, in connect
    return await connect_attempt
  File "/mnt/storage/nobackup/nmb1063/mamba/envs/fegrow/lib/python3.9/site-packages/distributed/core.py", line 1389, in _connect
    comm = await connect(
  File "/mnt/storage/nobackup/nmb1063/mamba/envs/fegrow/lib/python3.9/site-packages/distributed/comm/core.py", line 333, in connect
    raise OSError(
OSError: Timed out during handshake while connecting to tcp://10.3.89.122:39675 after 30 s
2024-01-16 11:52:46,803 - distributed.worker - ERROR - Worker stream died during communication: tcp://10.3.89.122:39675
Traceback (most recent call last):
  File "/mnt/storage/nobackup/nmb1063/mamba/envs/fegrow/lib/python3.9/site-packages/distributed/comm/tcp.py", line 225, in read
    frames_nbytes = await stream.read_bytes(fmt_size)
asyncio.exceptions.CancelledError

During handling of the above exception, another exception occurred:

Traceback (most recent call last):
  File "/mnt/storage/nobackup/nmb1063/mamba/envs/fegrow/lib/python3.9/asyncio/tasks.py", line 490, in wait_for
    return fut.result()
asyncio.exceptions.CancelledError

The above exception was the direct cause of the following exception:

Traceback (most recent call last):
  File "/mnt/storage/nobackup/nmb1063/mamba/envs/fegrow/lib/python3.9/site-packages/distributed/comm/core.py", line 328, in connect
    handshake = await asyncio.wait_for(comm.read(), time_left())
  File "/mnt/storage/nobackup/nmb1063/mamba/envs/fegrow/lib/python3.9/asyncio/tasks.py", line 492, in wait_for
    raise exceptions.TimeoutError() from exc
asyncio.exceptions.TimeoutError

The above exception was the direct cause of the following exception:

Traceback (most recent call last):
  File "/mnt/storage/nobackup/nmb1063/mamba/envs/fegrow/lib/python3.9/site-packages/distributed/worker.py", line 2081, in gather_dep
    response = await get_data_from_worker(
  File "/mnt/storage/nobackup/nmb1063/mamba/envs/fegrow/lib/python3.9/site-packages/distributed/worker.py", line 2900, in get_data_from_worker
    comm = await rpc.connect(worker)
  File "/mnt/storage/nobackup/nmb1063/mamba/envs/fegrow/lib/python3.9/site-packages/distributed/core.py", line 1468, in connect
    return await connect_attempt
  File "/mnt/storage/nobackup/nmb1063/mamba/envs/fegrow/lib/python3.9/site-packages/distributed/core.py", line 1389, in _connect
    comm = await connect(
  File "/mnt/storage/nobackup/nmb1063/mamba/envs/fegrow/lib/python3.9/site-packages/distributed/comm/core.py", line 333, in connect
    raise OSError(
OSError: Timed out during handshake while connecting to tcp://10.3.89.122:39675 after 30 s
2024-01-16 11:53:17,802 - distributed.worker - ERROR - Worker stream died during communication: tcp://10.3.89.122:39675
Traceback (most recent call last):
  File "/mnt/storage/nobackup/nmb1063/mamba/envs/fegrow/lib/python3.9/site-packages/distributed/comm/tcp.py", line 225, in read
    frames_nbytes = await stream.read_bytes(fmt_size)
asyncio.exceptions.CancelledError

During handling of the above exception, another exception occurred:

Traceback (most recent call last):
  File "/mnt/storage/nobackup/nmb1063/mamba/envs/fegrow/lib/python3.9/asyncio/tasks.py", line 490, in wait_for
    return fut.result()
asyncio.exceptions.CancelledError

The above exception was the direct cause of the following exception:

Traceback (most recent call last):
  File "/mnt/storage/nobackup/nmb1063/mamba/envs/fegrow/lib/python3.9/site-packages/distributed/comm/core.py", line 328, in connect
    handshake = await asyncio.wait_for(comm.read(), time_left())
  File "/mnt/storage/nobackup/nmb1063/mamba/envs/fegrow/lib/python3.9/asyncio/tasks.py", line 492, in wait_for
    raise exceptions.TimeoutError() from exc
asyncio.exceptions.TimeoutError

The above exception was the direct cause of the following exception:

Traceback (most recent call last):
  File "/mnt/storage/nobackup/nmb1063/mamba/envs/fegrow/lib/python3.9/site-packages/distributed/worker.py", line 2081, in gather_dep
    response = await get_data_from_worker(
  File "/mnt/storage/nobackup/nmb1063/mamba/envs/fegrow/lib/python3.9/site-packages/distributed/worker.py", line 2900, in get_data_from_worker
    comm = await rpc.connect(worker)
  File "/mnt/storage/nobackup/nmb1063/mamba/envs/fegrow/lib/python3.9/site-packages/distributed/core.py", line 1468, in connect
    return await connect_attempt
  File "/mnt/storage/nobackup/nmb1063/mamba/envs/fegrow/lib/python3.9/site-packages/distributed/core.py", line 1389, in _connect
    comm = await connect(
  File "/mnt/storage/nobackup/nmb1063/mamba/envs/fegrow/lib/python3.9/site-packages/distributed/comm/core.py", line 333, in connect
    raise OSError(
OSError: Timed out during handshake while connecting to tcp://10.3.89.122:39675 after 30 s
2024-01-16 11:53:17,804 - distributed.worker - ERROR - Worker stream died during communication: tcp://10.3.89.122:39675
Traceback (most recent call last):
  File "/mnt/storage/nobackup/nmb1063/mamba/envs/fegrow/lib/python3.9/site-packages/distributed/comm/tcp.py", line 225, in read
    frames_nbytes = await stream.read_bytes(fmt_size)
asyncio.exceptions.CancelledError

During handling of the above exception, another exception occurred:

Traceback (most recent call last):
  File "/mnt/storage/nobackup/nmb1063/mamba/envs/fegrow/lib/python3.9/asyncio/tasks.py", line 490, in wait_for
    return fut.result()
asyncio.exceptions.CancelledError

The above exception was the direct cause of the following exception:

Traceback (most recent call last):
  File "/mnt/storage/nobackup/nmb1063/mamba/envs/fegrow/lib/python3.9/site-packages/distributed/comm/core.py", line 328, in connect
    handshake = await asyncio.wait_for(comm.read(), time_left())
  File "/mnt/storage/nobackup/nmb1063/mamba/envs/fegrow/lib/python3.9/asyncio/tasks.py", line 492, in wait_for
    raise exceptions.TimeoutError() from exc
asyncio.exceptions.TimeoutError

The above exception was the direct cause of the following exception:

Traceback (most recent call last):
  File "/mnt/storage/nobackup/nmb1063/mamba/envs/fegrow/lib/python3.9/site-packages/distributed/worker.py", line 2081, in gather_dep
    response = await get_data_from_worker(
  File "/mnt/storage/nobackup/nmb1063/mamba/envs/fegrow/lib/python3.9/site-packages/distributed/worker.py", line 2900, in get_data_from_worker
    comm = await rpc.connect(worker)
  File "/mnt/storage/nobackup/nmb1063/mamba/envs/fegrow/lib/python3.9/site-packages/distributed/core.py", line 1468, in connect
    return await connect_attempt
  File "/mnt/storage/nobackup/nmb1063/mamba/envs/fegrow/lib/python3.9/site-packages/distributed/core.py", line 1389, in _connect
    comm = await connect(
  File "/mnt/storage/nobackup/nmb1063/mamba/envs/fegrow/lib/python3.9/site-packages/distributed/comm/core.py", line 333, in connect
    raise OSError(
OSError: Timed out during handshake while connecting to tcp://10.3.89.122:39675 after 30 s
2024-01-16 11:53:48,806 - distributed.worker - ERROR - Worker stream died during communication: tcp://10.3.89.122:39675
Traceback (most recent call last):
  File "/mnt/storage/nobackup/nmb1063/mamba/envs/fegrow/lib/python3.9/site-packages/distributed/comm/tcp.py", line 225, in read
    frames_nbytes = await stream.read_bytes(fmt_size)
asyncio.exceptions.CancelledError

During handling of the above exception, another exception occurred:

Traceback (most recent call last):
  File "/mnt/storage/nobackup/nmb1063/mamba/envs/fegrow/lib/python3.9/asyncio/tasks.py", line 490, in wait_for
    return fut.result()
asyncio.exceptions.CancelledError

The above exception was the direct cause of the following exception:

Traceback (most recent call last):
  File "/mnt/storage/nobackup/nmb1063/mamba/envs/fegrow/lib/python3.9/site-packages/distributed/comm/core.py", line 328, in connect
    handshake = await asyncio.wait_for(comm.read(), time_left())
  File "/mnt/storage/nobackup/nmb1063/mamba/envs/fegrow/lib/python3.9/asyncio/tasks.py", line 492, in wait_for
    raise exceptions.TimeoutError() from exc
asyncio.exceptions.TimeoutError

The above exception was the direct cause of the following exception:

Traceback (most recent call last):
  File "/mnt/storage/nobackup/nmb1063/mamba/envs/fegrow/lib/python3.9/site-packages/distributed/worker.py", line 2081, in gather_dep
    response = await get_data_from_worker(
  File "/mnt/storage/nobackup/nmb1063/mamba/envs/fegrow/lib/python3.9/site-packages/distributed/worker.py", line 2900, in get_data_from_worker
    comm = await rpc.connect(worker)
  File "/mnt/storage/nobackup/nmb1063/mamba/envs/fegrow/lib/python3.9/site-packages/distributed/core.py", line 1468, in connect
    return await connect_attempt
  File "/mnt/storage/nobackup/nmb1063/mamba/envs/fegrow/lib/python3.9/site-packages/distributed/core.py", line 1389, in _connect
    comm = await connect(
  File "/mnt/storage/nobackup/nmb1063/mamba/envs/fegrow/lib/python3.9/site-packages/distributed/comm/core.py", line 333, in connect
    raise OSError(
OSError: Timed out during handshake while connecting to tcp://10.3.89.122:39675 after 30 s
2024-01-16 11:53:48,804 - distributed.worker - ERROR - Worker stream died during communication: tcp://10.3.89.122:39675
Traceback (most recent call last):
  File "/mnt/storage/nobackup/nmb1063/mamba/envs/fegrow/lib/python3.9/site-packages/distributed/comm/tcp.py", line 225, in read
    frames_nbytes = await stream.read_bytes(fmt_size)
asyncio.exceptions.CancelledError

During handling of the above exception, another exception occurred:

Traceback (most recent call last):
  File "/mnt/storage/nobackup/nmb1063/mamba/envs/fegrow/lib/python3.9/asyncio/tasks.py", line 490, in wait_for
    return fut.result()
asyncio.exceptions.CancelledError

The above exception was the direct cause of the following exception:

Traceback (most recent call last):
  File "/mnt/storage/nobackup/nmb1063/mamba/envs/fegrow/lib/python3.9/site-packages/distributed/comm/core.py", line 328, in connect
    handshake = await asyncio.wait_for(comm.read(), time_left())
  File "/mnt/storage/nobackup/nmb1063/mamba/envs/fegrow/lib/python3.9/asyncio/tasks.py", line 492, in wait_for
    raise exceptions.TimeoutError() from exc
asyncio.exceptions.TimeoutError

The above exception was the direct cause of the following exception:

Traceback (most recent call last):
  File "/mnt/storage/nobackup/nmb1063/mamba/envs/fegrow/lib/python3.9/site-packages/distributed/worker.py", line 2081, in gather_dep
    response = await get_data_from_worker(
  File "/mnt/storage/nobackup/nmb1063/mamba/envs/fegrow/lib/python3.9/site-packages/distributed/worker.py", line 2900, in get_data_from_worker
    comm = await rpc.connect(worker)
  File "/mnt/storage/nobackup/nmb1063/mamba/envs/fegrow/lib/python3.9/site-packages/distributed/core.py", line 1468, in connect
    return await connect_attempt
  File "/mnt/storage/nobackup/nmb1063/mamba/envs/fegrow/lib/python3.9/site-packages/distributed/core.py", line 1389, in _connect
    comm = await connect(
  File "/mnt/storage/nobackup/nmb1063/mamba/envs/fegrow/lib/python3.9/site-packages/distributed/comm/core.py", line 333, in connect
    raise OSError(
OSError: Timed out during handshake while connecting to tcp://10.3.89.122:39675 after 30 s
2024-01-16 11:54:19,806 - distributed.worker - ERROR - Worker stream died during communication: tcp://10.3.89.122:39675
Traceback (most recent call last):
  File "/mnt/storage/nobackup/nmb1063/mamba/envs/fegrow/lib/python3.9/site-packages/distributed/comm/tcp.py", line 225, in read
    frames_nbytes = await stream.read_bytes(fmt_size)
asyncio.exceptions.CancelledError

During handling of the above exception, another exception occurred:

Traceback (most recent call last):
  File "/mnt/storage/nobackup/nmb1063/mamba/envs/fegrow/lib/python3.9/asyncio/tasks.py", line 490, in wait_for
    return fut.result()
asyncio.exceptions.CancelledError

The above exception was the direct cause of the following exception:

Traceback (most recent call last):
  File "/mnt/storage/nobackup/nmb1063/mamba/envs/fegrow/lib/python3.9/site-packages/distributed/comm/core.py", line 328, in connect
    handshake = await asyncio.wait_for(comm.read(), time_left())
  File "/mnt/storage/nobackup/nmb1063/mamba/envs/fegrow/lib/python3.9/asyncio/tasks.py", line 492, in wait_for
    raise exceptions.TimeoutError() from exc
asyncio.exceptions.TimeoutError

The above exception was the direct cause of the following exception:

Traceback (most recent call last):
  File "/mnt/storage/nobackup/nmb1063/mamba/envs/fegrow/lib/python3.9/site-packages/distributed/worker.py", line 2081, in gather_dep
    response = await get_data_from_worker(
  File "/mnt/storage/nobackup/nmb1063/mamba/envs/fegrow/lib/python3.9/site-packages/distributed/worker.py", line 2900, in get_data_from_worker
    comm = await rpc.connect(worker)
  File "/mnt/storage/nobackup/nmb1063/mamba/envs/fegrow/lib/python3.9/site-packages/distributed/core.py", line 1468, in connect
    return await connect_attempt
  File "/mnt/storage/nobackup/nmb1063/mamba/envs/fegrow/lib/python3.9/site-packages/distributed/core.py", line 1389, in _connect
    comm = await connect(
  File "/mnt/storage/nobackup/nmb1063/mamba/envs/fegrow/lib/python3.9/site-packages/distributed/comm/core.py", line 333, in connect
    raise OSError(
OSError: Timed out during handshake while connecting to tcp://10.3.89.122:39675 after 30 s
2024-01-16 11:54:19,804 - distributed.worker - ERROR - Worker stream died during communication: tcp://10.3.89.122:39675
Traceback (most recent call last):
  File "/mnt/storage/nobackup/nmb1063/mamba/envs/fegrow/lib/python3.9/site-packages/distributed/comm/tcp.py", line 225, in read
    frames_nbytes = await stream.read_bytes(fmt_size)
asyncio.exceptions.CancelledError

During handling of the above exception, another exception occurred:

Traceback (most recent call last):
  File "/mnt/storage/nobackup/nmb1063/mamba/envs/fegrow/lib/python3.9/asyncio/tasks.py", line 490, in wait_for
    return fut.result()
asyncio.exceptions.CancelledError

The above exception was the direct cause of the following exception:

Traceback (most recent call last):
  File "/mnt/storage/nobackup/nmb1063/mamba/envs/fegrow/lib/python3.9/site-packages/distributed/comm/core.py", line 328, in connect
    handshake = await asyncio.wait_for(comm.read(), time_left())
  File "/mnt/storage/nobackup/nmb1063/mamba/envs/fegrow/lib/python3.9/asyncio/tasks.py", line 492, in wait_for
    raise exceptions.TimeoutError() from exc
asyncio.exceptions.TimeoutError

The above exception was the direct cause of the following exception:

Traceback (most recent call last):
  File "/mnt/storage/nobackup/nmb1063/mamba/envs/fegrow/lib/python3.9/site-packages/distributed/worker.py", line 2081, in gather_dep
    response = await get_data_from_worker(
  File "/mnt/storage/nobackup/nmb1063/mamba/envs/fegrow/lib/python3.9/site-packages/distributed/worker.py", line 2900, in get_data_from_worker
    comm = await rpc.connect(worker)
  File "/mnt/storage/nobackup/nmb1063/mamba/envs/fegrow/lib/python3.9/site-packages/distributed/core.py", line 1468, in connect
    return await connect_attempt
  File "/mnt/storage/nobackup/nmb1063/mamba/envs/fegrow/lib/python3.9/site-packages/distributed/core.py", line 1389, in _connect
    comm = await connect(
  File "/mnt/storage/nobackup/nmb1063/mamba/envs/fegrow/lib/python3.9/site-packages/distributed/comm/core.py", line 333, in connect
    raise OSError(
OSError: Timed out during handshake while connecting to tcp://10.3.89.122:39675 after 30 s
2024-01-16 11:59:13,064 - distributed.core - INFO - Event loop was unresponsive in Worker for 280.44s.  This is often caused by long-running GIL-holding functions or moving large chunks of data. This can cause timeouts and instability.
2024-01-16 11:59:13,154 - distributed.core - INFO - Event loop was unresponsive in Worker for 280.70s.  This is often caused by long-running GIL-holding functions or moving large chunks of data. This can cause timeouts and instability.
Warning (not error because allow_undefined_stereo=True): RDMol has unspecified stereochemistry. Bonds with undefined stereochemistry are:
 - Bond 1 (atoms 1-2 of element (C-C)

/mnt/storage/nobackup/nmb1063/mamba/envs/fegrow/lib/python3.9/site-packages/parmed/structure.py:1775: UnitStrippedWarning: The unit of the quantity is stripped when downcasting to ndarray.
  coords = np.array(value, dtype=np.float64, copy=False, subok=True)
/mnt/storage/nobackup/nmb1063/mamba/envs/fegrow/lib/python3.9/site-packages/parmed/structure.py:1775: UnitStrippedWarning: The unit of the quantity is stripped when downcasting to ndarray.
  coords = np.array(value, dtype=np.float64, copy=False, subok=True)
Warning (not error because allow_undefined_stereo=True): RDMol has unspecified stereochemistry. Bonds with undefined stereochemistry are:
 - Bond 1 (atoms 1-2 of element (C-C)

Warning (not error because allow_undefined_stereo=True): RDMol has unspecified stereochemistry. Bonds with undefined stereochemistry are:
 - Bond 1 (atoms 1-2 of element (C-C)

Warning (not error because allow_undefined_stereo=True): RDMol has unspecified stereochemistry. Bonds with undefined stereochemistry are:
 - Bond 1 (atoms 1-2 of element (C-C)

Warning (not error because allow_undefined_stereo=True): RDMol has unspecified stereochemistry. Bonds with undefined stereochemistry are:
 - Bond 1 (atoms 1-2 of element (C-C)

Warning (not error because allow_undefined_stereo=True): RDMol has unspecified stereochemistry. Bonds with undefined stereochemistry are:
 - Bond 1 (atoms 1-2 of element (C-C)

/mnt/storage/nobackup/nmb1063/mamba/envs/fegrow/lib/python3.9/site-packages/torchani/__init__.py:55: UserWarning: Dependency not satisfied, torchani.ase will not be available
  warnings.warn("Dependency not satisfied, torchani.ase will not be available")
/mnt/storage/nobackup/nmb1063/mamba/envs/fegrow/lib/python3.9/site-packages/torchani/__init__.py:55: UserWarning: Dependency not satisfied, torchani.ase will not be available
  warnings.warn("Dependency not satisfied, torchani.ase will not be available")
2024-01-16 12:00:50,021 - distributed.core - INFO - Event loop was unresponsive in Worker for 4.42s.  This is often caused by long-running GIL-holding functions or moving large chunks of data. This can cause timeouts and instability.
2024-01-16 12:00:50,022 - distributed.core - INFO - Event loop was unresponsive in Worker for 4.42s.  This is often caused by long-running GIL-holding functions or moving large chunks of data. This can cause timeouts and instability.
Warning: importing 'simtk.openmm' is deprecated.  Import 'openmm' instead.
Warning: importing 'simtk.openmm' is deprecated.  Import 'openmm' instead.
2024-01-16 12:01:43,681 - distributed.nanny - INFO - Worker process 11011 was killed by signal 11
2024-01-16 12:01:43,687 - distributed.nanny - WARNING - Restarting worker
2024-01-16 12:01:43,788 - distributed.nanny - INFO - Worker process 11014 was killed by signal 11
2024-01-16 12:01:43,791 - distributed.nanny - WARNING - Restarting worker
2024-01-16 12:01:46,820 - distributed.worker - INFO -       Start worker at:     tcp://10.3.89.94:41448
2024-01-16 12:01:46,820 - distributed.worker - INFO -          Listening to:     tcp://10.3.89.94:41448
2024-01-16 12:01:46,820 - distributed.worker - INFO -           Worker name:          SLURMCluster-66-0
2024-01-16 12:01:46,820 - distributed.worker - INFO -          dashboard at:           10.3.89.94:36992
2024-01-16 12:01:46,820 - distributed.worker - INFO - Waiting to connect to:     tcp://10.3.88.12:37277
2024-01-16 12:01:46,820 - distributed.worker - INFO - -------------------------------------------------
2024-01-16 12:01:46,820 - distributed.worker - INFO -               Threads:                          2
2024-01-16 12:01:46,821 - distributed.worker - INFO -                Memory:                  10.24 GiB
2024-01-16 12:01:46,821 - distributed.worker - INFO -       Local Directory: /scratch/dask-worker-space/worker-0f43duoc
2024-01-16 12:01:46,821 - distributed.worker - INFO - -------------------------------------------------
2024-01-16 12:01:46,821 - distributed.worker - INFO -       Start worker at:     tcp://10.3.89.94:39667
2024-01-16 12:01:46,821 - distributed.worker - INFO -          Listening to:     tcp://10.3.89.94:39667
2024-01-16 12:01:46,821 - distributed.worker - INFO -           Worker name:          SLURMCluster-66-1
2024-01-16 12:01:46,821 - distributed.worker - INFO -          dashboard at:           10.3.89.94:45608
2024-01-16 12:01:46,821 - distributed.worker - INFO - Waiting to connect to:     tcp://10.3.88.12:37277
2024-01-16 12:01:46,821 - distributed.worker - INFO - -------------------------------------------------
2024-01-16 12:01:46,822 - distributed.worker - INFO -               Threads:                          2
2024-01-16 12:01:46,822 - distributed.worker - INFO -                Memory:                  10.24 GiB
2024-01-16 12:01:46,822 - distributed.worker - INFO -       Local Directory: /scratch/dask-worker-space/worker-pasz37c4
2024-01-16 12:01:46,822 - distributed.worker - INFO - -------------------------------------------------
2024-01-16 12:01:46,843 - distributed.worker - INFO -         Registered to:     tcp://10.3.88.12:37277
2024-01-16 12:01:46,843 - distributed.worker - INFO - -------------------------------------------------
2024-01-16 12:01:46,843 - distributed.core - INFO - Starting established connection to tcp://10.3.88.12:37277
2024-01-16 12:01:46,846 - distributed.worker - INFO -         Registered to:     tcp://10.3.88.12:37277
2024-01-16 12:01:46,846 - distributed.worker - INFO - -------------------------------------------------
2024-01-16 12:01:46,846 - distributed.core - INFO - Starting established connection to tcp://10.3.88.12:37277
2024-01-16 12:01:53,191 - distributed.core - INFO - Event loop was unresponsive in Worker for 5.99s.  This is often caused by long-running GIL-holding functions or moving large chunks of data. This can cause timeouts and instability.
2024-01-16 12:01:53,192 - distributed.core - INFO - Event loop was unresponsive in Worker for 5.98s.  This is often caused by long-running GIL-holding functions or moving large chunks of data. This can cause timeouts and instability.
/mnt/storage/nobackup/nmb1063/mamba/envs/fegrow/lib/python3.9/site-packages/parmed/structure.py:1775: UnitStrippedWarning: The unit of the quantity is stripped when downcasting to ndarray.
  coords = np.array(value, dtype=np.float64, copy=False, subok=True)
2024-01-16 12:01:59,843 - distributed.worker - WARNING - Compute Failed
Key:       evaluate-0a199804-7445-4b64-afbc-094d0ae742ce
Function:  evaluate
args:      (<rdkit.Chem.rdchem.Mol object at 0x2b25170cc5e0>, 6, '[H]c1nc([H])c(-c2nc(-c3nc4c([H])c([H])c([H])c([H])c4o3)c(=O)n([H])c2[H])c([H])c1[H]', '/mnt/storage/nobackup/nmb1063/code/gal/sars-cov-2-main-protease-al-study/rec_final.pdb', '/nobackup/nmb1063/sars-fegrow/gnina')
kwargs:    {}
Exception: "JSONDecodeError('Invalid control character at: line 96 column 141406 (char 3619649)')"

2024-01-16 12:02:00,816 - distributed.worker - WARNING - Compute Failed
Key:       evaluate-0bc2cadc-f81c-4f71-8fe5-d02f9ef27797
Function:  evaluate
args:      (<rdkit.Chem.rdchem.Mol object at 0x2b25170cc5e0>, 6, '[H]c1nc([H])c(-c2c(N([H])C(=O)c3oc([H])c([H])c3[H])c([H])nn2[H])c([H])c1[H]', '/mnt/storage/nobackup/nmb1063/code/gal/sars-cov-2-main-protease-al-study/rec_final.pdb', '/nobackup/nmb1063/sars-fegrow/gnina')
kwargs:    {}
Exception: "JSONDecodeError('Invalid control character at: line 96 column 141406 (char 3619649)')"

/mnt/storage/nobackup/nmb1063/mamba/envs/fegrow/lib/python3.9/site-packages/parmed/structure.py:1775: UnitStrippedWarning: The unit of the quantity is stripped when downcasting to ndarray.
  coords = np.array(value, dtype=np.float64, copy=False, subok=True)
2024-01-16 12:02:05,164 - distributed.utils_perf - INFO - full garbage collection released 9.76 MiB from 247308 reference cycles (threshold: 9.54 MiB)
2024-01-16 12:02:06,981 - distributed.worker - WARNING - Compute Failed
Key:       evaluate-104bc710-ed28-4ab0-b9f7-4c0d108dded5
Function:  evaluate
args:      (<rdkit.Chem.rdchem.Mol object at 0x2b6f077e87c0>, 6, '[H]c1nc([H])c([C@]2([H])N(c3c([H])c([H])c(OC(F)(F)F)c([H])c3[H])C([H])([H])C([H])([H])C2([H])[H])c([H])c1[H]', '/mnt/storage/nobackup/nmb1063/code/gal/sars-cov-2-main-protease-al-study/rec_final.pdb', '/nobackup/nmb1063/sars-fegrow/gnina')
kwargs:    {}
Exception: "JSONDecodeError('Invalid control character at: line 96 column 141406 (char 3619649)')"

2024-01-16 12:02:08,292 - distributed.worker - WARNING - Compute Failed
Key:       evaluate-0fa26dac-57cd-415e-ae4f-7f57663d1e5b
Function:  evaluate
args:      (<rdkit.Chem.rdchem.Mol object at 0x2b25170cc5e0>, 6, '[H]c1nc(C2(c3c([H])nc([H])c([H])c3[H])OC([H])([H])C([H])([H])O2)c([H])nc1N([H])[H]', '/mnt/storage/nobackup/nmb1063/code/gal/sars-cov-2-main-protease-al-study/rec_final.pdb', '/nobackup/nmb1063/sars-fegrow/gnina')
kwargs:    {}
Exception: "JSONDecodeError('Invalid control character at: line 96 column 141406 (char 3619649)')"

2024-01-16 12:02:09,571 - distributed.utils_perf - INFO - full garbage collection released 9.96 MiB from 247800 reference cycles (threshold: 9.54 MiB)
2024-01-16 12:02:11,974 - distributed.worker - WARNING - Compute Failed
Key:       evaluate-115d48fa-4c40-46d3-921c-f1a302a052b8
Function:  evaluate
args:      (<rdkit.Chem.rdchem.Mol object at 0x2b6f077e87c0>, 6, '[H]c1nc([H])c(N([H])Sc2c([H])nc([H])c(F)c2[H])c([H])c1[H]', '/mnt/storage/nobackup/nmb1063/code/gal/sars-cov-2-main-protease-al-study/rec_final.pdb', '/nobackup/nmb1063/sars-fegrow/gnina')
kwargs:    {}
Exception: "JSONDecodeError('Invalid control character at: line 96 column 141406 (char 3619649)')"

2024-01-16 12:02:15,515 - distributed.worker - WARNING - Compute Failed
Key:       evaluate-0fb4ca1d-ab4a-405d-bf57-74f01f13781e
Function:  evaluate
args:      (<rdkit.Chem.rdchem.Mol object at 0x2b6f077e87c0>, 6, '[H]c1nc([H])c([C@]2([H])OC([H])([H])[C@]3([H])[C@@]2([H])C([H])([H])O[C@]3([H])N2C([H])([H])C([H])([H])N(C([H])([H])[H])C([H])([H])C([H])([H])C2([H])[H])c([H])c1[H]', '/mnt/storage/nobackup/nmb1063/code/gal/sars-cov-2-main-protease-al-study/rec_final.pdb', '/nobackup/nmb1063/sars-fegrow/gnina')
kwargs:    {}
Exception: "JSONDecodeError('Invalid control character at: line 96 column 141406 (char 3619649)')"

Warning (not error because allow_undefined_stereo=True): RDMol has unspecified stereochemistry. Bonds with undefined stereochemistry are:
 - Bond 6 (atoms 6-7 of element (N-N)

2024-01-16 12:02:17,488 - distributed.worker - WARNING - Compute Failed
Key:       evaluate-b3932ce7-3427-4cbc-ab2a-37c65c195947
Function:  evaluate
args:      (<rdkit.Chem.rdchem.Mol object at 0x2b25170cc5e0>, 6, '[H]c1nc([H])c(C2=C(C([H])([H])N([H])[C@@]3([H])C([H])([H])[C@@]3([H])c3c([H])c([H])c([H])c([H])c3[H])C([H])([H])[C@@]3([H])S[C@]2([H])C([H])([H])C3([H])[H])c([H])c1[H]', '/mnt/storage/nobackup/nmb1063/code/gal/sars-cov-2-main-protease-al-study/rec_final.pdb', '/nobackup/nmb1063/sars-fegrow/gnina')
kwargs:    {}
Exception: "JSONDecodeError('Invalid control character at: line 96 column 141406 (char 3619649)')"

Warning (not error because allow_undefined_stereo=True): RDMol has unspecified stereochemistry. Bonds with undefined stereochemistry are:
 - Bond 1 (atoms 1-2 of element (C-C)

2024-01-16 12:02:19,277 - distributed.worker - WARNING - Compute Failed
Key:       evaluate-cb21da7b-6755-4db0-bbed-792c1829071c
Function:  evaluate
args:      (<rdkit.Chem.rdchem.Mol object at 0x2b6f077e87c0>, 6, '[H]c1nc([H])c(N=Nc2c([H])c([H])c([H])c3nc([H])c([H])c([H])c23)c([H])c1[H]', '/mnt/storage/nobackup/nmb1063/code/gal/sars-cov-2-main-protease-al-study/rec_final.pdb', '/nobackup/nmb1063/sars-fegrow/gnina')
kwargs:    {}
Exception: "JSONDecodeError('Invalid control character at: line 96 column 141406 (char 3619649)')"

2024-01-16 12:02:20,888 - distributed.worker - WARNING - Compute Failed
Key:       evaluate-b49cdee1-313c-4de3-aa67-01287d718b30
Function:  evaluate
args:      (<rdkit.Chem.rdchem.Mol object at 0x2b25170cc5e0>, 6, '[H]C(=C1C(N([H])C([H])([H])C([H])([H])N2C([H])([H])C([H])([H])OC([H])([H])C2([H])[H])=NC([H])([H])C1([H])[H])c1c([H])nc([H])c([H])c1[H]', '/mnt/storage/nobackup/nmb1063/code/gal/sars-cov-2-main-protease-al-study/rec_final.pdb', '/nobackup/nmb1063/sars-fegrow/gnina')
kwargs:    {}
Exception: "JSONDecodeError('Invalid control character at: line 96 column 141406 (char 3619649)')"

2024-01-16 12:02:23,906 - distributed.worker - WARNING - Compute Failed
Key:       evaluate-f7ee765e-55ac-479b-b711-cfe3fc16f2da
Function:  evaluate
args:      (<rdkit.Chem.rdchem.Mol object at 0x2b6f077e87c0>, 6, '[H]c1nc(N([H])[H])nc(-c2nc3n(c2-c2c([H])nc([H])c([H])c2[H])C([H])([H])C([H])([H])S3)c1[H]', '/mnt/storage/nobackup/nmb1063/code/gal/sars-cov-2-main-protease-al-study/rec_final.pdb', '/nobackup/nmb1063/sars-fegrow/gnina')
kwargs:    {}
Exception: "Exception('No Conformers')"

2024-01-16 12:02:24,185 - distributed.worker - WARNING - Compute Failed
Key:       evaluate-d66b38f9-0a00-4b88-abbc-9d03f5a7b1cf
Function:  evaluate
args:      (<rdkit.Chem.rdchem.Mol object at 0x2b25170cc5e0>, 6, '[H]c1nc([H])c([C@]([H])(Cl)C([H])([H])[C@]2([H])C([H])([H])OC([H])([H])C2([H])[H])c([H])c1[H]', '/mnt/storage/nobackup/nmb1063/code/gal/sars-cov-2-main-protease-al-study/rec_final.pdb', '/nobackup/nmb1063/sars-fegrow/gnina')
kwargs:    {}
Exception: "JSONDecodeError('Invalid control character at: line 96 column 141406 (char 3619649)')"

2024-01-16 12:02:25,281 - distributed.worker - WARNING - Compute Failed
Key:       evaluate-e4a22578-8541-46f6-ab71-4876b893ed3a
Function:  evaluate
args:      (<rdkit.Chem.rdchem.Mol object at 0x2b6f077e87c0>, 6, '[H]OC([H])([H])C([H])([H])N1C([H])([H])C([H])([H])N(c2nn(-c3c([H])nc([H])c([H])c3[H])c([H])c([H])c2=O)C([H])([H])C1([H])[H]', '/mnt/storage/nobackup/nmb1063/code/gal/sars-cov-2-main-protease-al-study/rec_final.pdb', '/nobackup/nmb1063/sars-fegrow/gnina')
kwargs:    {}
Exception: "JSONDecodeError('Invalid control character at: line 96 column 141406 (char 3619649)')"

2024-01-16 12:02:26,473 - distributed.worker - WARNING - Compute Failed
Key:       evaluate-f0d5c6fa-700d-48c3-ae90-8057db16ee09
Function:  evaluate
args:      (<rdkit.Chem.rdchem.Mol object at 0x2b25170cc5e0>, 6, '[H]c1nc([H])c(-c2c([H])c([H])n(N([H])C(=O)OC(C([H])([H])[H])(C([H])([H])[H])C([H])([H])[H])c(=O)c2[H])c([H])c1[H]', '/mnt/storage/nobackup/nmb1063/code/gal/sars-cov-2-main-protease-al-study/rec_final.pdb', '/nobackup/nmb1063/sars-fegrow/gnina')
kwargs:    {}
Exception: "Exception('No Conformers')"

slurmstepd: error: *** JOB 19761821 ON sb014 CANCELLED AT 2024-01-16T12:18:12 ***
