hostname sb001.cluster
ipconfig 1: lo: <LOOPBACK,UP,LOWER_UP> mtu 65536 qdisc noqueue state UNKNOWN group default qlen 1000 link/loopback 00:00:00:00:00:00 brd 00:00:00:00:00:00 inet 127.0.0.1/8 scope host lo valid_lft forever preferred_lft forever inet6 ::1/128 scope host valid_lft forever preferred_lft forever 2: enp4s0f0: <BROADCAST,MULTICAST,UP,LOWER_UP> mtu 9000 qdisc mq state UP group default qlen 1000 link/ether a0:8c:f8:61:07:5e brd ff:ff:ff:ff:ff:ff inet 10.3.81.81/22 brd 10.3.83.255 scope global enp4s0f0 valid_lft forever preferred_lft forever inet6 fe80::a28c:f8ff:fe61:75e/64 scope link valid_lft forever preferred_lft forever 3: enp4s0f1: <BROADCAST,MULTICAST> mtu 1500 qdisc noop state DOWN group default qlen 1000 link/ether a0:8c:f8:61:07:5f brd ff:ff:ff:ff:ff:ff 4: enp4s0f2: <BROADCAST,MULTICAST> mtu 1500 qdisc noop state DOWN group default qlen 1000 link/ether a0:8c:f8:61:07:60 brd ff:ff:ff:ff:ff:ff 5: enp4s0f3: <BROADCAST,MULTICAST> mtu 1500 qdisc noop state DOWN group default qlen 1000 link/ether a0:8c:f8:61:07:61 brd ff:ff:ff:ff:ff:ff 6: ib0: <BROADCAST,MULTICAST,UP,LOWER_UP> mtu 4092 qdisc pfifo_fast state UP group default qlen 256 link/infiniband 80:00:00:29:fe:80:00:00:00:00:00:00:38:bc:01:03:00:4c:f2:c0 brd 00:ff:ff:ff:ff:12:40:1b:ff:ff:00:00:00:00:00:00:ff:ff:ff:ff inet 10.3.89.81/22 brd 10.3.91.255 scope global ib0 valid_lft forever preferred_lft forever inet 10.3.93.81/22 brd 10.3.95.255 scope global ib0:1 valid_lft forever preferred_lft forever inet6 fe80::3abc:103:4c:f2c0/64 scope link valid_lft forever preferred_lft forever 7: ib1: <BROADCAST,MULTICAST> mtu 4092 qdisc noop state DOWN group default qlen 256 link/infiniband 80:00:00:29:fe:80:00:00:00:00:00:00:38:bc:01:03:00:4c:f2:c1 brd 00:ff:ff:ff:ff:12:40:1b:ff:ff:00:00:00:00:00:00:ff:ff:ff:ff
2024-01-16 11:48:21,236 - distributed.nanny - INFO -         Start Nanny at: 'tcp://10.3.89.81:38617'
2024-01-16 11:48:21,403 - distributed.nanny - INFO -         Start Nanny at: 'tcp://10.3.89.81:42318'
2024-01-16 11:49:30,469 - distributed.worker - INFO -       Start worker at:     tcp://10.3.89.81:37869
2024-01-16 11:49:30,469 - distributed.worker - INFO -       Start worker at:     tcp://10.3.89.81:33144
2024-01-16 11:49:30,470 - distributed.worker - INFO -          Listening to:     tcp://10.3.89.81:37869
2024-01-16 11:49:30,470 - distributed.worker - INFO -          Listening to:     tcp://10.3.89.81:33144
2024-01-16 11:49:30,470 - distributed.worker - INFO -           Worker name:          SLURMCluster-97-1
2024-01-16 11:49:30,470 - distributed.worker - INFO -           Worker name:          SLURMCluster-97-0
2024-01-16 11:49:30,470 - distributed.worker - INFO -          dashboard at:           10.3.89.81:40094
2024-01-16 11:49:30,470 - distributed.worker - INFO -          dashboard at:           10.3.89.81:32773
2024-01-16 11:49:30,470 - distributed.worker - INFO - Waiting to connect to:     tcp://10.3.88.12:37277
2024-01-16 11:49:30,470 - distributed.worker - INFO - Waiting to connect to:     tcp://10.3.88.12:37277
2024-01-16 11:49:30,470 - distributed.worker - INFO - -------------------------------------------------
2024-01-16 11:49:30,470 - distributed.worker - INFO - -------------------------------------------------
2024-01-16 11:49:30,470 - distributed.worker - INFO -               Threads:                          2
2024-01-16 11:49:30,470 - distributed.worker - INFO -               Threads:                          2
2024-01-16 11:49:30,470 - distributed.worker - INFO -                Memory:                  10.24 GiB
2024-01-16 11:49:30,470 - distributed.worker - INFO -                Memory:                  10.24 GiB
2024-01-16 11:49:30,470 - distributed.worker - INFO -       Local Directory: /scratch/dask-worker-space/worker-nt_c9r20
2024-01-16 11:49:30,470 - distributed.worker - INFO -       Local Directory: /scratch/dask-worker-space/worker-712c3n3s
2024-01-16 11:49:30,470 - distributed.worker - INFO - -------------------------------------------------
2024-01-16 11:49:30,470 - distributed.worker - INFO - -------------------------------------------------
2024-01-16 11:49:30,778 - distributed.worker - INFO -         Registered to:     tcp://10.3.88.12:37277
2024-01-16 11:49:30,779 - distributed.worker - INFO - -------------------------------------------------
2024-01-16 11:49:30,779 - distributed.core - INFO - Starting established connection to tcp://10.3.88.12:37277
2024-01-16 11:49:30,788 - distributed.worker - INFO -         Registered to:     tcp://10.3.88.12:37277
2024-01-16 11:49:30,788 - distributed.worker - INFO - -------------------------------------------------
2024-01-16 11:49:30,789 - distributed.core - INFO - Starting established connection to tcp://10.3.88.12:37277
2024-01-16 11:50:12,407 - distributed.worker - ERROR - Worker stream died during communication: tcp://10.3.89.122:39675
Traceback (most recent call last):
  File "/mnt/storage/nobackup/nmb1063/mamba/envs/fegrow/lib/python3.9/site-packages/distributed/comm/tcp.py", line 225, in read
    frames_nbytes = await stream.read_bytes(fmt_size)
asyncio.exceptions.CancelledError

During handling of the above exception, another exception occurred:

Traceback (most recent call last):
  File "/mnt/storage/nobackup/nmb1063/mamba/envs/fegrow/lib/python3.9/asyncio/tasks.py", line 490, in wait_for
    return fut.result()
asyncio.exceptions.CancelledError

The above exception was the direct cause of the following exception:

Traceback (most recent call last):
  File "/mnt/storage/nobackup/nmb1063/mamba/envs/fegrow/lib/python3.9/site-packages/distributed/comm/core.py", line 328, in connect
    handshake = await asyncio.wait_for(comm.read(), time_left())
  File "/mnt/storage/nobackup/nmb1063/mamba/envs/fegrow/lib/python3.9/asyncio/tasks.py", line 492, in wait_for
    raise exceptions.TimeoutError() from exc
asyncio.exceptions.TimeoutError

The above exception was the direct cause of the following exception:

Traceback (most recent call last):
  File "/mnt/storage/nobackup/nmb1063/mamba/envs/fegrow/lib/python3.9/site-packages/distributed/worker.py", line 2081, in gather_dep
    response = await get_data_from_worker(
  File "/mnt/storage/nobackup/nmb1063/mamba/envs/fegrow/lib/python3.9/site-packages/distributed/worker.py", line 2900, in get_data_from_worker
    comm = await rpc.connect(worker)
  File "/mnt/storage/nobackup/nmb1063/mamba/envs/fegrow/lib/python3.9/site-packages/distributed/core.py", line 1468, in connect
    return await connect_attempt
  File "/mnt/storage/nobackup/nmb1063/mamba/envs/fegrow/lib/python3.9/site-packages/distributed/core.py", line 1389, in _connect
    comm = await connect(
  File "/mnt/storage/nobackup/nmb1063/mamba/envs/fegrow/lib/python3.9/site-packages/distributed/comm/core.py", line 333, in connect
    raise OSError(
OSError: Timed out during handshake while connecting to tcp://10.3.89.122:39675 after 30 s
2024-01-16 11:50:12,408 - distributed.worker - ERROR - Worker stream died during communication: tcp://10.3.89.122:39675
Traceback (most recent call last):
  File "/mnt/storage/nobackup/nmb1063/mamba/envs/fegrow/lib/python3.9/site-packages/distributed/comm/tcp.py", line 225, in read
    frames_nbytes = await stream.read_bytes(fmt_size)
asyncio.exceptions.CancelledError

During handling of the above exception, another exception occurred:

Traceback (most recent call last):
  File "/mnt/storage/nobackup/nmb1063/mamba/envs/fegrow/lib/python3.9/asyncio/tasks.py", line 490, in wait_for
    return fut.result()
asyncio.exceptions.CancelledError

The above exception was the direct cause of the following exception:

Traceback (most recent call last):
  File "/mnt/storage/nobackup/nmb1063/mamba/envs/fegrow/lib/python3.9/site-packages/distributed/comm/core.py", line 328, in connect
    handshake = await asyncio.wait_for(comm.read(), time_left())
  File "/mnt/storage/nobackup/nmb1063/mamba/envs/fegrow/lib/python3.9/asyncio/tasks.py", line 492, in wait_for
    raise exceptions.TimeoutError() from exc
asyncio.exceptions.TimeoutError

The above exception was the direct cause of the following exception:

Traceback (most recent call last):
  File "/mnt/storage/nobackup/nmb1063/mamba/envs/fegrow/lib/python3.9/site-packages/distributed/worker.py", line 2081, in gather_dep
    response = await get_data_from_worker(
  File "/mnt/storage/nobackup/nmb1063/mamba/envs/fegrow/lib/python3.9/site-packages/distributed/worker.py", line 2900, in get_data_from_worker
    comm = await rpc.connect(worker)
  File "/mnt/storage/nobackup/nmb1063/mamba/envs/fegrow/lib/python3.9/site-packages/distributed/core.py", line 1468, in connect
    return await connect_attempt
  File "/mnt/storage/nobackup/nmb1063/mamba/envs/fegrow/lib/python3.9/site-packages/distributed/core.py", line 1389, in _connect
    comm = await connect(
  File "/mnt/storage/nobackup/nmb1063/mamba/envs/fegrow/lib/python3.9/site-packages/distributed/comm/core.py", line 333, in connect
    raise OSError(
OSError: Timed out during handshake while connecting to tcp://10.3.89.122:39675 after 30 s
2024-01-16 11:50:42,786 - distributed.worker - ERROR - Worker stream died during communication: tcp://10.3.89.122:39675
Traceback (most recent call last):
  File "/mnt/storage/nobackup/nmb1063/mamba/envs/fegrow/lib/python3.9/site-packages/distributed/comm/tcp.py", line 225, in read
    frames_nbytes = await stream.read_bytes(fmt_size)
asyncio.exceptions.CancelledError

During handling of the above exception, another exception occurred:

Traceback (most recent call last):
  File "/mnt/storage/nobackup/nmb1063/mamba/envs/fegrow/lib/python3.9/asyncio/tasks.py", line 490, in wait_for
    return fut.result()
asyncio.exceptions.CancelledError

The above exception was the direct cause of the following exception:

Traceback (most recent call last):
  File "/mnt/storage/nobackup/nmb1063/mamba/envs/fegrow/lib/python3.9/site-packages/distributed/comm/core.py", line 328, in connect
    handshake = await asyncio.wait_for(comm.read(), time_left())
  File "/mnt/storage/nobackup/nmb1063/mamba/envs/fegrow/lib/python3.9/asyncio/tasks.py", line 492, in wait_for
    raise exceptions.TimeoutError() from exc
asyncio.exceptions.TimeoutError

The above exception was the direct cause of the following exception:

Traceback (most recent call last):
  File "/mnt/storage/nobackup/nmb1063/mamba/envs/fegrow/lib/python3.9/site-packages/distributed/worker.py", line 2081, in gather_dep
    response = await get_data_from_worker(
  File "/mnt/storage/nobackup/nmb1063/mamba/envs/fegrow/lib/python3.9/site-packages/distributed/worker.py", line 2900, in get_data_from_worker
    comm = await rpc.connect(worker)
  File "/mnt/storage/nobackup/nmb1063/mamba/envs/fegrow/lib/python3.9/site-packages/distributed/core.py", line 1468, in connect
    return await connect_attempt
  File "/mnt/storage/nobackup/nmb1063/mamba/envs/fegrow/lib/python3.9/site-packages/distributed/core.py", line 1389, in _connect
    comm = await connect(
  File "/mnt/storage/nobackup/nmb1063/mamba/envs/fegrow/lib/python3.9/site-packages/distributed/comm/core.py", line 333, in connect
    raise OSError(
OSError: Timed out during handshake while connecting to tcp://10.3.89.122:39675 after 30 s
2024-01-16 11:50:42,795 - distributed.worker - ERROR - Worker stream died during communication: tcp://10.3.89.122:39675
Traceback (most recent call last):
  File "/mnt/storage/nobackup/nmb1063/mamba/envs/fegrow/lib/python3.9/site-packages/distributed/comm/tcp.py", line 225, in read
    frames_nbytes = await stream.read_bytes(fmt_size)
asyncio.exceptions.CancelledError

During handling of the above exception, another exception occurred:

Traceback (most recent call last):
  File "/mnt/storage/nobackup/nmb1063/mamba/envs/fegrow/lib/python3.9/asyncio/tasks.py", line 490, in wait_for
    return fut.result()
asyncio.exceptions.CancelledError

The above exception was the direct cause of the following exception:

Traceback (most recent call last):
  File "/mnt/storage/nobackup/nmb1063/mamba/envs/fegrow/lib/python3.9/site-packages/distributed/comm/core.py", line 328, in connect
    handshake = await asyncio.wait_for(comm.read(), time_left())
  File "/mnt/storage/nobackup/nmb1063/mamba/envs/fegrow/lib/python3.9/asyncio/tasks.py", line 492, in wait_for
    raise exceptions.TimeoutError() from exc
asyncio.exceptions.TimeoutError

The above exception was the direct cause of the following exception:

Traceback (most recent call last):
  File "/mnt/storage/nobackup/nmb1063/mamba/envs/fegrow/lib/python3.9/site-packages/distributed/worker.py", line 2081, in gather_dep
    response = await get_data_from_worker(
  File "/mnt/storage/nobackup/nmb1063/mamba/envs/fegrow/lib/python3.9/site-packages/distributed/worker.py", line 2900, in get_data_from_worker
    comm = await rpc.connect(worker)
  File "/mnt/storage/nobackup/nmb1063/mamba/envs/fegrow/lib/python3.9/site-packages/distributed/core.py", line 1468, in connect
    return await connect_attempt
  File "/mnt/storage/nobackup/nmb1063/mamba/envs/fegrow/lib/python3.9/site-packages/distributed/core.py", line 1389, in _connect
    comm = await connect(
  File "/mnt/storage/nobackup/nmb1063/mamba/envs/fegrow/lib/python3.9/site-packages/distributed/comm/core.py", line 333, in connect
    raise OSError(
OSError: Timed out during handshake while connecting to tcp://10.3.89.122:39675 after 30 s
2024-01-16 11:51:13,783 - distributed.worker - ERROR - Worker stream died during communication: tcp://10.3.89.122:39675
Traceback (most recent call last):
  File "/mnt/storage/nobackup/nmb1063/mamba/envs/fegrow/lib/python3.9/site-packages/distributed/comm/tcp.py", line 225, in read
    frames_nbytes = await stream.read_bytes(fmt_size)
asyncio.exceptions.CancelledError

During handling of the above exception, another exception occurred:

Traceback (most recent call last):
  File "/mnt/storage/nobackup/nmb1063/mamba/envs/fegrow/lib/python3.9/asyncio/tasks.py", line 490, in wait_for
    return fut.result()
asyncio.exceptions.CancelledError

The above exception was the direct cause of the following exception:

Traceback (most recent call last):
  File "/mnt/storage/nobackup/nmb1063/mamba/envs/fegrow/lib/python3.9/site-packages/distributed/comm/core.py", line 328, in connect
    handshake = await asyncio.wait_for(comm.read(), time_left())
  File "/mnt/storage/nobackup/nmb1063/mamba/envs/fegrow/lib/python3.9/asyncio/tasks.py", line 492, in wait_for
    raise exceptions.TimeoutError() from exc
asyncio.exceptions.TimeoutError

The above exception was the direct cause of the following exception:

Traceback (most recent call last):
  File "/mnt/storage/nobackup/nmb1063/mamba/envs/fegrow/lib/python3.9/site-packages/distributed/worker.py", line 2081, in gather_dep
    response = await get_data_from_worker(
  File "/mnt/storage/nobackup/nmb1063/mamba/envs/fegrow/lib/python3.9/site-packages/distributed/worker.py", line 2900, in get_data_from_worker
    comm = await rpc.connect(worker)
  File "/mnt/storage/nobackup/nmb1063/mamba/envs/fegrow/lib/python3.9/site-packages/distributed/core.py", line 1468, in connect
    return await connect_attempt
  File "/mnt/storage/nobackup/nmb1063/mamba/envs/fegrow/lib/python3.9/site-packages/distributed/core.py", line 1389, in _connect
    comm = await connect(
  File "/mnt/storage/nobackup/nmb1063/mamba/envs/fegrow/lib/python3.9/site-packages/distributed/comm/core.py", line 333, in connect
    raise OSError(
OSError: Timed out during handshake while connecting to tcp://10.3.89.122:39675 after 30 s
2024-01-16 11:51:13,794 - distributed.worker - ERROR - Worker stream died during communication: tcp://10.3.89.122:39675
Traceback (most recent call last):
  File "/mnt/storage/nobackup/nmb1063/mamba/envs/fegrow/lib/python3.9/site-packages/distributed/comm/tcp.py", line 225, in read
    frames_nbytes = await stream.read_bytes(fmt_size)
asyncio.exceptions.CancelledError

During handling of the above exception, another exception occurred:

Traceback (most recent call last):
  File "/mnt/storage/nobackup/nmb1063/mamba/envs/fegrow/lib/python3.9/asyncio/tasks.py", line 490, in wait_for
    return fut.result()
asyncio.exceptions.CancelledError

The above exception was the direct cause of the following exception:

Traceback (most recent call last):
  File "/mnt/storage/nobackup/nmb1063/mamba/envs/fegrow/lib/python3.9/site-packages/distributed/comm/core.py", line 328, in connect
    handshake = await asyncio.wait_for(comm.read(), time_left())
  File "/mnt/storage/nobackup/nmb1063/mamba/envs/fegrow/lib/python3.9/asyncio/tasks.py", line 492, in wait_for
    raise exceptions.TimeoutError() from exc
asyncio.exceptions.TimeoutError

The above exception was the direct cause of the following exception:

Traceback (most recent call last):
  File "/mnt/storage/nobackup/nmb1063/mamba/envs/fegrow/lib/python3.9/site-packages/distributed/worker.py", line 2081, in gather_dep
    response = await get_data_from_worker(
  File "/mnt/storage/nobackup/nmb1063/mamba/envs/fegrow/lib/python3.9/site-packages/distributed/worker.py", line 2900, in get_data_from_worker
    comm = await rpc.connect(worker)
  File "/mnt/storage/nobackup/nmb1063/mamba/envs/fegrow/lib/python3.9/site-packages/distributed/core.py", line 1468, in connect
    return await connect_attempt
  File "/mnt/storage/nobackup/nmb1063/mamba/envs/fegrow/lib/python3.9/site-packages/distributed/core.py", line 1389, in _connect
    comm = await connect(
  File "/mnt/storage/nobackup/nmb1063/mamba/envs/fegrow/lib/python3.9/site-packages/distributed/comm/core.py", line 333, in connect
    raise OSError(
OSError: Timed out during handshake while connecting to tcp://10.3.89.122:39675 after 30 s
2024-01-16 11:51:44,785 - distributed.worker - ERROR - Worker stream died during communication: tcp://10.3.89.122:39675
Traceback (most recent call last):
  File "/mnt/storage/nobackup/nmb1063/mamba/envs/fegrow/lib/python3.9/site-packages/distributed/comm/tcp.py", line 225, in read
    frames_nbytes = await stream.read_bytes(fmt_size)
asyncio.exceptions.CancelledError

During handling of the above exception, another exception occurred:

Traceback (most recent call last):
  File "/mnt/storage/nobackup/nmb1063/mamba/envs/fegrow/lib/python3.9/asyncio/tasks.py", line 490, in wait_for
    return fut.result()
asyncio.exceptions.CancelledError

The above exception was the direct cause of the following exception:

Traceback (most recent call last):
  File "/mnt/storage/nobackup/nmb1063/mamba/envs/fegrow/lib/python3.9/site-packages/distributed/comm/core.py", line 328, in connect
    handshake = await asyncio.wait_for(comm.read(), time_left())
  File "/mnt/storage/nobackup/nmb1063/mamba/envs/fegrow/lib/python3.9/asyncio/tasks.py", line 492, in wait_for
    raise exceptions.TimeoutError() from exc
asyncio.exceptions.TimeoutError

The above exception was the direct cause of the following exception:

Traceback (most recent call last):
  File "/mnt/storage/nobackup/nmb1063/mamba/envs/fegrow/lib/python3.9/site-packages/distributed/worker.py", line 2081, in gather_dep
    response = await get_data_from_worker(
  File "/mnt/storage/nobackup/nmb1063/mamba/envs/fegrow/lib/python3.9/site-packages/distributed/worker.py", line 2900, in get_data_from_worker
    comm = await rpc.connect(worker)
  File "/mnt/storage/nobackup/nmb1063/mamba/envs/fegrow/lib/python3.9/site-packages/distributed/core.py", line 1468, in connect
    return await connect_attempt
  File "/mnt/storage/nobackup/nmb1063/mamba/envs/fegrow/lib/python3.9/site-packages/distributed/core.py", line 1389, in _connect
    comm = await connect(
  File "/mnt/storage/nobackup/nmb1063/mamba/envs/fegrow/lib/python3.9/site-packages/distributed/comm/core.py", line 333, in connect
    raise OSError(
OSError: Timed out during handshake while connecting to tcp://10.3.89.122:39675 after 30 s
2024-01-16 11:51:44,795 - distributed.worker - ERROR - Worker stream died during communication: tcp://10.3.89.122:39675
Traceback (most recent call last):
  File "/mnt/storage/nobackup/nmb1063/mamba/envs/fegrow/lib/python3.9/site-packages/distributed/comm/tcp.py", line 225, in read
    frames_nbytes = await stream.read_bytes(fmt_size)
asyncio.exceptions.CancelledError

During handling of the above exception, another exception occurred:

Traceback (most recent call last):
  File "/mnt/storage/nobackup/nmb1063/mamba/envs/fegrow/lib/python3.9/asyncio/tasks.py", line 490, in wait_for
    return fut.result()
asyncio.exceptions.CancelledError

The above exception was the direct cause of the following exception:

Traceback (most recent call last):
  File "/mnt/storage/nobackup/nmb1063/mamba/envs/fegrow/lib/python3.9/site-packages/distributed/comm/core.py", line 328, in connect
    handshake = await asyncio.wait_for(comm.read(), time_left())
  File "/mnt/storage/nobackup/nmb1063/mamba/envs/fegrow/lib/python3.9/asyncio/tasks.py", line 492, in wait_for
    raise exceptions.TimeoutError() from exc
asyncio.exceptions.TimeoutError

The above exception was the direct cause of the following exception:

Traceback (most recent call last):
  File "/mnt/storage/nobackup/nmb1063/mamba/envs/fegrow/lib/python3.9/site-packages/distributed/worker.py", line 2081, in gather_dep
    response = await get_data_from_worker(
  File "/mnt/storage/nobackup/nmb1063/mamba/envs/fegrow/lib/python3.9/site-packages/distributed/worker.py", line 2900, in get_data_from_worker
    comm = await rpc.connect(worker)
  File "/mnt/storage/nobackup/nmb1063/mamba/envs/fegrow/lib/python3.9/site-packages/distributed/core.py", line 1468, in connect
    return await connect_attempt
  File "/mnt/storage/nobackup/nmb1063/mamba/envs/fegrow/lib/python3.9/site-packages/distributed/core.py", line 1389, in _connect
    comm = await connect(
  File "/mnt/storage/nobackup/nmb1063/mamba/envs/fegrow/lib/python3.9/site-packages/distributed/comm/core.py", line 333, in connect
    raise OSError(
OSError: Timed out during handshake while connecting to tcp://10.3.89.122:39675 after 30 s
2024-01-16 11:52:15,784 - distributed.worker - ERROR - Worker stream died during communication: tcp://10.3.89.122:39675
Traceback (most recent call last):
  File "/mnt/storage/nobackup/nmb1063/mamba/envs/fegrow/lib/python3.9/site-packages/distributed/comm/tcp.py", line 225, in read
    frames_nbytes = await stream.read_bytes(fmt_size)
asyncio.exceptions.CancelledError

During handling of the above exception, another exception occurred:

Traceback (most recent call last):
  File "/mnt/storage/nobackup/nmb1063/mamba/envs/fegrow/lib/python3.9/asyncio/tasks.py", line 490, in wait_for
    return fut.result()
asyncio.exceptions.CancelledError

The above exception was the direct cause of the following exception:

Traceback (most recent call last):
  File "/mnt/storage/nobackup/nmb1063/mamba/envs/fegrow/lib/python3.9/site-packages/distributed/comm/core.py", line 328, in connect
    handshake = await asyncio.wait_for(comm.read(), time_left())
  File "/mnt/storage/nobackup/nmb1063/mamba/envs/fegrow/lib/python3.9/asyncio/tasks.py", line 492, in wait_for
    raise exceptions.TimeoutError() from exc
asyncio.exceptions.TimeoutError

The above exception was the direct cause of the following exception:

Traceback (most recent call last):
  File "/mnt/storage/nobackup/nmb1063/mamba/envs/fegrow/lib/python3.9/site-packages/distributed/worker.py", line 2081, in gather_dep
    response = await get_data_from_worker(
  File "/mnt/storage/nobackup/nmb1063/mamba/envs/fegrow/lib/python3.9/site-packages/distributed/worker.py", line 2900, in get_data_from_worker
    comm = await rpc.connect(worker)
  File "/mnt/storage/nobackup/nmb1063/mamba/envs/fegrow/lib/python3.9/site-packages/distributed/core.py", line 1468, in connect
    return await connect_attempt
  File "/mnt/storage/nobackup/nmb1063/mamba/envs/fegrow/lib/python3.9/site-packages/distributed/core.py", line 1389, in _connect
    comm = await connect(
  File "/mnt/storage/nobackup/nmb1063/mamba/envs/fegrow/lib/python3.9/site-packages/distributed/comm/core.py", line 333, in connect
    raise OSError(
OSError: Timed out during handshake while connecting to tcp://10.3.89.122:39675 after 30 s
2024-01-16 11:52:15,794 - distributed.worker - ERROR - Worker stream died during communication: tcp://10.3.89.122:39675
Traceback (most recent call last):
  File "/mnt/storage/nobackup/nmb1063/mamba/envs/fegrow/lib/python3.9/site-packages/distributed/comm/tcp.py", line 225, in read
    frames_nbytes = await stream.read_bytes(fmt_size)
asyncio.exceptions.CancelledError

During handling of the above exception, another exception occurred:

Traceback (most recent call last):
  File "/mnt/storage/nobackup/nmb1063/mamba/envs/fegrow/lib/python3.9/asyncio/tasks.py", line 490, in wait_for
    return fut.result()
asyncio.exceptions.CancelledError

The above exception was the direct cause of the following exception:

Traceback (most recent call last):
  File "/mnt/storage/nobackup/nmb1063/mamba/envs/fegrow/lib/python3.9/site-packages/distributed/comm/core.py", line 328, in connect
    handshake = await asyncio.wait_for(comm.read(), time_left())
  File "/mnt/storage/nobackup/nmb1063/mamba/envs/fegrow/lib/python3.9/asyncio/tasks.py", line 492, in wait_for
    raise exceptions.TimeoutError() from exc
asyncio.exceptions.TimeoutError

The above exception was the direct cause of the following exception:

Traceback (most recent call last):
  File "/mnt/storage/nobackup/nmb1063/mamba/envs/fegrow/lib/python3.9/site-packages/distributed/worker.py", line 2081, in gather_dep
    response = await get_data_from_worker(
  File "/mnt/storage/nobackup/nmb1063/mamba/envs/fegrow/lib/python3.9/site-packages/distributed/worker.py", line 2900, in get_data_from_worker
    comm = await rpc.connect(worker)
  File "/mnt/storage/nobackup/nmb1063/mamba/envs/fegrow/lib/python3.9/site-packages/distributed/core.py", line 1468, in connect
    return await connect_attempt
  File "/mnt/storage/nobackup/nmb1063/mamba/envs/fegrow/lib/python3.9/site-packages/distributed/core.py", line 1389, in _connect
    comm = await connect(
  File "/mnt/storage/nobackup/nmb1063/mamba/envs/fegrow/lib/python3.9/site-packages/distributed/comm/core.py", line 333, in connect
    raise OSError(
OSError: Timed out during handshake while connecting to tcp://10.3.89.122:39675 after 30 s
2024-01-16 11:52:46,785 - distributed.worker - ERROR - Worker stream died during communication: tcp://10.3.89.122:39675
Traceback (most recent call last):
  File "/mnt/storage/nobackup/nmb1063/mamba/envs/fegrow/lib/python3.9/site-packages/distributed/comm/tcp.py", line 225, in read
    frames_nbytes = await stream.read_bytes(fmt_size)
asyncio.exceptions.CancelledError

During handling of the above exception, another exception occurred:

Traceback (most recent call last):
  File "/mnt/storage/nobackup/nmb1063/mamba/envs/fegrow/lib/python3.9/asyncio/tasks.py", line 490, in wait_for
    return fut.result()
asyncio.exceptions.CancelledError

The above exception was the direct cause of the following exception:

Traceback (most recent call last):
  File "/mnt/storage/nobackup/nmb1063/mamba/envs/fegrow/lib/python3.9/site-packages/distributed/comm/core.py", line 328, in connect
    handshake = await asyncio.wait_for(comm.read(), time_left())
  File "/mnt/storage/nobackup/nmb1063/mamba/envs/fegrow/lib/python3.9/asyncio/tasks.py", line 492, in wait_for
    raise exceptions.TimeoutError() from exc
asyncio.exceptions.TimeoutError

The above exception was the direct cause of the following exception:

Traceback (most recent call last):
  File "/mnt/storage/nobackup/nmb1063/mamba/envs/fegrow/lib/python3.9/site-packages/distributed/worker.py", line 2081, in gather_dep
    response = await get_data_from_worker(
  File "/mnt/storage/nobackup/nmb1063/mamba/envs/fegrow/lib/python3.9/site-packages/distributed/worker.py", line 2900, in get_data_from_worker
    comm = await rpc.connect(worker)
  File "/mnt/storage/nobackup/nmb1063/mamba/envs/fegrow/lib/python3.9/site-packages/distributed/core.py", line 1468, in connect
    return await connect_attempt
  File "/mnt/storage/nobackup/nmb1063/mamba/envs/fegrow/lib/python3.9/site-packages/distributed/core.py", line 1389, in _connect
    comm = await connect(
  File "/mnt/storage/nobackup/nmb1063/mamba/envs/fegrow/lib/python3.9/site-packages/distributed/comm/core.py", line 333, in connect
    raise OSError(
OSError: Timed out during handshake while connecting to tcp://10.3.89.122:39675 after 30 s
2024-01-16 11:52:46,795 - distributed.worker - ERROR - Worker stream died during communication: tcp://10.3.89.122:39675
Traceback (most recent call last):
  File "/mnt/storage/nobackup/nmb1063/mamba/envs/fegrow/lib/python3.9/site-packages/distributed/comm/tcp.py", line 225, in read
    frames_nbytes = await stream.read_bytes(fmt_size)
asyncio.exceptions.CancelledError

During handling of the above exception, another exception occurred:

Traceback (most recent call last):
  File "/mnt/storage/nobackup/nmb1063/mamba/envs/fegrow/lib/python3.9/asyncio/tasks.py", line 490, in wait_for
    return fut.result()
asyncio.exceptions.CancelledError

The above exception was the direct cause of the following exception:

Traceback (most recent call last):
  File "/mnt/storage/nobackup/nmb1063/mamba/envs/fegrow/lib/python3.9/site-packages/distributed/comm/core.py", line 328, in connect
    handshake = await asyncio.wait_for(comm.read(), time_left())
  File "/mnt/storage/nobackup/nmb1063/mamba/envs/fegrow/lib/python3.9/asyncio/tasks.py", line 492, in wait_for
    raise exceptions.TimeoutError() from exc
asyncio.exceptions.TimeoutError

The above exception was the direct cause of the following exception:

Traceback (most recent call last):
  File "/mnt/storage/nobackup/nmb1063/mamba/envs/fegrow/lib/python3.9/site-packages/distributed/worker.py", line 2081, in gather_dep
    response = await get_data_from_worker(
  File "/mnt/storage/nobackup/nmb1063/mamba/envs/fegrow/lib/python3.9/site-packages/distributed/worker.py", line 2900, in get_data_from_worker
    comm = await rpc.connect(worker)
  File "/mnt/storage/nobackup/nmb1063/mamba/envs/fegrow/lib/python3.9/site-packages/distributed/core.py", line 1468, in connect
    return await connect_attempt
  File "/mnt/storage/nobackup/nmb1063/mamba/envs/fegrow/lib/python3.9/site-packages/distributed/core.py", line 1389, in _connect
    comm = await connect(
  File "/mnt/storage/nobackup/nmb1063/mamba/envs/fegrow/lib/python3.9/site-packages/distributed/comm/core.py", line 333, in connect
    raise OSError(
OSError: Timed out during handshake while connecting to tcp://10.3.89.122:39675 after 30 s
2024-01-16 11:53:17,786 - distributed.worker - ERROR - Worker stream died during communication: tcp://10.3.89.122:39675
Traceback (most recent call last):
  File "/mnt/storage/nobackup/nmb1063/mamba/envs/fegrow/lib/python3.9/site-packages/distributed/comm/tcp.py", line 225, in read
    frames_nbytes = await stream.read_bytes(fmt_size)
asyncio.exceptions.CancelledError

During handling of the above exception, another exception occurred:

Traceback (most recent call last):
  File "/mnt/storage/nobackup/nmb1063/mamba/envs/fegrow/lib/python3.9/asyncio/tasks.py", line 490, in wait_for
    return fut.result()
asyncio.exceptions.CancelledError

The above exception was the direct cause of the following exception:

Traceback (most recent call last):
  File "/mnt/storage/nobackup/nmb1063/mamba/envs/fegrow/lib/python3.9/site-packages/distributed/comm/core.py", line 328, in connect
    handshake = await asyncio.wait_for(comm.read(), time_left())
  File "/mnt/storage/nobackup/nmb1063/mamba/envs/fegrow/lib/python3.9/asyncio/tasks.py", line 492, in wait_for
    raise exceptions.TimeoutError() from exc
asyncio.exceptions.TimeoutError

The above exception was the direct cause of the following exception:

Traceback (most recent call last):
  File "/mnt/storage/nobackup/nmb1063/mamba/envs/fegrow/lib/python3.9/site-packages/distributed/worker.py", line 2081, in gather_dep
    response = await get_data_from_worker(
  File "/mnt/storage/nobackup/nmb1063/mamba/envs/fegrow/lib/python3.9/site-packages/distributed/worker.py", line 2900, in get_data_from_worker
    comm = await rpc.connect(worker)
  File "/mnt/storage/nobackup/nmb1063/mamba/envs/fegrow/lib/python3.9/site-packages/distributed/core.py", line 1468, in connect
    return await connect_attempt
  File "/mnt/storage/nobackup/nmb1063/mamba/envs/fegrow/lib/python3.9/site-packages/distributed/core.py", line 1389, in _connect
    comm = await connect(
  File "/mnt/storage/nobackup/nmb1063/mamba/envs/fegrow/lib/python3.9/site-packages/distributed/comm/core.py", line 333, in connect
    raise OSError(
OSError: Timed out during handshake while connecting to tcp://10.3.89.122:39675 after 30 s
2024-01-16 11:53:17,795 - distributed.worker - ERROR - Worker stream died during communication: tcp://10.3.89.122:39675
Traceback (most recent call last):
  File "/mnt/storage/nobackup/nmb1063/mamba/envs/fegrow/lib/python3.9/site-packages/distributed/comm/tcp.py", line 225, in read
    frames_nbytes = await stream.read_bytes(fmt_size)
asyncio.exceptions.CancelledError

During handling of the above exception, another exception occurred:

Traceback (most recent call last):
  File "/mnt/storage/nobackup/nmb1063/mamba/envs/fegrow/lib/python3.9/asyncio/tasks.py", line 490, in wait_for
    return fut.result()
asyncio.exceptions.CancelledError

The above exception was the direct cause of the following exception:

Traceback (most recent call last):
  File "/mnt/storage/nobackup/nmb1063/mamba/envs/fegrow/lib/python3.9/site-packages/distributed/comm/core.py", line 328, in connect
    handshake = await asyncio.wait_for(comm.read(), time_left())
  File "/mnt/storage/nobackup/nmb1063/mamba/envs/fegrow/lib/python3.9/asyncio/tasks.py", line 492, in wait_for
    raise exceptions.TimeoutError() from exc
asyncio.exceptions.TimeoutError

The above exception was the direct cause of the following exception:

Traceback (most recent call last):
  File "/mnt/storage/nobackup/nmb1063/mamba/envs/fegrow/lib/python3.9/site-packages/distributed/worker.py", line 2081, in gather_dep
    response = await get_data_from_worker(
  File "/mnt/storage/nobackup/nmb1063/mamba/envs/fegrow/lib/python3.9/site-packages/distributed/worker.py", line 2900, in get_data_from_worker
    comm = await rpc.connect(worker)
  File "/mnt/storage/nobackup/nmb1063/mamba/envs/fegrow/lib/python3.9/site-packages/distributed/core.py", line 1468, in connect
    return await connect_attempt
  File "/mnt/storage/nobackup/nmb1063/mamba/envs/fegrow/lib/python3.9/site-packages/distributed/core.py", line 1389, in _connect
    comm = await connect(
  File "/mnt/storage/nobackup/nmb1063/mamba/envs/fegrow/lib/python3.9/site-packages/distributed/comm/core.py", line 333, in connect
    raise OSError(
OSError: Timed out during handshake while connecting to tcp://10.3.89.122:39675 after 30 s
2024-01-16 11:53:48,784 - distributed.worker - ERROR - Worker stream died during communication: tcp://10.3.89.122:39675
Traceback (most recent call last):
  File "/mnt/storage/nobackup/nmb1063/mamba/envs/fegrow/lib/python3.9/site-packages/distributed/comm/tcp.py", line 225, in read
    frames_nbytes = await stream.read_bytes(fmt_size)
asyncio.exceptions.CancelledError

During handling of the above exception, another exception occurred:

Traceback (most recent call last):
  File "/mnt/storage/nobackup/nmb1063/mamba/envs/fegrow/lib/python3.9/asyncio/tasks.py", line 490, in wait_for
    return fut.result()
asyncio.exceptions.CancelledError

The above exception was the direct cause of the following exception:

Traceback (most recent call last):
  File "/mnt/storage/nobackup/nmb1063/mamba/envs/fegrow/lib/python3.9/site-packages/distributed/comm/core.py", line 328, in connect
    handshake = await asyncio.wait_for(comm.read(), time_left())
  File "/mnt/storage/nobackup/nmb1063/mamba/envs/fegrow/lib/python3.9/asyncio/tasks.py", line 492, in wait_for
    raise exceptions.TimeoutError() from exc
asyncio.exceptions.TimeoutError

The above exception was the direct cause of the following exception:

Traceback (most recent call last):
  File "/mnt/storage/nobackup/nmb1063/mamba/envs/fegrow/lib/python3.9/site-packages/distributed/worker.py", line 2081, in gather_dep
    response = await get_data_from_worker(
  File "/mnt/storage/nobackup/nmb1063/mamba/envs/fegrow/lib/python3.9/site-packages/distributed/worker.py", line 2900, in get_data_from_worker
    comm = await rpc.connect(worker)
  File "/mnt/storage/nobackup/nmb1063/mamba/envs/fegrow/lib/python3.9/site-packages/distributed/core.py", line 1468, in connect
    return await connect_attempt
  File "/mnt/storage/nobackup/nmb1063/mamba/envs/fegrow/lib/python3.9/site-packages/distributed/core.py", line 1389, in _connect
    comm = await connect(
  File "/mnt/storage/nobackup/nmb1063/mamba/envs/fegrow/lib/python3.9/site-packages/distributed/comm/core.py", line 333, in connect
    raise OSError(
OSError: Timed out during handshake while connecting to tcp://10.3.89.122:39675 after 30 s
2024-01-16 11:53:48,795 - distributed.worker - ERROR - Worker stream died during communication: tcp://10.3.89.122:39675
Traceback (most recent call last):
  File "/mnt/storage/nobackup/nmb1063/mamba/envs/fegrow/lib/python3.9/site-packages/distributed/comm/tcp.py", line 225, in read
    frames_nbytes = await stream.read_bytes(fmt_size)
asyncio.exceptions.CancelledError

During handling of the above exception, another exception occurred:

Traceback (most recent call last):
  File "/mnt/storage/nobackup/nmb1063/mamba/envs/fegrow/lib/python3.9/asyncio/tasks.py", line 490, in wait_for
    return fut.result()
asyncio.exceptions.CancelledError

The above exception was the direct cause of the following exception:

Traceback (most recent call last):
  File "/mnt/storage/nobackup/nmb1063/mamba/envs/fegrow/lib/python3.9/site-packages/distributed/comm/core.py", line 328, in connect
    handshake = await asyncio.wait_for(comm.read(), time_left())
  File "/mnt/storage/nobackup/nmb1063/mamba/envs/fegrow/lib/python3.9/asyncio/tasks.py", line 492, in wait_for
    raise exceptions.TimeoutError() from exc
asyncio.exceptions.TimeoutError

The above exception was the direct cause of the following exception:

Traceback (most recent call last):
  File "/mnt/storage/nobackup/nmb1063/mamba/envs/fegrow/lib/python3.9/site-packages/distributed/worker.py", line 2081, in gather_dep
    response = await get_data_from_worker(
  File "/mnt/storage/nobackup/nmb1063/mamba/envs/fegrow/lib/python3.9/site-packages/distributed/worker.py", line 2900, in get_data_from_worker
    comm = await rpc.connect(worker)
  File "/mnt/storage/nobackup/nmb1063/mamba/envs/fegrow/lib/python3.9/site-packages/distributed/core.py", line 1468, in connect
    return await connect_attempt
  File "/mnt/storage/nobackup/nmb1063/mamba/envs/fegrow/lib/python3.9/site-packages/distributed/core.py", line 1389, in _connect
    comm = await connect(
  File "/mnt/storage/nobackup/nmb1063/mamba/envs/fegrow/lib/python3.9/site-packages/distributed/comm/core.py", line 333, in connect
    raise OSError(
OSError: Timed out during handshake while connecting to tcp://10.3.89.122:39675 after 30 s
2024-01-16 11:54:19,784 - distributed.worker - ERROR - Worker stream died during communication: tcp://10.3.89.122:39675
Traceback (most recent call last):
  File "/mnt/storage/nobackup/nmb1063/mamba/envs/fegrow/lib/python3.9/site-packages/distributed/comm/tcp.py", line 225, in read
    frames_nbytes = await stream.read_bytes(fmt_size)
asyncio.exceptions.CancelledError

During handling of the above exception, another exception occurred:

Traceback (most recent call last):
  File "/mnt/storage/nobackup/nmb1063/mamba/envs/fegrow/lib/python3.9/asyncio/tasks.py", line 490, in wait_for
    return fut.result()
asyncio.exceptions.CancelledError

The above exception was the direct cause of the following exception:

Traceback (most recent call last):
  File "/mnt/storage/nobackup/nmb1063/mamba/envs/fegrow/lib/python3.9/site-packages/distributed/comm/core.py", line 328, in connect
    handshake = await asyncio.wait_for(comm.read(), time_left())
  File "/mnt/storage/nobackup/nmb1063/mamba/envs/fegrow/lib/python3.9/asyncio/tasks.py", line 492, in wait_for
    raise exceptions.TimeoutError() from exc
asyncio.exceptions.TimeoutError

The above exception was the direct cause of the following exception:

Traceback (most recent call last):
  File "/mnt/storage/nobackup/nmb1063/mamba/envs/fegrow/lib/python3.9/site-packages/distributed/worker.py", line 2081, in gather_dep
    response = await get_data_from_worker(
  File "/mnt/storage/nobackup/nmb1063/mamba/envs/fegrow/lib/python3.9/site-packages/distributed/worker.py", line 2900, in get_data_from_worker
    comm = await rpc.connect(worker)
  File "/mnt/storage/nobackup/nmb1063/mamba/envs/fegrow/lib/python3.9/site-packages/distributed/core.py", line 1468, in connect
    return await connect_attempt
  File "/mnt/storage/nobackup/nmb1063/mamba/envs/fegrow/lib/python3.9/site-packages/distributed/core.py", line 1389, in _connect
    comm = await connect(
  File "/mnt/storage/nobackup/nmb1063/mamba/envs/fegrow/lib/python3.9/site-packages/distributed/comm/core.py", line 333, in connect
    raise OSError(
OSError: Timed out during handshake while connecting to tcp://10.3.89.122:39675 after 30 s
2024-01-16 11:54:19,795 - distributed.worker - ERROR - Worker stream died during communication: tcp://10.3.89.122:39675
Traceback (most recent call last):
  File "/mnt/storage/nobackup/nmb1063/mamba/envs/fegrow/lib/python3.9/site-packages/distributed/comm/tcp.py", line 225, in read
    frames_nbytes = await stream.read_bytes(fmt_size)
asyncio.exceptions.CancelledError

During handling of the above exception, another exception occurred:

Traceback (most recent call last):
  File "/mnt/storage/nobackup/nmb1063/mamba/envs/fegrow/lib/python3.9/asyncio/tasks.py", line 490, in wait_for
    return fut.result()
asyncio.exceptions.CancelledError

The above exception was the direct cause of the following exception:

Traceback (most recent call last):
  File "/mnt/storage/nobackup/nmb1063/mamba/envs/fegrow/lib/python3.9/site-packages/distributed/comm/core.py", line 328, in connect
    handshake = await asyncio.wait_for(comm.read(), time_left())
  File "/mnt/storage/nobackup/nmb1063/mamba/envs/fegrow/lib/python3.9/asyncio/tasks.py", line 492, in wait_for
    raise exceptions.TimeoutError() from exc
asyncio.exceptions.TimeoutError

The above exception was the direct cause of the following exception:

Traceback (most recent call last):
  File "/mnt/storage/nobackup/nmb1063/mamba/envs/fegrow/lib/python3.9/site-packages/distributed/worker.py", line 2081, in gather_dep
    response = await get_data_from_worker(
  File "/mnt/storage/nobackup/nmb1063/mamba/envs/fegrow/lib/python3.9/site-packages/distributed/worker.py", line 2900, in get_data_from_worker
    comm = await rpc.connect(worker)
  File "/mnt/storage/nobackup/nmb1063/mamba/envs/fegrow/lib/python3.9/site-packages/distributed/core.py", line 1468, in connect
    return await connect_attempt
  File "/mnt/storage/nobackup/nmb1063/mamba/envs/fegrow/lib/python3.9/site-packages/distributed/core.py", line 1389, in _connect
    comm = await connect(
  File "/mnt/storage/nobackup/nmb1063/mamba/envs/fegrow/lib/python3.9/site-packages/distributed/comm/core.py", line 333, in connect
    raise OSError(
OSError: Timed out during handshake while connecting to tcp://10.3.89.122:39675 after 30 s
2024-01-16 11:59:13,063 - distributed.core - INFO - Event loop was unresponsive in Worker for 280.62s.  This is often caused by long-running GIL-holding functions or moving large chunks of data. This can cause timeouts and instability.
2024-01-16 11:59:13,202 - distributed.core - INFO - Event loop was unresponsive in Worker for 280.75s.  This is often caused by long-running GIL-holding functions or moving large chunks of data. This can cause timeouts and instability.
/mnt/storage/nobackup/nmb1063/mamba/envs/fegrow/lib/python3.9/site-packages/parmed/structure.py:1775: UnitStrippedWarning: The unit of the quantity is stripped when downcasting to ndarray.
  coords = np.array(value, dtype=np.float64, copy=False, subok=True)
/mnt/storage/nobackup/nmb1063/mamba/envs/fegrow/lib/python3.9/site-packages/parmed/structure.py:1775: UnitStrippedWarning: The unit of the quantity is stripped when downcasting to ndarray.
  coords = np.array(value, dtype=np.float64, copy=False, subok=True)
Warning (not error because allow_undefined_stereo=True): RDMol has unspecified stereochemistry. Bonds with undefined stereochemistry are:
 - Bond 1 (atoms 1-2 of element (C-C)

Warning (not error because allow_undefined_stereo=True): RDMol has unspecified stereochemistry. Bonds with undefined stereochemistry are:
 - Bond 1 (atoms 1-2 of element (C-C)

Warning (not error because allow_undefined_stereo=True): RDMol has unspecified stereochemistry. Bonds with undefined stereochemistry are:
 - Bond 1 (atoms 1-2 of element (C-C)

Warning (not error because allow_undefined_stereo=True): RDMol has unspecified stereochemistry. Bonds with undefined stereochemistry are:
 - Bond 1 (atoms 1-2 of element (C-C)

/mnt/storage/nobackup/nmb1063/mamba/envs/fegrow/lib/python3.9/site-packages/torchani/__init__.py:55: UserWarning: Dependency not satisfied, torchani.ase will not be available
  warnings.warn("Dependency not satisfied, torchani.ase will not be available")
/mnt/storage/nobackup/nmb1063/mamba/envs/fegrow/lib/python3.9/site-packages/torchani/__init__.py:55: UserWarning: Dependency not satisfied, torchani.ase will not be available
  warnings.warn("Dependency not satisfied, torchani.ase will not be available")
2024-01-16 12:00:50,020 - distributed.core - INFO - Event loop was unresponsive in Worker for 4.43s.  This is often caused by long-running GIL-holding functions or moving large chunks of data. This can cause timeouts and instability.
2024-01-16 12:00:50,021 - distributed.core - INFO - Event loop was unresponsive in Worker for 4.42s.  This is often caused by long-running GIL-holding functions or moving large chunks of data. This can cause timeouts and instability.
Warning: importing 'simtk.openmm' is deprecated.  Import 'openmm' instead.
Warning: importing 'simtk.openmm' is deprecated.  Import 'openmm' instead.
2024-01-16 12:01:37,251 - distributed.worker - WARNING - Compute Failed
Key:       evaluate-126321e2-3c42-4d37-b41a-089107ce74bc
Function:  evaluate
args:      (<rdkit.Chem.rdchem.Mol object at 0x2b6a8924b450>, 6, '[H]Oc1c([H])c(Cl)c([H])c([H])c1On1nc([H])nc1-c1c([H])nc([H])c([H])c1[H]', '/mnt/storage/nobackup/nmb1063/code/gal/sars-cov-2-main-protease-al-study/rec_final.pdb', '/nobackup/nmb1063/sars-fegrow/gnina')
kwargs:    {}
Exception: "JSONDecodeError('Invalid control character at: line 96 column 141406 (char 3619649)')"

/mnt/storage/nobackup/nmb1063/mamba/envs/fegrow/lib/python3.9/site-packages/parmed/structure.py:1775: UnitStrippedWarning: The unit of the quantity is stripped when downcasting to ndarray.
  coords = np.array(value, dtype=np.float64, copy=False, subok=True)
2024-01-16 12:01:43,685 - distributed.nanny - INFO - Worker process 10134 was killed by signal 11
2024-01-16 12:01:43,689 - distributed.nanny - WARNING - Restarting worker
2024-01-16 12:01:44,002 - distributed.worker - WARNING - Compute Failed
Key:       evaluate-08d024d0-e5cd-4450-a1d6-27a9aa9956d8
Function:  evaluate
args:      (<rdkit.Chem.rdchem.Mol object at 0x2b6a8924b450>, 6, '[H]c1nc([H])c(-c2c([H])nnn2C(=O)N2C([H])([H])C([H])([H])N(C([H])([H])[H])C([H])([H])C2([H])[H])c([H])c1[H]', '/mnt/storage/nobackup/nmb1063/code/gal/sars-cov-2-main-protease-al-study/rec_final.pdb', '/nobackup/nmb1063/sars-fegrow/gnina')
kwargs:    {}
Exception: "JSONDecodeError('Invalid control character at: line 96 column 141406 (char 3619649)')"

2024-01-16 12:01:46,870 - distributed.worker - INFO -       Start worker at:     tcp://10.3.89.81:34330
2024-01-16 12:01:46,871 - distributed.worker - INFO -          Listening to:     tcp://10.3.89.81:34330
2024-01-16 12:01:46,871 - distributed.worker - INFO -           Worker name:          SLURMCluster-97-1
2024-01-16 12:01:46,871 - distributed.worker - INFO -          dashboard at:           10.3.89.81:41099
2024-01-16 12:01:46,871 - distributed.worker - INFO - Waiting to connect to:     tcp://10.3.88.12:37277
2024-01-16 12:01:46,871 - distributed.worker - INFO - -------------------------------------------------
2024-01-16 12:01:46,871 - distributed.worker - INFO -               Threads:                          2
2024-01-16 12:01:46,871 - distributed.worker - INFO -                Memory:                  10.24 GiB
2024-01-16 12:01:46,871 - distributed.worker - INFO -       Local Directory: /scratch/dask-worker-space/worker-79ynsy_e
2024-01-16 12:01:46,872 - distributed.worker - INFO - -------------------------------------------------
2024-01-16 12:01:46,905 - distributed.worker - INFO -         Registered to:     tcp://10.3.88.12:37277
2024-01-16 12:01:46,905 - distributed.worker - INFO - -------------------------------------------------
2024-01-16 12:01:46,905 - distributed.core - INFO - Starting established connection to tcp://10.3.88.12:37277
TIME changed dir: 0.0s
TIME changed dir: 0.0s
using ani2x
/mnt/storage/nobackup/nmb1063/mamba/envs/fegrow/lib/python3.9/site-packages/torchani/resources/
TIME changed dir: 0.0s
failed to equip `nnpops` with error: No module named 'NNPOps'
TIME changed dir: 0.0s
Optimising conformer:   0%|                               | 0/3 [00:00<?, ?it/s][W BinaryOps.cpp:601] Warning: floor_divide is deprecated, and will be removed in a future version of pytorch. It currently rounds toward 0 (like the 'trunc' function NOT 'floor'). This results in incorrect rounding for negative values.
To keep the current behavior, use torch.div(a, b, rounding_mode='trunc'), or for actual floor division, use torch.div(a, b, rounding_mode='floor'). (function operator())
2024-01-16 12:01:49,517 - distributed.worker - WARNING - Compute Failed
Key:       evaluate-89df8d28-07e8-4630-ad2c-723057acb71f
Function:  evaluate
args:      (<rdkit.Chem.rdchem.Mol object at 0x2b6a8924b450>, 6, '[H]c1nc([H])c(-n2c(-c3c([H])nc([H])c(OC([H])([H])[H])c3[H])c([H])oc2=O)c([H])c1[H]', '/mnt/storage/nobackup/nmb1063/code/gal/sars-cov-2-main-protease-al-study/rec_final.pdb', '/nobackup/nmb1063/sars-fegrow/gnina')
kwargs:    {}
Exception: "JSONDecodeError('Invalid control character at: line 96 column 141406 (char 3619649)')"

Optimising conformer:  33%|███████▋               | 1/3 [00:03<00:06,  3.15s/it]2024-01-16 12:01:52,683 - distributed.worker - WARNING - Compute Failed
Key:       evaluate-0329b235-0e17-4329-9211-321680263807
Function:  evaluate
args:      (<rdkit.Chem.rdchem.Mol object at 0x2b6a8924b450>, 6, '[H]ON(c1c([H])nc([H])c([H])c1[H])c1c([H])c([H])c(Cl)c([H])c1Cl', '/mnt/storage/nobackup/nmb1063/code/gal/sars-cov-2-main-protease-al-study/rec_final.pdb', '/nobackup/nmb1063/sars-fegrow/gnina')
kwargs:    {}
Exception: "JSONDecodeError('Invalid control character at: line 96 column 141406 (char 3619649)')"

2024-01-16 12:01:53,880 - distributed.core - INFO - Event loop was unresponsive in Worker for 6.83s.  This is often caused by long-running GIL-holding functions or moving large chunks of data. This can cause timeouts and instability.
Optimising conformer:  67%|███████████████▎       | 2/3 [00:07<00:03,  3.82s/it]Optimising conformer: 100%|███████████████████████| 3/3 [00:09<00:00,  3.01s/it]Optimising conformer: 100%|███████████████████████| 3/3 [00:09<00:00,  3.17s/it]
2024-01-16 12:01:58,925 - distributed.worker - WARNING - Compute Failed
Key:       evaluate-9be0ebe7-c7cd-46dc-a010-7658ace0e88a
Function:  evaluate
args:      (<rdkit.Chem.rdchem.Mol object at 0x2b6a8924b450>, 6, '[H]C([H])=C([H])C([H])([H])O[C@@]1([H])C([H])([H])C([H])([H])C([H])([H])C([H])([H])[C@]1([H])c1c([H])nc([H])c([H])c1[H]', '/mnt/storage/nobackup/nmb1063/code/gal/sars-cov-2-main-protease-al-study/rec_final.pdb', '/nobackup/nmb1063/sars-fegrow/gnina')
kwargs:    {}
Exception: "JSONDecodeError('Invalid control character at: line 96 column 141406 (char 3619649)')"

2024-01-16 12:02:02,768 - distributed.worker - WARNING - Compute Failed
Key:       evaluate-a4e09783-e6c0-44f3-be5d-76544e2dae47
Function:  evaluate
args:      (<rdkit.Chem.rdchem.Mol object at 0x2b6a8924b450>, 6, '[H]c1nc(N([H])c2c([H])nn(-c3c([H])nc([H])c([H])c3[H])c2[H])c([H])c([H])c1[H]', '/mnt/storage/nobackup/nmb1063/code/gal/sars-cov-2-main-protease-al-study/rec_final.pdb', '/nobackup/nmb1063/sars-fegrow/gnina')
kwargs:    {}
Exception: "JSONDecodeError('Invalid control character at: line 96 column 141406 (char 3619649)')"

/mnt/storage/nobackup/nmb1063/mamba/envs/fegrow/lib/python3.9/site-packages/parmed/structure.py:1775: UnitStrippedWarning: The unit of the quantity is stripped when downcasting to ndarray.
  coords = np.array(value, dtype=np.float64, copy=False, subok=True)
2024-01-16 12:02:04,795 - distributed.worker - WARNING - Compute Failed
Key:       evaluate-1d953be2-1580-4882-8a23-38eb10b9f342
Function:  evaluate
args:      (<rdkit.Chem.rdchem.Mol object at 0x2b2cc4133950>, 6, '[H]c1nc([H])c(C([H])([H])n2c([H])c([H])c([H])c2C(=O)N([H])C([H])([H])C([H])([H])OC([H])([H])[H])c([H])c1[H]', '/mnt/storage/nobackup/nmb1063/code/gal/sars-cov-2-main-protease-al-study/rec_final.pdb', '/nobackup/nmb1063/sars-fegrow/gnina')
kwargs:    {}
Exception: "JSONDecodeError('Invalid control character at: line 96 column 141406 (char 3619649)')"

2024-01-16 12:02:04,795 - distributed.worker - WARNING - Compute Failed
Key:       evaluate-142e4682-96fa-4479-ba23-7d873edb74b7
Function:  evaluate
args:      (<rdkit.Chem.rdchem.Mol object at 0x2b2cc4133950>, 6, '[H]c1nc([H])c([C@@]2([H])C([H])([H])c3nn([H])c(-c4c([H])c([H])c([H])c(C(F)(F)F)c4[H])c3C2([H])[H])c([H])c1[H]', '/mnt/storage/nobackup/nmb1063/code/gal/sars-cov-2-main-protease-al-study/rec_final.pdb', '/nobackup/nmb1063/sars-fegrow/gnina')
kwargs:    {}
Exception: "JSONDecodeError('Invalid control character at: line 96 column 141406 (char 3619649)')"

2024-01-16 12:02:07,307 - distributed.worker - WARNING - Compute Failed
Key:       evaluate-af2f9ad1-445f-4ab7-b58f-0d29ed024f2e
Function:  evaluate
args:      (<rdkit.Chem.rdchem.Mol object at 0x2b6a8924b450>, 6, '[H]c1nc([H])c(-c2nc(=O)n([H])c(C(=O)c3c([H])c([H])c(F)c([H])c3[H])c2[H])c([H])c1[H]', '/mnt/storage/nobackup/nmb1063/code/gal/sars-cov-2-main-protease-al-study/rec_final.pdb', '/nobackup/nmb1063/sars-fegrow/gnina')
kwargs:    {}
Exception: "JSONDecodeError('Invalid control character at: line 96 column 141406 (char 3619649)')"

2024-01-16 12:02:09,034 - distributed.utils_perf - INFO - full garbage collection released 18.80 MiB from 465838 reference cycles (threshold: 9.54 MiB)
2024-01-16 12:02:11,018 - distributed.worker - WARNING - Compute Failed
Key:       evaluate-c3be75ea-a654-401c-9d3b-7bd3184653c4
Function:  evaluate
args:      (<rdkit.Chem.rdchem.Mol object at 0x2b2cc4133950>, 6, '[H]c1nc([H])c(C(=O)[C@@]([H])(c2nn(C([H])([H])[H])c([H])c2[H])C([H])([H])[H])c([H])c1[H]', '/mnt/storage/nobackup/nmb1063/code/gal/sars-cov-2-main-protease-al-study/rec_final.pdb', '/nobackup/nmb1063/sars-fegrow/gnina')
kwargs:    {}
Exception: "JSONDecodeError('Invalid control character at: line 96 column 141406 (char 3619649)')"

Warning (not error because allow_undefined_stereo=True): RDMol has unspecified stereochemistry. Bonds with undefined stereochemistry are:
 - Bond 1 (atoms 1-2 of element (C-C)

2024-01-16 12:02:13,420 - distributed.worker - WARNING - Compute Failed
Key:       evaluate-bce7cc1f-ec7b-459a-b749-68e185913328
Function:  evaluate
args:      (<rdkit.Chem.rdchem.Mol object at 0x2b6a8924b450>, 6, '[H]C(=C(Cl)c1c([H])nc([H])c([H])c1[H])c1c([H])c([H])c([H])c2c([H])c([H])c([H])nc12', '/mnt/storage/nobackup/nmb1063/code/gal/sars-cov-2-main-protease-al-study/rec_final.pdb', '/nobackup/nmb1063/sars-fegrow/gnina')
kwargs:    {}
Exception: "JSONDecodeError('Invalid control character at: line 96 column 141406 (char 3619649)')"

2024-01-16 12:02:14,396 - distributed.worker - WARNING - Compute Failed
Key:       evaluate-1dba6f61-b0ec-486e-8338-102408637bf5
Function:  evaluate
args:      (<rdkit.Chem.rdchem.Mol object at 0x2b2cc4133950>, 6, '[H]c1nc([H])c(C2(C(=O)N([H])C([H])([H])n3c([H])nc([H])c3[H])C([H])([H])C2([H])[H])c([H])c1[H]', '/mnt/storage/nobackup/nmb1063/code/gal/sars-cov-2-main-protease-al-study/rec_final.pdb', '/nobackup/nmb1063/sars-fegrow/gnina')
kwargs:    {}
Exception: "JSONDecodeError('Invalid control character at: line 96 column 141406 (char 3619649)')"

Warning (not error because allow_undefined_stereo=True): RDMol has unspecified stereochemistry. Bonds with undefined stereochemistry are:
 - Bond 23 (atoms 1-24 of element (C-C)

2024-01-16 12:02:18,753 - distributed.worker - WARNING - Compute Failed
Key:       evaluate-cdf1f018-5912-427f-aaaf-0ffb98d59153
Function:  evaluate
args:      (<rdkit.Chem.rdchem.Mol object at 0x2b6a8924b450>, 6, '[H]C(OC([H])([H])C([H])([H])N(C([H])([H])C([H])([H])[H])C([H])([H])C([H])([H])[H])=C([H])c1c([H])nc([H])c([H])c1[H]', '/mnt/storage/nobackup/nmb1063/code/gal/sars-cov-2-main-protease-al-study/rec_final.pdb', '/nobackup/nmb1063/sars-fegrow/gnina')
kwargs:    {}
Exception: "JSONDecodeError('Invalid control character at: line 96 column 141406 (char 3619649)')"

2024-01-16 12:02:18,755 - distributed.worker - WARNING - Compute Failed
Key:       evaluate-c421e3a1-aabd-42a0-becc-80189fb98b13
Function:  evaluate
args:      (<rdkit.Chem.rdchem.Mol object at 0x2b2cc4133950>, 6, '[H]OC([H])([H])C1([H])C([H])([H])C([H])([H])N(n2nnnc2Oc2c([H])nc([H])c([H])c2[H])C([H])([H])C1([H])[H]', '/mnt/storage/nobackup/nmb1063/code/gal/sars-cov-2-main-protease-al-study/rec_final.pdb', '/nobackup/nmb1063/sars-fegrow/gnina')
kwargs:    {}
Exception: "JSONDecodeError('Invalid control character at: line 96 column 141406 (char 3619649)')"

Warning (not error because allow_undefined_stereo=True): RDMol has unspecified stereochemistry. Bonds with undefined stereochemistry are:
 - Bond 1 (atoms 1-2 of element (C-C)

2024-01-16 12:02:21,595 - distributed.worker - WARNING - Compute Failed
Key:       evaluate-e1702ce1-4fe6-477a-834a-29cd33852102
Function:  evaluate
args:      (<rdkit.Chem.rdchem.Mol object at 0x2b2cc4133950>, 6, '[H]C(=C(Br)c1c([H])sc2c([H])c([H])c([H])c([H])c12)c1c([H])nc([H])c([H])c1[H]', '/mnt/storage/nobackup/nmb1063/code/gal/sars-cov-2-main-protease-al-study/rec_final.pdb', '/nobackup/nmb1063/sars-fegrow/gnina')
kwargs:    {}
Exception: "JSONDecodeError('Invalid control character at: line 96 column 141406 (char 3619649)')"

2024-01-16 12:02:24,156 - distributed.worker - WARNING - Compute Failed
Key:       evaluate-d2b0f9ba-c78e-4b4b-adcf-80ddcc56a89f
Function:  evaluate
args:      (<rdkit.Chem.rdchem.Mol object at 0x2b6a8924b450>, 6, '[H]c1nc([H])c(S(=O)(=O)N([H])C(=O)N([H])C(=O)N([H])c2c([H])c([H])c(Cl)c([H])c2[H])c([H])c1[H]', '/mnt/storage/nobackup/nmb1063/code/gal/sars-cov-2-main-protease-al-study/rec_final.pdb', '/nobackup/nmb1063/sars-fegrow/gnina')
kwargs:    {}
Exception: "JSONDecodeError('Invalid control character at: line 96 column 141406 (char 3619649)')"

2024-01-16 12:02:25,257 - distributed.worker - WARNING - Compute Failed
Key:       evaluate-f160d7d1-ee69-4ddc-a543-656a37ae7576
Function:  evaluate
args:      (<rdkit.Chem.rdchem.Mol object at 0x2b2cc4133950>, 6, '[H]c1nc([H])c(-c2noc(N([H])c3c([H])c([H])c(C([H])([H])[H])c([H])c3[H])c2[H])c([H])c1[H]', '/mnt/storage/nobackup/nmb1063/code/gal/sars-cov-2-main-protease-al-study/rec_final.pdb', '/nobackup/nmb1063/sars-fegrow/gnina')
kwargs:    {}
Exception: "JSONDecodeError('Invalid control character at: line 96 column 141406 (char 3619649)')"

2024-01-16 12:02:26,262 - distributed.worker - WARNING - Compute Failed
Key:       evaluate-e82e9f5d-1bba-45ff-a87b-a1bc1e909677
Function:  evaluate
args:      (<rdkit.Chem.rdchem.Mol object at 0x2b6a8924b450>, 6, '[H]Oc1c([H])c([H])c([H])c([H])c1N1C(=O)N([H])C(c2c([H])nc([H])c([H])c2[H])=C([H])C1([H])[H]', '/mnt/storage/nobackup/nmb1063/code/gal/sars-cov-2-main-protease-al-study/rec_final.pdb', '/nobackup/nmb1063/sars-fegrow/gnina')
kwargs:    {}
Exception: "JSONDecodeError('Invalid control character at: line 96 column 141406 (char 3619649)')"

2024-01-16 12:02:27,948 - distributed.worker - WARNING - Compute Failed
Key:       evaluate-ad65556b-1bde-4f56-8fda-b59064812d27
Function:  evaluate
args:      (<rdkit.Chem.rdchem.Mol object at 0x2b2cc4133950>, 6, '[H]OC(=O)c1c([H])c([H])c([H])c(S(=O)(=O)Oc2c([H])nc([H])c([H])c2[H])c1[H]', '/mnt/storage/nobackup/nmb1063/code/gal/sars-cov-2-main-protease-al-study/rec_final.pdb', '/nobackup/nmb1063/sars-fegrow/gnina')
kwargs:    {}
Exception: "JSONDecodeError('Invalid control character at: line 96 column 141406 (char 3619649)')"

slurmstepd: error: *** JOB 19761819 ON sb001 CANCELLED AT 2024-01-16T12:18:11 ***
