hostname sb047.cluster
ipconfig 1: lo: <LOOPBACK,UP,LOWER_UP> mtu 65536 qdisc noqueue state UNKNOWN group default qlen 1000 link/loopback 00:00:00:00:00:00 brd 00:00:00:00:00:00 inet 127.0.0.1/8 scope host lo valid_lft forever preferred_lft forever inet6 ::1/128 scope host valid_lft forever preferred_lft forever 2: enp4s0f0: <BROADCAST,MULTICAST,UP,LOWER_UP> mtu 9000 qdisc mq state UP group default qlen 1000 link/ether a0:8c:f8:34:c9:9c brd ff:ff:ff:ff:ff:ff inet 10.3.81.127/22 brd 10.3.83.255 scope global enp4s0f0 valid_lft forever preferred_lft forever inet6 fe80::a28c:f8ff:fe34:c99c/64 scope link valid_lft forever preferred_lft forever 3: enp4s0f1: <BROADCAST,MULTICAST> mtu 1500 qdisc noop state DOWN group default qlen 1000 link/ether a0:8c:f8:34:c9:9d brd ff:ff:ff:ff:ff:ff 4: enp4s0f2: <BROADCAST,MULTICAST> mtu 1500 qdisc noop state DOWN group default qlen 1000 link/ether a0:8c:f8:34:c9:9e brd ff:ff:ff:ff:ff:ff 5: enp4s0f3: <BROADCAST,MULTICAST> mtu 1500 qdisc noop state DOWN group default qlen 1000 link/ether a0:8c:f8:34:c9:9f brd ff:ff:ff:ff:ff:ff 6: ib0: <BROADCAST,MULTICAST,UP,LOWER_UP> mtu 4092 qdisc pfifo_fast state UP group default qlen 256 link/infiniband 80:00:00:29:fe:80:00:00:00:00:00:00:38:bc:01:03:00:4c:f4:b0 brd 00:ff:ff:ff:ff:12:40:1b:ff:ff:00:00:00:00:00:00:ff:ff:ff:ff inet 10.3.89.127/22 brd 10.3.91.255 scope global ib0 valid_lft forever preferred_lft forever inet 10.3.93.127/22 brd 10.3.95.255 scope global ib0:1 valid_lft forever preferred_lft forever inet6 fe80::3abc:103:4c:f4b0/64 scope link valid_lft forever preferred_lft forever 7: ib1: <BROADCAST,MULTICAST> mtu 4092 qdisc noop state DOWN group default qlen 256 link/infiniband 80:00:00:29:fe:80:00:00:00:00:00:00:38:bc:01:03:00:4c:f4:b1 brd 00:ff:ff:ff:ff:12:40:1b:ff:ff:00:00:00:00:00:00:ff:ff:ff:ff
2024-01-19 07:55:55,238 - distributed.nanny - INFO -         Start Nanny at: 'tcp://10.3.89.127:41369'
2024-01-19 07:55:55,253 - distributed.nanny - INFO -         Start Nanny at: 'tcp://10.3.89.127:36257'
2024-01-19 07:55:59,906 - distributed.worker - INFO -       Start worker at:    tcp://10.3.89.127:34935
2024-01-19 07:55:59,906 - distributed.worker - INFO -       Start worker at:    tcp://10.3.89.127:33438
2024-01-19 07:55:59,907 - distributed.worker - INFO -          Listening to:    tcp://10.3.89.127:34935
2024-01-19 07:55:59,907 - distributed.worker - INFO -          Listening to:    tcp://10.3.89.127:33438
2024-01-19 07:55:59,907 - distributed.worker - INFO -           Worker name:         SLURMCluster-286-1
2024-01-19 07:55:59,907 - distributed.worker - INFO -           Worker name:         SLURMCluster-286-0
2024-01-19 07:55:59,907 - distributed.worker - INFO -          dashboard at:          10.3.89.127:42522
2024-01-19 07:55:59,907 - distributed.worker - INFO -          dashboard at:          10.3.89.127:44502
2024-01-19 07:55:59,907 - distributed.worker - INFO - Waiting to connect to:     tcp://10.3.88.12:42763
2024-01-19 07:55:59,907 - distributed.worker - INFO - Waiting to connect to:     tcp://10.3.88.12:42763
2024-01-19 07:55:59,907 - distributed.worker - INFO - -------------------------------------------------
2024-01-19 07:55:59,907 - distributed.worker - INFO - -------------------------------------------------
2024-01-19 07:55:59,907 - distributed.worker - INFO -               Threads:                          2
2024-01-19 07:55:59,907 - distributed.worker - INFO -               Threads:                          2
2024-01-19 07:55:59,907 - distributed.worker - INFO -                Memory:                  10.24 GiB
2024-01-19 07:55:59,907 - distributed.worker - INFO -                Memory:                  10.24 GiB
2024-01-19 07:55:59,907 - distributed.worker - INFO -       Local Directory: /scratch/dask-worker-space/worker-g6_cvati
2024-01-19 07:55:59,907 - distributed.worker - INFO -       Local Directory: /scratch/dask-worker-space/worker-eqvfxeu0
2024-01-19 07:55:59,907 - distributed.worker - INFO - -------------------------------------------------
2024-01-19 07:55:59,907 - distributed.worker - INFO - -------------------------------------------------
2024-01-19 07:55:59,939 - distributed.worker - INFO -         Registered to:     tcp://10.3.88.12:42763
2024-01-19 07:55:59,939 - distributed.worker - INFO - -------------------------------------------------
2024-01-19 07:55:59,940 - distributed.core - INFO - Starting established connection to tcp://10.3.88.12:42763
2024-01-19 07:55:59,959 - distributed.worker - INFO -         Registered to:     tcp://10.3.88.12:42763
2024-01-19 07:55:59,960 - distributed.worker - INFO - -------------------------------------------------
2024-01-19 07:55:59,960 - distributed.core - INFO - Starting established connection to tcp://10.3.88.12:42763
2024-01-19 08:03:39,321 - distributed.worker - ERROR - Worker stream died during communication: tcp://10.3.89.124:40469
Traceback (most recent call last):
  File "/mnt/storage/nobackup/nmb1063/mamba/envs/fegrow/lib/python3.9/site-packages/distributed/comm/tcp.py", line 225, in read
    frames_nbytes = await stream.read_bytes(fmt_size)
asyncio.exceptions.CancelledError

During handling of the above exception, another exception occurred:

Traceback (most recent call last):
  File "/mnt/storage/nobackup/nmb1063/mamba/envs/fegrow/lib/python3.9/asyncio/tasks.py", line 490, in wait_for
    return fut.result()
asyncio.exceptions.CancelledError

The above exception was the direct cause of the following exception:

Traceback (most recent call last):
  File "/mnt/storage/nobackup/nmb1063/mamba/envs/fegrow/lib/python3.9/site-packages/distributed/comm/core.py", line 328, in connect
    handshake = await asyncio.wait_for(comm.read(), time_left())
  File "/mnt/storage/nobackup/nmb1063/mamba/envs/fegrow/lib/python3.9/asyncio/tasks.py", line 492, in wait_for
    raise exceptions.TimeoutError() from exc
asyncio.exceptions.TimeoutError

The above exception was the direct cause of the following exception:

Traceback (most recent call last):
  File "/mnt/storage/nobackup/nmb1063/mamba/envs/fegrow/lib/python3.9/site-packages/distributed/worker.py", line 2081, in gather_dep
    response = await get_data_from_worker(
  File "/mnt/storage/nobackup/nmb1063/mamba/envs/fegrow/lib/python3.9/site-packages/distributed/worker.py", line 2900, in get_data_from_worker
    comm = await rpc.connect(worker)
  File "/mnt/storage/nobackup/nmb1063/mamba/envs/fegrow/lib/python3.9/site-packages/distributed/core.py", line 1468, in connect
    return await connect_attempt
  File "/mnt/storage/nobackup/nmb1063/mamba/envs/fegrow/lib/python3.9/site-packages/distributed/core.py", line 1389, in _connect
    comm = await connect(
  File "/mnt/storage/nobackup/nmb1063/mamba/envs/fegrow/lib/python3.9/site-packages/distributed/comm/core.py", line 333, in connect
    raise OSError(
OSError: Timed out during handshake while connecting to tcp://10.3.89.124:40469 after 30 s
2024-01-19 08:03:39,381 - distributed.worker - ERROR - Worker stream died during communication: tcp://10.3.89.124:44379
Traceback (most recent call last):
  File "/mnt/storage/nobackup/nmb1063/mamba/envs/fegrow/lib/python3.9/site-packages/distributed/comm/tcp.py", line 225, in read
    frames_nbytes = await stream.read_bytes(fmt_size)
asyncio.exceptions.CancelledError

During handling of the above exception, another exception occurred:

Traceback (most recent call last):
  File "/mnt/storage/nobackup/nmb1063/mamba/envs/fegrow/lib/python3.9/asyncio/tasks.py", line 490, in wait_for
    return fut.result()
asyncio.exceptions.CancelledError

The above exception was the direct cause of the following exception:

Traceback (most recent call last):
  File "/mnt/storage/nobackup/nmb1063/mamba/envs/fegrow/lib/python3.9/site-packages/distributed/comm/core.py", line 328, in connect
    handshake = await asyncio.wait_for(comm.read(), time_left())
  File "/mnt/storage/nobackup/nmb1063/mamba/envs/fegrow/lib/python3.9/asyncio/tasks.py", line 492, in wait_for
    raise exceptions.TimeoutError() from exc
asyncio.exceptions.TimeoutError

The above exception was the direct cause of the following exception:

Traceback (most recent call last):
  File "/mnt/storage/nobackup/nmb1063/mamba/envs/fegrow/lib/python3.9/site-packages/distributed/worker.py", line 2081, in gather_dep
    response = await get_data_from_worker(
  File "/mnt/storage/nobackup/nmb1063/mamba/envs/fegrow/lib/python3.9/site-packages/distributed/worker.py", line 2900, in get_data_from_worker
    comm = await rpc.connect(worker)
  File "/mnt/storage/nobackup/nmb1063/mamba/envs/fegrow/lib/python3.9/site-packages/distributed/core.py", line 1468, in connect
    return await connect_attempt
  File "/mnt/storage/nobackup/nmb1063/mamba/envs/fegrow/lib/python3.9/site-packages/distributed/core.py", line 1389, in _connect
    comm = await connect(
  File "/mnt/storage/nobackup/nmb1063/mamba/envs/fegrow/lib/python3.9/site-packages/distributed/comm/core.py", line 333, in connect
    raise OSError(
OSError: Timed out during handshake while connecting to tcp://10.3.89.124:44379 after 30 s
2024-01-19 08:03:59,959 - distributed.core - INFO - Event loop was unresponsive in Worker for 20.19s.  This is often caused by long-running GIL-holding functions or moving large chunks of data. This can cause timeouts and instability.
/mnt/storage/nobackup/nmb1063/mamba/envs/fegrow/lib/python3.9/site-packages/parmed/structure.py:1775: UnitStrippedWarning: The unit of the quantity is stripped when downcasting to ndarray.
  coords = np.array(value, dtype=np.float64, copy=False, subok=True)
/mnt/storage/nobackup/nmb1063/mamba/envs/fegrow/lib/python3.9/site-packages/parmed/structure.py:1775: UnitStrippedWarning: The unit of the quantity is stripped when downcasting to ndarray.
  coords = np.array(value, dtype=np.float64, copy=False, subok=True)
/mnt/storage/nobackup/nmb1063/mamba/envs/fegrow/lib/python3.9/site-packages/torchani/__init__.py:55: UserWarning: Dependency not satisfied, torchani.ase will not be available
  warnings.warn("Dependency not satisfied, torchani.ase will not be available")
Warning: importing 'simtk.openmm' is deprecated.  Import 'openmm' instead.
TIME changed dir: 0.0s
Generated 42 conformers. 
Removed 27 conformers. 
TIME changed dir: 0.0s
Generated 12 conformers. 
Removed 9 conformers. 
using ani2x
/mnt/storage/nobackup/nmb1063/mamba/envs/fegrow/lib/python3.9/site-packages/torchani/resources/
failed to equip `nnpops` with error: No module named 'NNPOps'
Optimising conformer:   0%|                              | 0/15 [00:00<?, ?it/s][W BinaryOps.cpp:601] Warning: floor_divide is deprecated, and will be removed in a future version of pytorch. It currently rounds toward 0 (like the 'trunc' function NOT 'floor'). This results in incorrect rounding for negative values.
To keep the current behavior, use torch.div(a, b, rounding_mode='trunc'), or for actual floor division, use torch.div(a, b, rounding_mode='floor'). (function operator())
Optimising conformer:   7%|█▍                    | 1/15 [00:04<00:59,  4.28s/it]Optimising conformer:  13%|██▉                   | 2/15 [00:06<00:43,  3.31s/it]Optimising conformer:  20%|████▍                 | 3/15 [00:09<00:37,  3.16s/it]Optimising conformer:  27%|█████▊                | 4/15 [00:13<00:36,  3.27s/it]Optimising conformer:  33%|███████▎              | 5/15 [00:17<00:35,  3.57s/it]Optimising conformer:  40%|████████▊             | 6/15 [00:19<00:27,  3.08s/it]Optimising conformer:  47%|██████████▎           | 7/15 [00:23<00:25,  3.24s/it]Optimising conformer:  53%|███████████▋          | 8/15 [00:26<00:22,  3.17s/it]using ani2x
/mnt/storage/nobackup/nmb1063/mamba/envs/fegrow/lib/python3.9/site-packages/torchani/resources/
failed to equip `nnpops` with error: No module named 'NNPOps'

Optimising conformer:   0%|                               | 0/3 [00:00<?, ?it/s][AOptimising conformer:  60%|█████████████▏        | 9/15 [00:27<00:16,  2.75s/it]
Optimising conformer:  33%|███████▋               | 1/3 [00:03<00:06,  3.00s/it][A
Optimising conformer:  67%|███████████████▎       | 2/3 [00:04<00:02,  2.29s/it][A
Optimising conformer: 100%|███████████████████████| 3/3 [00:06<00:00,  2.14s/it][AOptimising conformer: 100%|███████████████████████| 3/3 [00:06<00:00,  2.26s/it]
Optimising conformer:  67%|██████████████       | 10/15 [01:35<01:53, 22.63s/it]Optimising conformer:  73%|███████████████▍     | 11/15 [01:37<01:06, 16.50s/it]Optimising conformer:  80%|████████████████▊    | 12/15 [01:40<00:36, 12.25s/it]Optimising conformer:  87%|██████████████████▏  | 13/15 [01:42<00:18,  9.13s/it]Optimising conformer:  93%|███████████████████▌ | 14/15 [01:44<00:07,  7.13s/it]Optimising conformer: 100%|█████████████████████| 15/15 [01:46<00:00,  5.67s/it]Optimising conformer: 100%|█████████████████████| 15/15 [01:46<00:00,  7.13s/it]
2024-01-19 09:24:32,215 - distributed.worker - ERROR - Failed to communicate with scheduler during heartbeat.
Traceback (most recent call last):
  File "/mnt/storage/nobackup/nmb1063/mamba/envs/fegrow/lib/python3.9/site-packages/tornado/iostream.py", line 861, in _read_to_buffer
    bytes_read = self.read_from_fd(buf)
  File "/mnt/storage/nobackup/nmb1063/mamba/envs/fegrow/lib/python3.9/site-packages/tornado/iostream.py", line 1116, in read_from_fd
    return self.socket.recv_into(buf, len(buf))
TimeoutError: [Errno 110] Connection timed out

The above exception was the direct cause of the following exception:

Traceback (most recent call last):
  File "/mnt/storage/nobackup/nmb1063/mamba/envs/fegrow/lib/python3.9/site-packages/distributed/worker.py", line 1237, in heartbeat
    response = await retry_operation(
  File "/mnt/storage/nobackup/nmb1063/mamba/envs/fegrow/lib/python3.9/site-packages/distributed/utils_comm.py", line 434, in retry_operation
    return await retry(
  File "/mnt/storage/nobackup/nmb1063/mamba/envs/fegrow/lib/python3.9/site-packages/distributed/utils_comm.py", line 413, in retry
    return await coro()
  File "/mnt/storage/nobackup/nmb1063/mamba/envs/fegrow/lib/python3.9/site-packages/distributed/core.py", line 1227, in send_recv_from_rpc
    return await send_recv(comm=comm, op=key, **kwargs)
  File "/mnt/storage/nobackup/nmb1063/mamba/envs/fegrow/lib/python3.9/site-packages/distributed/core.py", line 986, in send_recv
    response = await comm.read(deserializers=deserializers)
  File "/mnt/storage/nobackup/nmb1063/mamba/envs/fegrow/lib/python3.9/site-packages/distributed/comm/tcp.py", line 241, in read
    convert_stream_closed_error(self, e)
  File "/mnt/storage/nobackup/nmb1063/mamba/envs/fegrow/lib/python3.9/site-packages/distributed/comm/tcp.py", line 142, in convert_stream_closed_error
    raise CommClosedError(f"in {obj}: {exc.__class__.__name__}: {exc}") from exc
distributed.comm.core.CommClosedError: in <TCP (closed) ConnectionPool.heartbeat_worker local=tcp://10.3.89.127:51636 remote=tcp://10.3.88.12:42763>: TimeoutError: [Errno 110] Connection timed out
2024-01-19 09:24:32,215 - distributed.worker - ERROR - Failed to communicate with scheduler during heartbeat.
Traceback (most recent call last):
  File "/mnt/storage/nobackup/nmb1063/mamba/envs/fegrow/lib/python3.9/site-packages/tornado/iostream.py", line 861, in _read_to_buffer
    bytes_read = self.read_from_fd(buf)
  File "/mnt/storage/nobackup/nmb1063/mamba/envs/fegrow/lib/python3.9/site-packages/tornado/iostream.py", line 1116, in read_from_fd
    return self.socket.recv_into(buf, len(buf))
TimeoutError: [Errno 110] Connection timed out

The above exception was the direct cause of the following exception:

Traceback (most recent call last):
  File "/mnt/storage/nobackup/nmb1063/mamba/envs/fegrow/lib/python3.9/site-packages/distributed/worker.py", line 1237, in heartbeat
    response = await retry_operation(
  File "/mnt/storage/nobackup/nmb1063/mamba/envs/fegrow/lib/python3.9/site-packages/distributed/utils_comm.py", line 434, in retry_operation
    return await retry(
  File "/mnt/storage/nobackup/nmb1063/mamba/envs/fegrow/lib/python3.9/site-packages/distributed/utils_comm.py", line 413, in retry
    return await coro()
  File "/mnt/storage/nobackup/nmb1063/mamba/envs/fegrow/lib/python3.9/site-packages/distributed/core.py", line 1227, in send_recv_from_rpc
    return await send_recv(comm=comm, op=key, **kwargs)
  File "/mnt/storage/nobackup/nmb1063/mamba/envs/fegrow/lib/python3.9/site-packages/distributed/core.py", line 986, in send_recv
    response = await comm.read(deserializers=deserializers)
  File "/mnt/storage/nobackup/nmb1063/mamba/envs/fegrow/lib/python3.9/site-packages/distributed/comm/tcp.py", line 241, in read
    convert_stream_closed_error(self, e)
  File "/mnt/storage/nobackup/nmb1063/mamba/envs/fegrow/lib/python3.9/site-packages/distributed/comm/tcp.py", line 142, in convert_stream_closed_error
    raise CommClosedError(f"in {obj}: {exc.__class__.__name__}: {exc}") from exc
distributed.comm.core.CommClosedError: in <TCP (closed) ConnectionPool.heartbeat_worker local=tcp://10.3.89.127:51626 remote=tcp://10.3.88.12:42763>: TimeoutError: [Errno 110] Connection timed out
2024-01-19 09:24:38,623 - distributed.core - INFO - Connection to tcp://10.3.88.12:42763 has been closed.
2024-01-19 09:24:38,624 - distributed.worker - INFO - Stopping worker at tcp://10.3.89.127:33438. Reason: worker-handle-scheduler-connection-broken
2024-01-19 09:24:38,623 - distributed.core - INFO - Connection to tcp://10.3.88.12:42763 has been closed.
2024-01-19 09:24:38,627 - distributed.worker - INFO - Stopping worker at tcp://10.3.89.127:34935. Reason: worker-handle-scheduler-connection-broken
2024-01-19 09:24:38,628 - distributed.nanny - INFO - Closing Nanny gracefully at 'tcp://10.3.89.127:41369'. Reason: worker-handle-scheduler-connection-broken
2024-01-19 09:24:38,630 - distributed.nanny - INFO - Closing Nanny gracefully at 'tcp://10.3.89.127:36257'. Reason: worker-handle-scheduler-connection-broken
2024-01-19 09:24:38,636 - distributed.worker - ERROR - Failed to communicate with scheduler during heartbeat.
Traceback (most recent call last):
  File "/mnt/storage/nobackup/nmb1063/mamba/envs/fegrow/lib/python3.9/site-packages/distributed/core.py", line 1389, in _connect
    comm = await connect(
  File "/mnt/storage/nobackup/nmb1063/mamba/envs/fegrow/lib/python3.9/site-packages/distributed/comm/core.py", line 291, in connect
    comm = await asyncio.wait_for(
  File "/mnt/storage/nobackup/nmb1063/mamba/envs/fegrow/lib/python3.9/asyncio/tasks.py", line 466, in wait_for
    await waiter
asyncio.exceptions.CancelledError

During handling of the above exception, another exception occurred:

Traceback (most recent call last):
  File "/mnt/storage/nobackup/nmb1063/mamba/envs/fegrow/lib/python3.9/site-packages/distributed/worker.py", line 1237, in heartbeat
    response = await retry_operation(
  File "/mnt/storage/nobackup/nmb1063/mamba/envs/fegrow/lib/python3.9/site-packages/distributed/utils_comm.py", line 434, in retry_operation
    return await retry(
  File "/mnt/storage/nobackup/nmb1063/mamba/envs/fegrow/lib/python3.9/site-packages/distributed/utils_comm.py", line 413, in retry
    return await coro()
  File "/mnt/storage/nobackup/nmb1063/mamba/envs/fegrow/lib/python3.9/site-packages/distributed/core.py", line 1224, in send_recv_from_rpc
    comm = await self.pool.connect(self.addr)
  File "/mnt/storage/nobackup/nmb1063/mamba/envs/fegrow/lib/python3.9/site-packages/distributed/core.py", line 1468, in connect
    return await connect_attempt
  File "/mnt/storage/nobackup/nmb1063/mamba/envs/fegrow/lib/python3.9/site-packages/distributed/core.py", line 1412, in _connect
    raise CommClosedError(reason)
distributed.comm.core.CommClosedError: ConnectionPool closing.
2024-01-19 09:24:38,642 - distributed.nanny - INFO - Worker closed
2024-01-19 09:24:38,631 - distributed.worker - ERROR - Failed to communicate with scheduler during heartbeat.
Traceback (most recent call last):
  File "/mnt/storage/nobackup/nmb1063/mamba/envs/fegrow/lib/python3.9/site-packages/distributed/core.py", line 1389, in _connect
    comm = await connect(
  File "/mnt/storage/nobackup/nmb1063/mamba/envs/fegrow/lib/python3.9/site-packages/distributed/comm/core.py", line 291, in connect
    comm = await asyncio.wait_for(
  File "/mnt/storage/nobackup/nmb1063/mamba/envs/fegrow/lib/python3.9/asyncio/tasks.py", line 466, in wait_for
    await waiter
asyncio.exceptions.CancelledError

During handling of the above exception, another exception occurred:

Traceback (most recent call last):
  File "/mnt/storage/nobackup/nmb1063/mamba/envs/fegrow/lib/python3.9/site-packages/distributed/worker.py", line 1237, in heartbeat
    response = await retry_operation(
  File "/mnt/storage/nobackup/nmb1063/mamba/envs/fegrow/lib/python3.9/site-packages/distributed/utils_comm.py", line 434, in retry_operation
    return await retry(
  File "/mnt/storage/nobackup/nmb1063/mamba/envs/fegrow/lib/python3.9/site-packages/distributed/utils_comm.py", line 413, in retry
    return await coro()
  File "/mnt/storage/nobackup/nmb1063/mamba/envs/fegrow/lib/python3.9/site-packages/distributed/core.py", line 1224, in send_recv_from_rpc
    comm = await self.pool.connect(self.addr)
  File "/mnt/storage/nobackup/nmb1063/mamba/envs/fegrow/lib/python3.9/site-packages/distributed/core.py", line 1468, in connect
    return await connect_attempt
  File "/mnt/storage/nobackup/nmb1063/mamba/envs/fegrow/lib/python3.9/site-packages/distributed/core.py", line 1412, in _connect
    raise CommClosedError(reason)
distributed.comm.core.CommClosedError: ConnectionPool closing.
2024-01-19 09:24:38,656 - distributed.nanny - INFO - Worker closed
2024-01-19 09:24:40,646 - distributed.nanny - ERROR - Worker process died unexpectedly
TIME Completed the molecule generation in 83.2s.
TIME Completed the molecule generation in 251.1s.
2024-01-19 09:24:40,893 - distributed.nanny - INFO - Closing Nanny at 'tcp://10.3.89.127:41369'. Reason: nanny-close-gracefully
2024-01-19 09:24:43,765 - distributed.nanny - INFO - Closing Nanny at 'tcp://10.3.89.127:36257'. Reason: nanny-close-gracefully
2024-01-19 09:24:43,766 - distributed.dask_worker - INFO - End worker
