hostname sb048.cluster
ipconfig 1: lo: <LOOPBACK,UP,LOWER_UP> mtu 65536 qdisc noqueue state UNKNOWN group default qlen 1000 link/loopback 00:00:00:00:00:00 brd 00:00:00:00:00:00 inet 127.0.0.1/8 scope host lo valid_lft forever preferred_lft forever inet6 ::1/128 scope host valid_lft forever preferred_lft forever 2: enp4s0f0: <BROADCAST,MULTICAST,UP,LOWER_UP> mtu 9000 qdisc mq state UP group default qlen 1000 link/ether a0:8c:f8:34:c9:d8 brd ff:ff:ff:ff:ff:ff inet 10.3.81.128/22 brd 10.3.83.255 scope global enp4s0f0 valid_lft forever preferred_lft forever inet6 fe80::a28c:f8ff:fe34:c9d8/64 scope link valid_lft forever preferred_lft forever 3: enp4s0f1: <BROADCAST,MULTICAST> mtu 1500 qdisc noop state DOWN group default qlen 1000 link/ether a0:8c:f8:34:c9:d9 brd ff:ff:ff:ff:ff:ff 4: enp4s0f2: <BROADCAST,MULTICAST> mtu 1500 qdisc noop state DOWN group default qlen 1000 link/ether a0:8c:f8:34:c9:da brd ff:ff:ff:ff:ff:ff 5: enp4s0f3: <BROADCAST,MULTICAST> mtu 1500 qdisc noop state DOWN group default qlen 1000 link/ether a0:8c:f8:34:c9:db brd ff:ff:ff:ff:ff:ff 6: ib0: <BROADCAST,MULTICAST,UP,LOWER_UP> mtu 4092 qdisc pfifo_fast state UP group default qlen 256 link/infiniband 80:00:00:29:fe:80:00:00:00:00:00:00:38:bc:01:03:00:4c:f4:00 brd 00:ff:ff:ff:ff:12:40:1b:ff:ff:00:00:00:00:00:00:ff:ff:ff:ff inet 10.3.89.128/22 brd 10.3.91.255 scope global ib0 valid_lft forever preferred_lft forever inet 10.3.97.128/22 brd 10.3.99.255 scope global ib0:1 valid_lft forever preferred_lft forever inet6 fe80::3abc:103:4c:f400/64 scope link valid_lft forever preferred_lft forever 7: ib1: <NO-CARRIER,BROADCAST,MULTICAST,UP> mtu 4092 qdisc pfifo_fast state DOWN group default qlen 256 link/infiniband 80:00:00:29:fe:80:00:00:00:00:00:00:38:bc:01:03:00:4c:f4:01 brd 00:ff:ff:ff:ff:12:40:1b:ff:ff:00:00:00:00:00:00:ff:ff:ff:ff
2024-01-19 07:55:56,210 - distributed.nanny - INFO -         Start Nanny at: 'tcp://10.3.89.128:33872'
2024-01-19 07:55:56,225 - distributed.nanny - INFO -         Start Nanny at: 'tcp://10.3.89.128:33442'
2024-01-19 07:55:58,277 - distributed.diskutils - INFO - Found stale lock file and directory '/scratch/dask-worker-space/worker-kzzpnl4_', purging
2024-01-19 07:55:58,279 - distributed.diskutils - INFO - Found stale lock file and directory '/scratch/dask-worker-space/worker-4ucisnkd', purging
2024-01-19 07:55:58,279 - distributed.diskutils - INFO - Found stale lock file and directory '/scratch/dask-worker-space/worker-ofgjm_ua', purging
2024-01-19 07:55:58,279 - distributed.diskutils - INFO - Found stale lock file and directory '/scratch/dask-worker-space/worker-sv4sxcw7', purging
2024-01-19 07:55:58,280 - distributed.diskutils - INFO - Found stale lock file and directory '/scratch/dask-worker-space/worker-jj8b_uiw', purging
2024-01-19 07:55:58,280 - distributed.diskutils - INFO - Found stale lock file and directory '/scratch/dask-worker-space/worker-r24lr7bs', purging
2024-01-19 07:56:01,896 - distributed.worker - INFO -       Start worker at:    tcp://10.3.89.128:40147
2024-01-19 07:56:01,896 - distributed.worker - INFO -          Listening to:    tcp://10.3.89.128:40147
2024-01-19 07:56:01,896 - distributed.worker - INFO -           Worker name:         SLURMCluster-111-0
2024-01-19 07:56:01,897 - distributed.worker - INFO -          dashboard at:          10.3.89.128:33904
2024-01-19 07:56:01,897 - distributed.worker - INFO - Waiting to connect to:     tcp://10.3.88.12:42763
2024-01-19 07:56:01,897 - distributed.worker - INFO - -------------------------------------------------
2024-01-19 07:56:01,897 - distributed.worker - INFO -               Threads:                          2
2024-01-19 07:56:01,897 - distributed.worker - INFO -       Start worker at:    tcp://10.3.89.128:34338
2024-01-19 07:56:01,897 - distributed.worker - INFO -                Memory:                  10.24 GiB
2024-01-19 07:56:01,897 - distributed.worker - INFO -          Listening to:    tcp://10.3.89.128:34338
2024-01-19 07:56:01,897 - distributed.worker - INFO -       Local Directory: /scratch/dask-worker-space/worker-con31n3i
2024-01-19 07:56:01,897 - distributed.worker - INFO -           Worker name:         SLURMCluster-111-1
2024-01-19 07:56:01,897 - distributed.worker - INFO - -------------------------------------------------
2024-01-19 07:56:01,897 - distributed.worker - INFO -          dashboard at:          10.3.89.128:41369
2024-01-19 07:56:01,897 - distributed.worker - INFO - Waiting to connect to:     tcp://10.3.88.12:42763
2024-01-19 07:56:01,897 - distributed.worker - INFO - -------------------------------------------------
2024-01-19 07:56:01,897 - distributed.worker - INFO -               Threads:                          2
2024-01-19 07:56:01,897 - distributed.worker - INFO -                Memory:                  10.24 GiB
2024-01-19 07:56:01,897 - distributed.worker - INFO -       Local Directory: /scratch/dask-worker-space/worker-__oze4d8
2024-01-19 07:56:01,897 - distributed.worker - INFO - -------------------------------------------------
2024-01-19 07:56:01,934 - distributed.worker - INFO -         Registered to:     tcp://10.3.88.12:42763
2024-01-19 07:56:01,934 - distributed.worker - INFO - -------------------------------------------------
2024-01-19 07:56:01,934 - distributed.core - INFO - Starting established connection to tcp://10.3.88.12:42763
2024-01-19 07:56:01,937 - distributed.worker - INFO -         Registered to:     tcp://10.3.88.12:42763
2024-01-19 07:56:01,937 - distributed.worker - INFO - -------------------------------------------------
2024-01-19 07:56:01,938 - distributed.core - INFO - Starting established connection to tcp://10.3.88.12:42763
2024-01-19 08:03:39,299 - distributed.worker - ERROR - Worker stream died during communication: tcp://10.3.89.124:40469
Traceback (most recent call last):
  File "/mnt/storage/nobackup/nmb1063/mamba/envs/fegrow/lib/python3.9/site-packages/distributed/comm/tcp.py", line 225, in read
    frames_nbytes = await stream.read_bytes(fmt_size)
asyncio.exceptions.CancelledError

During handling of the above exception, another exception occurred:

Traceback (most recent call last):
  File "/mnt/storage/nobackup/nmb1063/mamba/envs/fegrow/lib/python3.9/asyncio/tasks.py", line 490, in wait_for
    return fut.result()
asyncio.exceptions.CancelledError

The above exception was the direct cause of the following exception:

Traceback (most recent call last):
  File "/mnt/storage/nobackup/nmb1063/mamba/envs/fegrow/lib/python3.9/site-packages/distributed/comm/core.py", line 328, in connect
    handshake = await asyncio.wait_for(comm.read(), time_left())
  File "/mnt/storage/nobackup/nmb1063/mamba/envs/fegrow/lib/python3.9/asyncio/tasks.py", line 492, in wait_for
    raise exceptions.TimeoutError() from exc
asyncio.exceptions.TimeoutError

The above exception was the direct cause of the following exception:

Traceback (most recent call last):
  File "/mnt/storage/nobackup/nmb1063/mamba/envs/fegrow/lib/python3.9/site-packages/distributed/worker.py", line 2081, in gather_dep
    response = await get_data_from_worker(
  File "/mnt/storage/nobackup/nmb1063/mamba/envs/fegrow/lib/python3.9/site-packages/distributed/worker.py", line 2900, in get_data_from_worker
    comm = await rpc.connect(worker)
  File "/mnt/storage/nobackup/nmb1063/mamba/envs/fegrow/lib/python3.9/site-packages/distributed/core.py", line 1468, in connect
    return await connect_attempt
  File "/mnt/storage/nobackup/nmb1063/mamba/envs/fegrow/lib/python3.9/site-packages/distributed/core.py", line 1389, in _connect
    comm = await connect(
  File "/mnt/storage/nobackup/nmb1063/mamba/envs/fegrow/lib/python3.9/site-packages/distributed/comm/core.py", line 333, in connect
    raise OSError(
OSError: Timed out during handshake while connecting to tcp://10.3.89.124:40469 after 30 s
2024-01-19 08:03:39,380 - distributed.worker - ERROR - Worker stream died during communication: tcp://10.3.89.124:44379
Traceback (most recent call last):
  File "/mnt/storage/nobackup/nmb1063/mamba/envs/fegrow/lib/python3.9/site-packages/distributed/comm/tcp.py", line 225, in read
    frames_nbytes = await stream.read_bytes(fmt_size)
asyncio.exceptions.CancelledError

During handling of the above exception, another exception occurred:

Traceback (most recent call last):
  File "/mnt/storage/nobackup/nmb1063/mamba/envs/fegrow/lib/python3.9/asyncio/tasks.py", line 490, in wait_for
    return fut.result()
asyncio.exceptions.CancelledError

The above exception was the direct cause of the following exception:

Traceback (most recent call last):
  File "/mnt/storage/nobackup/nmb1063/mamba/envs/fegrow/lib/python3.9/site-packages/distributed/comm/core.py", line 328, in connect
    handshake = await asyncio.wait_for(comm.read(), time_left())
  File "/mnt/storage/nobackup/nmb1063/mamba/envs/fegrow/lib/python3.9/asyncio/tasks.py", line 492, in wait_for
    raise exceptions.TimeoutError() from exc
asyncio.exceptions.TimeoutError

The above exception was the direct cause of the following exception:

Traceback (most recent call last):
  File "/mnt/storage/nobackup/nmb1063/mamba/envs/fegrow/lib/python3.9/site-packages/distributed/worker.py", line 2081, in gather_dep
    response = await get_data_from_worker(
  File "/mnt/storage/nobackup/nmb1063/mamba/envs/fegrow/lib/python3.9/site-packages/distributed/worker.py", line 2900, in get_data_from_worker
    comm = await rpc.connect(worker)
  File "/mnt/storage/nobackup/nmb1063/mamba/envs/fegrow/lib/python3.9/site-packages/distributed/core.py", line 1468, in connect
    return await connect_attempt
  File "/mnt/storage/nobackup/nmb1063/mamba/envs/fegrow/lib/python3.9/site-packages/distributed/core.py", line 1389, in _connect
    comm = await connect(
  File "/mnt/storage/nobackup/nmb1063/mamba/envs/fegrow/lib/python3.9/site-packages/distributed/comm/core.py", line 333, in connect
    raise OSError(
OSError: Timed out during handshake while connecting to tcp://10.3.89.124:44379 after 30 s
2024-01-19 08:03:59,965 - distributed.core - INFO - Event loop was unresponsive in Worker for 20.44s.  This is often caused by long-running GIL-holding functions or moving large chunks of data. This can cause timeouts and instability.
/mnt/storage/nobackup/nmb1063/mamba/envs/fegrow/lib/python3.9/site-packages/parmed/structure.py:1775: UnitStrippedWarning: The unit of the quantity is stripped when downcasting to ndarray.
  coords = np.array(value, dtype=np.float64, copy=False, subok=True)
/mnt/storage/nobackup/nmb1063/mamba/envs/fegrow/lib/python3.9/site-packages/torchani/__init__.py:55: UserWarning: Dependency not satisfied, torchani.ase will not be available
  warnings.warn("Dependency not satisfied, torchani.ase will not be available")
Warning: importing 'simtk.openmm' is deprecated.  Import 'openmm' instead.
TIME changed dir: 0.0s
TIME changed dir: 0.0s
Generated 34 conformers. 
Removed 13 conformers. 
Generated 8 conformers. 
Removed 4 conformers. 
using ani2x
/mnt/storage/nobackup/nmb1063/mamba/envs/fegrow/lib/python3.9/site-packages/torchani/resources/
failed to equip `nnpops` with error: No module named 'NNPOps'
Optimising conformer:   0%|                              | 0/21 [00:00<?, ?it/s][W BinaryOps.cpp:601] Warning: floor_divide is deprecated, and will be removed in a future version of pytorch. It currently rounds toward 0 (like the 'trunc' function NOT 'floor'). This results in incorrect rounding for negative values.
To keep the current behavior, use torch.div(a, b, rounding_mode='trunc'), or for actual floor division, use torch.div(a, b, rounding_mode='floor'). (function operator())
Optimising conformer:   5%|█                     | 1/21 [00:07<02:21,  7.08s/it]Optimising conformer:  10%|██                    | 2/21 [00:08<01:15,  4.00s/it]Optimising conformer:  14%|███▏                  | 3/21 [00:11<01:01,  3.43s/it]Optimising conformer:  19%|████▏                 | 4/21 [00:14<00:55,  3.24s/it]Optimising conformer:  24%|█████▏                | 5/21 [00:16<00:43,  2.74s/it]Optimising conformer:  29%|██████▎               | 6/21 [00:19<00:40,  2.73s/it]Optimising conformer:  33%|███████▎              | 7/21 [00:24<00:51,  3.68s/it]Optimising conformer:  38%|████████▍             | 8/21 [00:26<00:39,  3.05s/it]Optimising conformer:  43%|█████████▍            | 9/21 [00:28<00:32,  2.72s/it]Optimising conformer:  48%|██████████           | 10/21 [00:30<00:28,  2.55s/it]Optimising conformer:  52%|███████████          | 11/21 [00:32<00:23,  2.32s/it]Optimising conformer:  57%|████████████         | 12/21 [00:35<00:23,  2.57s/it]Optimising conformer:  62%|█████████████        | 13/21 [00:37<00:19,  2.43s/it]Optimising conformer:  67%|██████████████       | 14/21 [00:39<00:16,  2.30s/it]Optimising conformer:  71%|███████████████      | 15/21 [00:41<00:13,  2.20s/it]Optimising conformer:  76%|████████████████     | 16/21 [00:43<00:10,  2.13s/it]using ani2x
/mnt/storage/nobackup/nmb1063/mamba/envs/fegrow/lib/python3.9/site-packages/torchani/resources/
failed to equip `nnpops` with error: No module named 'NNPOps'

Optimising conformer:   0%|                               | 0/4 [00:00<?, ?it/s][AOptimising conformer:  81%|█████████████████    | 17/21 [00:45<00:08,  2.15s/it]Optimising conformer:  86%|██████████████████   | 18/21 [00:48<00:06,  2.21s/it]
Optimising conformer:  25%|█████▊                 | 1/4 [00:04<00:14,  4.84s/it][AOptimising conformer:  90%|███████████████████  | 19/21 [00:50<00:04,  2.37s/it]
Optimising conformer:  50%|███████████▌           | 2/4 [00:06<00:06,  3.17s/it][A
Optimising conformer:  75%|█████████████████▎     | 3/4 [00:08<00:02,  2.28s/it][AOptimising conformer:  95%|████████████████████ | 20/21 [00:53<00:02,  2.31s/it]
Optimising conformer: 100%|███████████████████████| 4/4 [00:11<00:00,  2.57s/it][AOptimising conformer: 100%|███████████████████████| 4/4 [00:11<00:00,  2.77s/it]
Optimising conformer: 100%|█████████████████████| 21/21 [00:55<00:00,  2.39s/it]Optimising conformer: 100%|█████████████████████| 21/21 [00:55<00:00,  2.65s/it]
2024-01-19 09:24:31,912 - distributed.worker - ERROR - Failed to communicate with scheduler during heartbeat.
Traceback (most recent call last):
  File "/mnt/storage/nobackup/nmb1063/mamba/envs/fegrow/lib/python3.9/site-packages/tornado/iostream.py", line 861, in _read_to_buffer
    bytes_read = self.read_from_fd(buf)
  File "/mnt/storage/nobackup/nmb1063/mamba/envs/fegrow/lib/python3.9/site-packages/tornado/iostream.py", line 1116, in read_from_fd
    return self.socket.recv_into(buf, len(buf))
TimeoutError: [Errno 110] Connection timed out

The above exception was the direct cause of the following exception:

Traceback (most recent call last):
  File "/mnt/storage/nobackup/nmb1063/mamba/envs/fegrow/lib/python3.9/site-packages/distributed/worker.py", line 1237, in heartbeat
    response = await retry_operation(
  File "/mnt/storage/nobackup/nmb1063/mamba/envs/fegrow/lib/python3.9/site-packages/distributed/utils_comm.py", line 434, in retry_operation
    return await retry(
  File "/mnt/storage/nobackup/nmb1063/mamba/envs/fegrow/lib/python3.9/site-packages/distributed/utils_comm.py", line 413, in retry
    return await coro()
  File "/mnt/storage/nobackup/nmb1063/mamba/envs/fegrow/lib/python3.9/site-packages/distributed/core.py", line 1227, in send_recv_from_rpc
    return await send_recv(comm=comm, op=key, **kwargs)
  File "/mnt/storage/nobackup/nmb1063/mamba/envs/fegrow/lib/python3.9/site-packages/distributed/core.py", line 986, in send_recv
    response = await comm.read(deserializers=deserializers)
  File "/mnt/storage/nobackup/nmb1063/mamba/envs/fegrow/lib/python3.9/site-packages/distributed/comm/tcp.py", line 241, in read
    convert_stream_closed_error(self, e)
  File "/mnt/storage/nobackup/nmb1063/mamba/envs/fegrow/lib/python3.9/site-packages/distributed/comm/tcp.py", line 142, in convert_stream_closed_error
    raise CommClosedError(f"in {obj}: {exc.__class__.__name__}: {exc}") from exc
distributed.comm.core.CommClosedError: in <TCP (closed) ConnectionPool.heartbeat_worker local=tcp://10.3.89.128:39544 remote=tcp://10.3.88.12:42763>: TimeoutError: [Errno 110] Connection timed out
2024-01-19 09:24:31,912 - distributed.worker - ERROR - Failed to communicate with scheduler during heartbeat.
Traceback (most recent call last):
  File "/mnt/storage/nobackup/nmb1063/mamba/envs/fegrow/lib/python3.9/site-packages/tornado/iostream.py", line 861, in _read_to_buffer
    bytes_read = self.read_from_fd(buf)
  File "/mnt/storage/nobackup/nmb1063/mamba/envs/fegrow/lib/python3.9/site-packages/tornado/iostream.py", line 1116, in read_from_fd
    return self.socket.recv_into(buf, len(buf))
TimeoutError: [Errno 110] Connection timed out

The above exception was the direct cause of the following exception:

Traceback (most recent call last):
  File "/mnt/storage/nobackup/nmb1063/mamba/envs/fegrow/lib/python3.9/site-packages/distributed/worker.py", line 1237, in heartbeat
    response = await retry_operation(
  File "/mnt/storage/nobackup/nmb1063/mamba/envs/fegrow/lib/python3.9/site-packages/distributed/utils_comm.py", line 434, in retry_operation
    return await retry(
  File "/mnt/storage/nobackup/nmb1063/mamba/envs/fegrow/lib/python3.9/site-packages/distributed/utils_comm.py", line 413, in retry
    return await coro()
  File "/mnt/storage/nobackup/nmb1063/mamba/envs/fegrow/lib/python3.9/site-packages/distributed/core.py", line 1227, in send_recv_from_rpc
    return await send_recv(comm=comm, op=key, **kwargs)
  File "/mnt/storage/nobackup/nmb1063/mamba/envs/fegrow/lib/python3.9/site-packages/distributed/core.py", line 986, in send_recv
    response = await comm.read(deserializers=deserializers)
  File "/mnt/storage/nobackup/nmb1063/mamba/envs/fegrow/lib/python3.9/site-packages/distributed/comm/tcp.py", line 241, in read
    convert_stream_closed_error(self, e)
  File "/mnt/storage/nobackup/nmb1063/mamba/envs/fegrow/lib/python3.9/site-packages/distributed/comm/tcp.py", line 142, in convert_stream_closed_error
    raise CommClosedError(f"in {obj}: {exc.__class__.__name__}: {exc}") from exc
distributed.comm.core.CommClosedError: in <TCP (closed) ConnectionPool.heartbeat_worker local=tcp://10.3.89.128:39546 remote=tcp://10.3.88.12:42763>: TimeoutError: [Errno 110] Connection timed out
2024-01-19 09:24:53,543 - distributed.core - INFO - Connection to tcp://10.3.88.12:42763 has been closed.
2024-01-19 09:24:53,544 - distributed.worker - INFO - Stopping worker at tcp://10.3.89.128:40147. Reason: worker-handle-scheduler-connection-broken
2024-01-19 09:24:53,543 - distributed.core - INFO - Connection to tcp://10.3.88.12:42763 has been closed.
2024-01-19 09:24:53,551 - distributed.worker - INFO - Stopping worker at tcp://10.3.89.128:34338. Reason: worker-handle-scheduler-connection-broken
2024-01-19 09:24:53,553 - distributed.nanny - INFO - Closing Nanny gracefully at 'tcp://10.3.89.128:33872'. Reason: worker-handle-scheduler-connection-broken
2024-01-19 09:24:53,555 - distributed.nanny - INFO - Closing Nanny gracefully at 'tcp://10.3.89.128:33442'. Reason: worker-handle-scheduler-connection-broken
2024-01-19 09:24:53,568 - distributed.worker - ERROR - Failed to communicate with scheduler during heartbeat.
Traceback (most recent call last):
  File "/mnt/storage/nobackup/nmb1063/mamba/envs/fegrow/lib/python3.9/site-packages/distributed/core.py", line 1389, in _connect
    comm = await connect(
  File "/mnt/storage/nobackup/nmb1063/mamba/envs/fegrow/lib/python3.9/site-packages/distributed/comm/core.py", line 291, in connect
    comm = await asyncio.wait_for(
  File "/mnt/storage/nobackup/nmb1063/mamba/envs/fegrow/lib/python3.9/asyncio/tasks.py", line 466, in wait_for
    await waiter
asyncio.exceptions.CancelledError

During handling of the above exception, another exception occurred:

Traceback (most recent call last):
  File "/mnt/storage/nobackup/nmb1063/mamba/envs/fegrow/lib/python3.9/site-packages/distributed/worker.py", line 1237, in heartbeat
    response = await retry_operation(
  File "/mnt/storage/nobackup/nmb1063/mamba/envs/fegrow/lib/python3.9/site-packages/distributed/utils_comm.py", line 434, in retry_operation
    return await retry(
  File "/mnt/storage/nobackup/nmb1063/mamba/envs/fegrow/lib/python3.9/site-packages/distributed/utils_comm.py", line 413, in retry
    return await coro()
  File "/mnt/storage/nobackup/nmb1063/mamba/envs/fegrow/lib/python3.9/site-packages/distributed/core.py", line 1224, in send_recv_from_rpc
    comm = await self.pool.connect(self.addr)
  File "/mnt/storage/nobackup/nmb1063/mamba/envs/fegrow/lib/python3.9/site-packages/distributed/core.py", line 1468, in connect
    return await connect_attempt
  File "/mnt/storage/nobackup/nmb1063/mamba/envs/fegrow/lib/python3.9/site-packages/distributed/core.py", line 1412, in _connect
    raise CommClosedError(reason)
distributed.comm.core.CommClosedError: ConnectionPool closing.
2024-01-19 09:24:53,564 - distributed.worker - ERROR - Failed to communicate with scheduler during heartbeat.
Traceback (most recent call last):
  File "/mnt/storage/nobackup/nmb1063/mamba/envs/fegrow/lib/python3.9/site-packages/distributed/core.py", line 1389, in _connect
    comm = await connect(
  File "/mnt/storage/nobackup/nmb1063/mamba/envs/fegrow/lib/python3.9/site-packages/distributed/comm/core.py", line 291, in connect
    comm = await asyncio.wait_for(
  File "/mnt/storage/nobackup/nmb1063/mamba/envs/fegrow/lib/python3.9/asyncio/tasks.py", line 466, in wait_for
    await waiter
asyncio.exceptions.CancelledError

During handling of the above exception, another exception occurred:

Traceback (most recent call last):
  File "/mnt/storage/nobackup/nmb1063/mamba/envs/fegrow/lib/python3.9/site-packages/distributed/worker.py", line 1237, in heartbeat
    response = await retry_operation(
  File "/mnt/storage/nobackup/nmb1063/mamba/envs/fegrow/lib/python3.9/site-packages/distributed/utils_comm.py", line 434, in retry_operation
    return await retry(
  File "/mnt/storage/nobackup/nmb1063/mamba/envs/fegrow/lib/python3.9/site-packages/distributed/utils_comm.py", line 413, in retry
    return await coro()
  File "/mnt/storage/nobackup/nmb1063/mamba/envs/fegrow/lib/python3.9/site-packages/distributed/core.py", line 1224, in send_recv_from_rpc
    comm = await self.pool.connect(self.addr)
  File "/mnt/storage/nobackup/nmb1063/mamba/envs/fegrow/lib/python3.9/site-packages/distributed/core.py", line 1468, in connect
    return await connect_attempt
  File "/mnt/storage/nobackup/nmb1063/mamba/envs/fegrow/lib/python3.9/site-packages/distributed/core.py", line 1412, in _connect
    raise CommClosedError(reason)
distributed.comm.core.CommClosedError: ConnectionPool closing.
2024-01-19 09:24:53,573 - distributed.nanny - INFO - Worker closed
2024-01-19 09:24:53,574 - distributed.nanny - INFO - Worker closed
2024-01-19 09:24:55,586 - distributed.nanny - ERROR - Worker process died unexpectedly
TIME Completed the molecule generation in 103.7s.
TIME Completed the molecule generation in 107.6s.
2024-01-19 09:24:56,025 - distributed.nanny - INFO - Closing Nanny at 'tcp://10.3.89.128:33872'. Reason: nanny-close-gracefully
2024-01-19 09:24:58,504 - distributed.nanny - INFO - Closing Nanny at 'tcp://10.3.89.128:33442'. Reason: nanny-close-gracefully
2024-01-19 09:24:58,507 - distributed.dask_worker - INFO - End worker
