hostname sb104.cluster
ipconfig 1: lo: <LOOPBACK,UP,LOWER_UP> mtu 65536 qdisc noqueue state UNKNOWN group default qlen 1000 link/loopback 00:00:00:00:00:00 brd 00:00:00:00:00:00 inet 127.0.0.1/8 scope host lo valid_lft forever preferred_lft forever inet6 ::1/128 scope host valid_lft forever preferred_lft forever 2: enp4s0f0: <BROADCAST,MULTICAST,UP,LOWER_UP> mtu 9000 qdisc mq state UP group default qlen 1000 link/ether a0:8c:f8:61:07:6e brd ff:ff:ff:ff:ff:ff inet 10.3.81.184/22 brd 10.3.83.255 scope global enp4s0f0 valid_lft forever preferred_lft forever inet6 fe80::a28c:f8ff:fe61:76e/64 scope link valid_lft forever preferred_lft forever 3: enp4s0f1: <BROADCAST,MULTICAST> mtu 1500 qdisc noop state DOWN group default qlen 1000 link/ether a0:8c:f8:61:07:6f brd ff:ff:ff:ff:ff:ff 4: enp4s0f2: <BROADCAST,MULTICAST> mtu 1500 qdisc noop state DOWN group default qlen 1000 link/ether a0:8c:f8:61:07:70 brd ff:ff:ff:ff:ff:ff 5: enp4s0f3: <BROADCAST,MULTICAST> mtu 1500 qdisc noop state DOWN group default qlen 1000 link/ether a0:8c:f8:61:07:71 brd ff:ff:ff:ff:ff:ff 6: ib0: <BROADCAST,MULTICAST,UP,LOWER_UP> mtu 4092 qdisc pfifo_fast state UP group default qlen 256 link/infiniband 80:00:00:29:fe:80:00:00:00:00:00:00:88:66:39:03:00:23:b9:71 brd 00:ff:ff:ff:ff:12:40:1b:ff:ff:00:00:00:00:00:00:ff:ff:ff:ff inet 10.3.89.184/22 brd 10.3.91.255 scope global ib0 valid_lft forever preferred_lft forever inet 10.3.97.184/22 brd 10.3.99.255 scope global ib0:1 valid_lft forever preferred_lft forever inet6 fe80::8a66:3903:23:b971/64 scope link valid_lft forever preferred_lft forever 7: ib1: <NO-CARRIER,BROADCAST,MULTICAST,UP> mtu 4092 qdisc pfifo_fast state DOWN group default qlen 256 link/infiniband 80:00:00:29:fe:80:00:00:00:00:00:00:88:66:39:03:00:23:b9:72 brd 00:ff:ff:ff:ff:12:40:1b:ff:ff:00:00:00:00:00:00:ff:ff:ff:ff
2024-01-19 07:59:30,095 - distributed.nanny - INFO -         Start Nanny at: 'tcp://10.3.89.184:44148'
2024-01-19 07:59:30,117 - distributed.nanny - INFO -         Start Nanny at: 'tcp://10.3.89.184:36907'
2024-01-19 07:59:31,909 - distributed.diskutils - INFO - Found stale lock file and directory '/scratch/dask-worker-space/worker-9rkaay1j', purging
2024-01-19 07:59:31,910 - distributed.diskutils - INFO - Found stale lock file and directory '/scratch/dask-worker-space/worker-b23fe9t9', purging
2024-01-19 07:59:45,081 - distributed.worker - INFO -       Start worker at:    tcp://10.3.89.184:37674
2024-01-19 07:59:45,083 - distributed.worker - INFO -          Listening to:    tcp://10.3.89.184:37674
2024-01-19 07:59:45,083 - distributed.worker - INFO -           Worker name:         SLURMCluster-186-1
2024-01-19 07:59:45,083 - distributed.worker - INFO -          dashboard at:          10.3.89.184:41749
2024-01-19 07:59:45,083 - distributed.worker - INFO - Waiting to connect to:     tcp://10.3.88.12:42763
2024-01-19 07:59:45,083 - distributed.worker - INFO - -------------------------------------------------
2024-01-19 07:59:45,083 - distributed.worker - INFO -               Threads:                          2
2024-01-19 07:59:45,083 - distributed.worker - INFO -                Memory:                  10.24 GiB
2024-01-19 07:59:45,083 - distributed.worker - INFO -       Local Directory: /scratch/dask-worker-space/worker-llc6kqe5
2024-01-19 07:59:45,083 - distributed.worker - INFO - -------------------------------------------------
2024-01-19 07:59:45,118 - distributed.worker - INFO -       Start worker at:    tcp://10.3.89.184:37621
2024-01-19 07:59:45,119 - distributed.worker - INFO -          Listening to:    tcp://10.3.89.184:37621
2024-01-19 07:59:45,119 - distributed.worker - INFO -           Worker name:         SLURMCluster-186-0
2024-01-19 07:59:45,120 - distributed.worker - INFO -          dashboard at:          10.3.89.184:40861
2024-01-19 07:59:45,120 - distributed.worker - INFO - Waiting to connect to:     tcp://10.3.88.12:42763
2024-01-19 07:59:45,120 - distributed.worker - INFO - -------------------------------------------------
2024-01-19 07:59:45,120 - distributed.worker - INFO -               Threads:                          2
2024-01-19 07:59:45,120 - distributed.worker - INFO -                Memory:                  10.24 GiB
2024-01-19 07:59:45,120 - distributed.worker - INFO -       Local Directory: /scratch/dask-worker-space/worker-x1kvr7og
2024-01-19 07:59:45,120 - distributed.worker - INFO - -------------------------------------------------
2024-01-19 07:59:45,162 - distributed.worker - INFO -         Registered to:     tcp://10.3.88.12:42763
2024-01-19 07:59:45,162 - distributed.worker - INFO - -------------------------------------------------
2024-01-19 07:59:45,163 - distributed.core - INFO - Starting established connection to tcp://10.3.88.12:42763
2024-01-19 07:59:45,166 - distributed.worker - INFO -         Registered to:     tcp://10.3.88.12:42763
2024-01-19 07:59:45,166 - distributed.worker - INFO - -------------------------------------------------
2024-01-19 07:59:45,167 - distributed.core - INFO - Starting established connection to tcp://10.3.88.12:42763
2024-01-19 09:04:44,804 - distributed.core - INFO - Event loop was unresponsive in Nanny for 4.17s.  This is often caused by long-running GIL-holding functions or moving large chunks of data. This can cause timeouts and instability.
2024-01-19 09:04:44,805 - distributed.core - INFO - Event loop was unresponsive in Nanny for 4.16s.  This is often caused by long-running GIL-holding functions or moving large chunks of data. This can cause timeouts and instability.
2024-01-19 09:04:44,809 - distributed.core - INFO - Event loop was unresponsive in Worker for 11.27s.  This is often caused by long-running GIL-holding functions or moving large chunks of data. This can cause timeouts and instability.
2024-01-19 09:04:44,825 - distributed.core - INFO - Event loop was unresponsive in Worker for 11.28s.  This is often caused by long-running GIL-holding functions or moving large chunks of data. This can cause timeouts and instability.
2024-01-19 09:24:31,629 - distributed.worker - ERROR - Failed to communicate with scheduler during heartbeat.
Traceback (most recent call last):
  File "/mnt/storage/nobackup/nmb1063/mamba/envs/fegrow/lib/python3.9/site-packages/tornado/iostream.py", line 861, in _read_to_buffer
    bytes_read = self.read_from_fd(buf)
  File "/mnt/storage/nobackup/nmb1063/mamba/envs/fegrow/lib/python3.9/site-packages/tornado/iostream.py", line 1116, in read_from_fd
    return self.socket.recv_into(buf, len(buf))
TimeoutError: [Errno 110] Connection timed out

The above exception was the direct cause of the following exception:

Traceback (most recent call last):
  File "/mnt/storage/nobackup/nmb1063/mamba/envs/fegrow/lib/python3.9/site-packages/distributed/worker.py", line 1237, in heartbeat
    response = await retry_operation(
  File "/mnt/storage/nobackup/nmb1063/mamba/envs/fegrow/lib/python3.9/site-packages/distributed/utils_comm.py", line 434, in retry_operation
    return await retry(
  File "/mnt/storage/nobackup/nmb1063/mamba/envs/fegrow/lib/python3.9/site-packages/distributed/utils_comm.py", line 413, in retry
    return await coro()
  File "/mnt/storage/nobackup/nmb1063/mamba/envs/fegrow/lib/python3.9/site-packages/distributed/core.py", line 1227, in send_recv_from_rpc
    return await send_recv(comm=comm, op=key, **kwargs)
  File "/mnt/storage/nobackup/nmb1063/mamba/envs/fegrow/lib/python3.9/site-packages/distributed/core.py", line 986, in send_recv
    response = await comm.read(deserializers=deserializers)
  File "/mnt/storage/nobackup/nmb1063/mamba/envs/fegrow/lib/python3.9/site-packages/distributed/comm/tcp.py", line 241, in read
    convert_stream_closed_error(self, e)
  File "/mnt/storage/nobackup/nmb1063/mamba/envs/fegrow/lib/python3.9/site-packages/distributed/comm/tcp.py", line 142, in convert_stream_closed_error
    raise CommClosedError(f"in {obj}: {exc.__class__.__name__}: {exc}") from exc
distributed.comm.core.CommClosedError: in <TCP (closed) ConnectionPool.heartbeat_worker local=tcp://10.3.89.184:50834 remote=tcp://10.3.88.12:42763>: TimeoutError: [Errno 110] Connection timed out
2024-01-19 09:24:31,629 - distributed.worker - ERROR - Failed to communicate with scheduler during heartbeat.
Traceback (most recent call last):
  File "/mnt/storage/nobackup/nmb1063/mamba/envs/fegrow/lib/python3.9/site-packages/tornado/iostream.py", line 861, in _read_to_buffer
    bytes_read = self.read_from_fd(buf)
  File "/mnt/storage/nobackup/nmb1063/mamba/envs/fegrow/lib/python3.9/site-packages/tornado/iostream.py", line 1116, in read_from_fd
    return self.socket.recv_into(buf, len(buf))
TimeoutError: [Errno 110] Connection timed out

The above exception was the direct cause of the following exception:

Traceback (most recent call last):
  File "/mnt/storage/nobackup/nmb1063/mamba/envs/fegrow/lib/python3.9/site-packages/distributed/worker.py", line 1237, in heartbeat
    response = await retry_operation(
  File "/mnt/storage/nobackup/nmb1063/mamba/envs/fegrow/lib/python3.9/site-packages/distributed/utils_comm.py", line 434, in retry_operation
    return await retry(
  File "/mnt/storage/nobackup/nmb1063/mamba/envs/fegrow/lib/python3.9/site-packages/distributed/utils_comm.py", line 413, in retry
    return await coro()
  File "/mnt/storage/nobackup/nmb1063/mamba/envs/fegrow/lib/python3.9/site-packages/distributed/core.py", line 1227, in send_recv_from_rpc
    return await send_recv(comm=comm, op=key, **kwargs)
  File "/mnt/storage/nobackup/nmb1063/mamba/envs/fegrow/lib/python3.9/site-packages/distributed/core.py", line 986, in send_recv
    response = await comm.read(deserializers=deserializers)
  File "/mnt/storage/nobackup/nmb1063/mamba/envs/fegrow/lib/python3.9/site-packages/distributed/comm/tcp.py", line 241, in read
    convert_stream_closed_error(self, e)
  File "/mnt/storage/nobackup/nmb1063/mamba/envs/fegrow/lib/python3.9/site-packages/distributed/comm/tcp.py", line 142, in convert_stream_closed_error
    raise CommClosedError(f"in {obj}: {exc.__class__.__name__}: {exc}") from exc
distributed.comm.core.CommClosedError: in <TCP (closed) ConnectionPool.heartbeat_worker local=tcp://10.3.89.184:50832 remote=tcp://10.3.88.12:42763>: TimeoutError: [Errno 110] Connection timed out
2024-01-19 09:24:36,748 - distributed.core - INFO - Connection to tcp://10.3.88.12:42763 has been closed.
2024-01-19 09:24:36,748 - distributed.core - INFO - Connection to tcp://10.3.88.12:42763 has been closed.
2024-01-19 09:24:36,749 - distributed.worker - INFO - Stopping worker at tcp://10.3.89.184:37621. Reason: worker-handle-scheduler-connection-broken
2024-01-19 09:24:36,749 - distributed.worker - INFO - Stopping worker at tcp://10.3.89.184:37674. Reason: worker-handle-scheduler-connection-broken
2024-01-19 09:24:36,759 - distributed.nanny - INFO - Closing Nanny gracefully at 'tcp://10.3.89.184:36907'. Reason: worker-handle-scheduler-connection-broken
2024-01-19 09:24:36,760 - distributed.nanny - INFO - Closing Nanny gracefully at 'tcp://10.3.89.184:44148'. Reason: worker-handle-scheduler-connection-broken
2024-01-19 09:24:36,769 - distributed.worker - ERROR - Failed to communicate with scheduler during heartbeat.
Traceback (most recent call last):
  File "/mnt/storage/nobackup/nmb1063/mamba/envs/fegrow/lib/python3.9/site-packages/distributed/core.py", line 1389, in _connect
    comm = await connect(
  File "/mnt/storage/nobackup/nmb1063/mamba/envs/fegrow/lib/python3.9/site-packages/distributed/comm/core.py", line 291, in connect
    comm = await asyncio.wait_for(
  File "/mnt/storage/nobackup/nmb1063/mamba/envs/fegrow/lib/python3.9/asyncio/tasks.py", line 466, in wait_for
    await waiter
asyncio.exceptions.CancelledError

During handling of the above exception, another exception occurred:

Traceback (most recent call last):
  File "/mnt/storage/nobackup/nmb1063/mamba/envs/fegrow/lib/python3.9/site-packages/distributed/worker.py", line 1237, in heartbeat
    response = await retry_operation(
  File "/mnt/storage/nobackup/nmb1063/mamba/envs/fegrow/lib/python3.9/site-packages/distributed/utils_comm.py", line 434, in retry_operation
    return await retry(
  File "/mnt/storage/nobackup/nmb1063/mamba/envs/fegrow/lib/python3.9/site-packages/distributed/utils_comm.py", line 413, in retry
    return await coro()
  File "/mnt/storage/nobackup/nmb1063/mamba/envs/fegrow/lib/python3.9/site-packages/distributed/core.py", line 1224, in send_recv_from_rpc
    comm = await self.pool.connect(self.addr)
  File "/mnt/storage/nobackup/nmb1063/mamba/envs/fegrow/lib/python3.9/site-packages/distributed/core.py", line 1468, in connect
    return await connect_attempt
  File "/mnt/storage/nobackup/nmb1063/mamba/envs/fegrow/lib/python3.9/site-packages/distributed/core.py", line 1412, in _connect
    raise CommClosedError(reason)
distributed.comm.core.CommClosedError: ConnectionPool closing.
2024-01-19 09:24:36,788 - distributed.nanny - INFO - Worker closed
2024-01-19 09:24:36,769 - distributed.worker - ERROR - Failed to communicate with scheduler during heartbeat.
Traceback (most recent call last):
  File "/mnt/storage/nobackup/nmb1063/mamba/envs/fegrow/lib/python3.9/site-packages/distributed/core.py", line 1389, in _connect
    comm = await connect(
  File "/mnt/storage/nobackup/nmb1063/mamba/envs/fegrow/lib/python3.9/site-packages/distributed/comm/core.py", line 291, in connect
    comm = await asyncio.wait_for(
  File "/mnt/storage/nobackup/nmb1063/mamba/envs/fegrow/lib/python3.9/asyncio/tasks.py", line 466, in wait_for
    await waiter
asyncio.exceptions.CancelledError

During handling of the above exception, another exception occurred:

Traceback (most recent call last):
  File "/mnt/storage/nobackup/nmb1063/mamba/envs/fegrow/lib/python3.9/site-packages/distributed/worker.py", line 1237, in heartbeat
    response = await retry_operation(
  File "/mnt/storage/nobackup/nmb1063/mamba/envs/fegrow/lib/python3.9/site-packages/distributed/utils_comm.py", line 434, in retry_operation
    return await retry(
  File "/mnt/storage/nobackup/nmb1063/mamba/envs/fegrow/lib/python3.9/site-packages/distributed/utils_comm.py", line 413, in retry
    return await coro()
  File "/mnt/storage/nobackup/nmb1063/mamba/envs/fegrow/lib/python3.9/site-packages/distributed/core.py", line 1224, in send_recv_from_rpc
    comm = await self.pool.connect(self.addr)
  File "/mnt/storage/nobackup/nmb1063/mamba/envs/fegrow/lib/python3.9/site-packages/distributed/core.py", line 1468, in connect
    return await connect_attempt
  File "/mnt/storage/nobackup/nmb1063/mamba/envs/fegrow/lib/python3.9/site-packages/distributed/core.py", line 1412, in _connect
    raise CommClosedError(reason)
distributed.comm.core.CommClosedError: ConnectionPool closing.
2024-01-19 09:24:36,789 - distributed.nanny - INFO - Worker closed
2024-01-19 09:24:38,800 - distributed.nanny - ERROR - Worker process died unexpectedly
2024-01-19 09:24:40,368 - distributed.nanny - INFO - Closing Nanny at 'tcp://10.3.89.184:44148'. Reason: nanny-close-gracefully
2024-01-19 09:24:40,370 - distributed.nanny - INFO - Closing Nanny at 'tcp://10.3.89.184:36907'. Reason: nanny-close-gracefully
2024-01-19 09:24:40,372 - distributed.dask_worker - INFO - End worker
