hostname sb096.cluster
ipconfig 1: lo: <LOOPBACK,UP,LOWER_UP> mtu 65536 qdisc noqueue state UNKNOWN group default qlen 1000 link/loopback 00:00:00:00:00:00 brd 00:00:00:00:00:00 inet 127.0.0.1/8 scope host lo valid_lft forever preferred_lft forever inet6 ::1/128 scope host valid_lft forever preferred_lft forever 2: enp4s0f0: <BROADCAST,MULTICAST,UP,LOWER_UP> mtu 9000 qdisc mq state UP group default qlen 1000 link/ether a0:8c:f8:61:07:a2 brd ff:ff:ff:ff:ff:ff inet 10.3.81.176/22 brd 10.3.83.255 scope global enp4s0f0 valid_lft forever preferred_lft forever inet6 fe80::a28c:f8ff:fe61:7a2/64 scope link valid_lft forever preferred_lft forever 3: enp4s0f1: <BROADCAST,MULTICAST> mtu 1500 qdisc noop state DOWN group default qlen 1000 link/ether a0:8c:f8:61:07:a3 brd ff:ff:ff:ff:ff:ff 4: enp4s0f2: <BROADCAST,MULTICAST> mtu 1500 qdisc noop state DOWN group default qlen 1000 link/ether a0:8c:f8:61:07:a4 brd ff:ff:ff:ff:ff:ff 5: enp4s0f3: <BROADCAST,MULTICAST> mtu 1500 qdisc noop state DOWN group default qlen 1000 link/ether a0:8c:f8:61:07:a5 brd ff:ff:ff:ff:ff:ff 6: ib0: <BROADCAST,MULTICAST,UP,LOWER_UP> mtu 4092 qdisc pfifo_fast state UP group default qlen 256 link/infiniband 80:00:00:29:fe:80:00:00:00:00:00:00:88:66:39:03:00:23:bc:71 brd 00:ff:ff:ff:ff:12:40:1b:ff:ff:00:00:00:00:00:00:ff:ff:ff:ff inet 10.3.89.176/22 brd 10.3.91.255 scope global ib0 valid_lft forever preferred_lft forever inet 10.3.97.176/22 brd 10.3.99.255 scope global ib0:1 valid_lft forever preferred_lft forever inet6 fe80::8a66:3903:23:bc71/64 scope link valid_lft forever preferred_lft forever 7: ib1: <BROADCAST,MULTICAST> mtu 4092 qdisc noop state DOWN group default qlen 256 link/infiniband 80:00:00:29:fe:80:00:00:00:00:00:00:88:66:39:03:00:23:bc:72 brd 00:ff:ff:ff:ff:12:40:1b:ff:ff:00:00:00:00:00:00:ff:ff:ff:ff
2024-01-19 05:03:35,769 - distributed.nanny - INFO -         Start Nanny at: 'tcp://10.3.89.176:45582'
2024-01-19 05:03:35,835 - distributed.nanny - INFO -         Start Nanny at: 'tcp://10.3.89.176:43557'
2024-01-19 05:03:38,063 - distributed.diskutils - INFO - Found stale lock file and directory '/scratch/dask-worker-space/worker-0jparsip', purging
2024-01-19 05:03:48,107 - distributed.worker - INFO -       Start worker at:    tcp://10.3.89.176:41159
2024-01-19 05:03:48,107 - distributed.worker - INFO -       Start worker at:    tcp://10.3.89.176:38728
2024-01-19 05:03:48,108 - distributed.worker - INFO -          Listening to:    tcp://10.3.89.176:41159
2024-01-19 05:03:48,108 - distributed.worker - INFO -           Worker name:          SLURMCluster-61-0
2024-01-19 05:03:48,108 - distributed.worker - INFO -          Listening to:    tcp://10.3.89.176:38728
2024-01-19 05:03:48,108 - distributed.worker - INFO -          dashboard at:          10.3.89.176:36596
2024-01-19 05:03:48,108 - distributed.worker - INFO -           Worker name:          SLURMCluster-61-1
2024-01-19 05:03:48,108 - distributed.worker - INFO - Waiting to connect to:     tcp://10.3.88.12:42763
2024-01-19 05:03:48,108 - distributed.worker - INFO -          dashboard at:          10.3.89.176:38441
2024-01-19 05:03:48,108 - distributed.worker - INFO - -------------------------------------------------
2024-01-19 05:03:48,108 - distributed.worker - INFO - Waiting to connect to:     tcp://10.3.88.12:42763
2024-01-19 05:03:48,108 - distributed.worker - INFO - -------------------------------------------------
2024-01-19 05:03:48,108 - distributed.worker - INFO -               Threads:                          2
2024-01-19 05:03:48,108 - distributed.worker - INFO -               Threads:                          2
2024-01-19 05:03:48,108 - distributed.worker - INFO -                Memory:                  10.24 GiB
2024-01-19 05:03:48,108 - distributed.worker - INFO -                Memory:                  10.24 GiB
2024-01-19 05:03:48,108 - distributed.worker - INFO -       Local Directory: /scratch/dask-worker-space/worker-vpsdlgxl
2024-01-19 05:03:48,109 - distributed.worker - INFO -       Local Directory: /scratch/dask-worker-space/worker-ixxpz_ht
2024-01-19 05:03:48,109 - distributed.worker - INFO - -------------------------------------------------
2024-01-19 05:03:48,109 - distributed.worker - INFO - -------------------------------------------------
2024-01-19 05:03:48,223 - distributed.worker - INFO -         Registered to:     tcp://10.3.88.12:42763
2024-01-19 05:03:48,224 - distributed.worker - INFO - -------------------------------------------------
2024-01-19 05:03:48,224 - distributed.core - INFO - Starting established connection to tcp://10.3.88.12:42763
2024-01-19 05:03:48,228 - distributed.worker - INFO -         Registered to:     tcp://10.3.88.12:42763
2024-01-19 05:03:48,228 - distributed.worker - INFO - -------------------------------------------------
2024-01-19 05:03:48,229 - distributed.core - INFO - Starting established connection to tcp://10.3.88.12:42763
2024-01-19 05:37:21,225 - distributed.worker - ERROR - Worker stream died during communication: tcp://10.3.89.134:36679
Traceback (most recent call last):
  File "/mnt/storage/nobackup/nmb1063/mamba/envs/fegrow/lib/python3.9/site-packages/distributed/comm/tcp.py", line 225, in read
    frames_nbytes = await stream.read_bytes(fmt_size)
asyncio.exceptions.CancelledError

During handling of the above exception, another exception occurred:

Traceback (most recent call last):
  File "/mnt/storage/nobackup/nmb1063/mamba/envs/fegrow/lib/python3.9/asyncio/tasks.py", line 490, in wait_for
    return fut.result()
asyncio.exceptions.CancelledError

The above exception was the direct cause of the following exception:

Traceback (most recent call last):
  File "/mnt/storage/nobackup/nmb1063/mamba/envs/fegrow/lib/python3.9/site-packages/distributed/comm/core.py", line 328, in connect
    handshake = await asyncio.wait_for(comm.read(), time_left())
  File "/mnt/storage/nobackup/nmb1063/mamba/envs/fegrow/lib/python3.9/asyncio/tasks.py", line 492, in wait_for
    raise exceptions.TimeoutError() from exc
asyncio.exceptions.TimeoutError

The above exception was the direct cause of the following exception:

Traceback (most recent call last):
  File "/mnt/storage/nobackup/nmb1063/mamba/envs/fegrow/lib/python3.9/site-packages/distributed/worker.py", line 2081, in gather_dep
    response = await get_data_from_worker(
  File "/mnt/storage/nobackup/nmb1063/mamba/envs/fegrow/lib/python3.9/site-packages/distributed/worker.py", line 2900, in get_data_from_worker
    comm = await rpc.connect(worker)
  File "/mnt/storage/nobackup/nmb1063/mamba/envs/fegrow/lib/python3.9/site-packages/distributed/core.py", line 1468, in connect
    return await connect_attempt
  File "/mnt/storage/nobackup/nmb1063/mamba/envs/fegrow/lib/python3.9/site-packages/distributed/core.py", line 1389, in _connect
    comm = await connect(
  File "/mnt/storage/nobackup/nmb1063/mamba/envs/fegrow/lib/python3.9/site-packages/distributed/comm/core.py", line 333, in connect
    raise OSError(
OSError: Timed out during handshake while connecting to tcp://10.3.89.134:36679 after 30 s
2024-01-19 05:37:21,244 - distributed.worker - ERROR - Worker stream died during communication: tcp://10.3.89.129:41350
Traceback (most recent call last):
  File "/mnt/storage/nobackup/nmb1063/mamba/envs/fegrow/lib/python3.9/site-packages/distributed/comm/tcp.py", line 225, in read
    frames_nbytes = await stream.read_bytes(fmt_size)
asyncio.exceptions.CancelledError

During handling of the above exception, another exception occurred:

Traceback (most recent call last):
  File "/mnt/storage/nobackup/nmb1063/mamba/envs/fegrow/lib/python3.9/asyncio/tasks.py", line 490, in wait_for
    return fut.result()
asyncio.exceptions.CancelledError

The above exception was the direct cause of the following exception:

Traceback (most recent call last):
  File "/mnt/storage/nobackup/nmb1063/mamba/envs/fegrow/lib/python3.9/site-packages/distributed/comm/core.py", line 328, in connect
    handshake = await asyncio.wait_for(comm.read(), time_left())
  File "/mnt/storage/nobackup/nmb1063/mamba/envs/fegrow/lib/python3.9/asyncio/tasks.py", line 492, in wait_for
    raise exceptions.TimeoutError() from exc
asyncio.exceptions.TimeoutError

The above exception was the direct cause of the following exception:

Traceback (most recent call last):
  File "/mnt/storage/nobackup/nmb1063/mamba/envs/fegrow/lib/python3.9/site-packages/distributed/worker.py", line 2081, in gather_dep
    response = await get_data_from_worker(
  File "/mnt/storage/nobackup/nmb1063/mamba/envs/fegrow/lib/python3.9/site-packages/distributed/worker.py", line 2900, in get_data_from_worker
    comm = await rpc.connect(worker)
  File "/mnt/storage/nobackup/nmb1063/mamba/envs/fegrow/lib/python3.9/site-packages/distributed/core.py", line 1468, in connect
    return await connect_attempt
  File "/mnt/storage/nobackup/nmb1063/mamba/envs/fegrow/lib/python3.9/site-packages/distributed/core.py", line 1389, in _connect
    comm = await connect(
  File "/mnt/storage/nobackup/nmb1063/mamba/envs/fegrow/lib/python3.9/site-packages/distributed/comm/core.py", line 333, in connect
    raise OSError(
OSError: Timed out during handshake while connecting to tcp://10.3.89.129:41350 after 30 s
2024-01-19 05:37:54,514 - distributed.core - INFO - Event loop was unresponsive in Worker for 33.27s.  This is often caused by long-running GIL-holding functions or moving large chunks of data. This can cause timeouts and instability.
/mnt/storage/nobackup/nmb1063/mamba/envs/fegrow/lib/python3.9/site-packages/parmed/structure.py:1775: UnitStrippedWarning: The unit of the quantity is stripped when downcasting to ndarray.
  coords = np.array(value, dtype=np.float64, copy=False, subok=True)
/mnt/storage/nobackup/nmb1063/mamba/envs/fegrow/lib/python3.9/site-packages/torchani/__init__.py:55: UserWarning: Dependency not satisfied, torchani.ase will not be available
  warnings.warn("Dependency not satisfied, torchani.ase will not be available")
Warning: importing 'simtk.openmm' is deprecated.  Import 'openmm' instead.
2024-01-19 05:39:32,516 - distributed.worker - WARNING - Compute Failed
Key:       evaluate-23a5f3d7-cd0e-4767-98ad-ff1703bb7af7
Function:  evaluate
args:      (<rdkit.Chem.rdchem.Mol object at 0x2b3555824590>, 6, '[H]c1nc([H])c(N([H])c2c([H])nn([H])c2-c2sc(Cl)c([H])c2[H])c([H])c1[H]', '/mnt/storage/nobackup/nmb1063/code/gal/sars-cov-2-main-protease-al-study/rec_final.pdb', '/nobackup/nmb1063/sars-fegrow/gnina')
kwargs:    {}
Exception: 'RuntimeError("Can\'t redefine method: forward on class: __torch__.torchani.nn.SpeciesConverter (of Python compilation unit at: 0x2b355bc4f270)")'

TIME changed dir: 0.0s
TIME changed dir: 0.0s
Generated 8 conformers. 
Removed 3 conformers. 
Generated 18 conformers. 
Removed 13 conformers. 
using ani2x
using ani2x
/mnt/storage/nobackup/nmb1063/mamba/envs/fegrow/lib/python3.9/site-packages/torchani/resources/
/mnt/storage/nobackup/nmb1063/mamba/envs/fegrow/lib/python3.9/site-packages/torchani/resources/
failed to equip `nnpops` with error: No module named 'NNPOps'
failed to equip `nnpops` with error: No module named 'NNPOps'
Optimising conformer:   0%|                               | 0/5 [00:00<?, ?it/s][W BinaryOps.cpp:601] Warning: floor_divide is deprecated, and will be removed in a future version of pytorch. It currently rounds toward 0 (like the 'trunc' function NOT 'floor'). This results in incorrect rounding for negative values.
To keep the current behavior, use torch.div(a, b, rounding_mode='trunc'), or for actual floor division, use torch.div(a, b, rounding_mode='floor'). (function operator())
Optimising conformer:  20%|████▌                  | 1/5 [00:03<00:13,  3.41s/it]Optimising conformer:  40%|█████████▏             | 2/5 [00:05<00:08,  2.74s/it]Optimising conformer:  60%|█████████████▊         | 3/5 [00:07<00:04,  2.31s/it]Optimising conformer:  80%|██████████████████▍    | 4/5 [00:08<00:01,  1.98s/it]Optimising conformer: 100%|███████████████████████| 5/5 [00:10<00:00,  2.00s/it]Optimising conformer: 100%|███████████████████████| 5/5 [00:10<00:00,  2.20s/it]
2024-01-19 06:14:36,001 - distributed.utils_perf - INFO - full garbage collection released 25.75 MiB from 490973 reference cycles (threshold: 9.54 MiB)
/mnt/storage/nobackup/nmb1063/mamba/envs/fegrow/lib/python3.9/site-packages/parmed/structure.py:1775: UnitStrippedWarning: The unit of the quantity is stripped when downcasting to ndarray.
  coords = np.array(value, dtype=np.float64, copy=False, subok=True)
/mnt/storage/nobackup/nmb1063/mamba/envs/fegrow/lib/python3.9/site-packages/parmed/structure.py:1775: UnitStrippedWarning: The unit of the quantity is stripped when downcasting to ndarray.
  coords = np.array(value, dtype=np.float64, copy=False, subok=True)
TIME Completed the molecule generation in 115.4s.
TIME changed dir: 0.0s
TIME changed dir: 0.0s
Generated 8 conformers. 
Generated 24 conformers. 
Removed 6 conformers. 
Removed 12 conformers. 
using ani2x
/mnt/storage/nobackup/nmb1063/mamba/envs/fegrow/lib/python3.9/site-packages/torchani/resources/
failed to equip `nnpops` with error: No module named 'NNPOps'
Optimising conformer:   0%|                              | 0/12 [00:00<?, ?it/s]Optimising conformer:   8%|█▊                    | 1/12 [00:04<00:45,  4.11s/it]Optimising conformer:  17%|███▋                  | 2/12 [00:06<00:30,  3.05s/it]Optimising conformer:  25%|█████▌                | 3/12 [00:08<00:24,  2.76s/it]Optimising conformer:  33%|███████▎              | 4/12 [00:12<00:24,  3.02s/it]Optimising conformer:  42%|█████████▏            | 5/12 [00:15<00:21,  3.01s/it]Optimising conformer:  50%|███████████           | 6/12 [00:18<00:18,  3.00s/it]Optimising conformer:  58%|████████████▊         | 7/12 [00:21<00:15,  3.04s/it]Optimising conformer:  67%|██████████████▋       | 8/12 [00:24<00:12,  3.02s/it]Optimising conformer:  75%|████████████████▌     | 9/12 [00:27<00:09,  3.17s/it]Using force field

Optimising conformer:   0%|                               | 0/2 [00:00<?, ?it/s][A
Optimising conformer:  50%|███████████▌           | 1/2 [00:00<00:00,  2.59it/s][A
Optimising conformer: 100%|███████████████████████| 2/2 [00:00<00:00,  2.43it/s][AOptimising conformer: 100%|███████████████████████| 2/2 [00:00<00:00,  2.45it/s]
Optimising conformer:  83%|█████████████████▌   | 10/12 [00:45<00:15,  7.59s/it]Optimising conformer:  92%|███████████████████▎ | 11/12 [00:47<00:05,  5.94s/it]Optimising conformer: 100%|█████████████████████| 12/12 [00:50<00:00,  5.14s/it]Optimising conformer: 100%|█████████████████████| 12/12 [00:50<00:00,  4.24s/it]
2024-01-19 07:42:07,114 - distributed.worker - ERROR - Worker stream died during communication: tcp://10.3.89.95:35361
Traceback (most recent call last):
  File "/mnt/storage/nobackup/nmb1063/mamba/envs/fegrow/lib/python3.9/site-packages/distributed/comm/tcp.py", line 225, in read
    frames_nbytes = await stream.read_bytes(fmt_size)
asyncio.exceptions.CancelledError

During handling of the above exception, another exception occurred:

Traceback (most recent call last):
  File "/mnt/storage/nobackup/nmb1063/mamba/envs/fegrow/lib/python3.9/asyncio/tasks.py", line 490, in wait_for
    return fut.result()
asyncio.exceptions.CancelledError

The above exception was the direct cause of the following exception:

Traceback (most recent call last):
  File "/mnt/storage/nobackup/nmb1063/mamba/envs/fegrow/lib/python3.9/site-packages/distributed/comm/core.py", line 328, in connect
    handshake = await asyncio.wait_for(comm.read(), time_left())
  File "/mnt/storage/nobackup/nmb1063/mamba/envs/fegrow/lib/python3.9/asyncio/tasks.py", line 492, in wait_for
    raise exceptions.TimeoutError() from exc
asyncio.exceptions.TimeoutError

The above exception was the direct cause of the following exception:

Traceback (most recent call last):
  File "/mnt/storage/nobackup/nmb1063/mamba/envs/fegrow/lib/python3.9/site-packages/distributed/worker.py", line 2081, in gather_dep
    response = await get_data_from_worker(
  File "/mnt/storage/nobackup/nmb1063/mamba/envs/fegrow/lib/python3.9/site-packages/distributed/worker.py", line 2900, in get_data_from_worker
    comm = await rpc.connect(worker)
  File "/mnt/storage/nobackup/nmb1063/mamba/envs/fegrow/lib/python3.9/site-packages/distributed/core.py", line 1468, in connect
    return await connect_attempt
  File "/mnt/storage/nobackup/nmb1063/mamba/envs/fegrow/lib/python3.9/site-packages/distributed/core.py", line 1389, in _connect
    comm = await connect(
  File "/mnt/storage/nobackup/nmb1063/mamba/envs/fegrow/lib/python3.9/site-packages/distributed/comm/core.py", line 333, in connect
    raise OSError(
OSError: Timed out during handshake while connecting to tcp://10.3.89.95:35361 after 30 s
2024-01-19 07:42:07,146 - distributed.worker - ERROR - Worker stream died during communication: tcp://10.3.89.95:33957
Traceback (most recent call last):
  File "/mnt/storage/nobackup/nmb1063/mamba/envs/fegrow/lib/python3.9/site-packages/distributed/comm/tcp.py", line 225, in read
    frames_nbytes = await stream.read_bytes(fmt_size)
asyncio.exceptions.CancelledError

During handling of the above exception, another exception occurred:

Traceback (most recent call last):
  File "/mnt/storage/nobackup/nmb1063/mamba/envs/fegrow/lib/python3.9/asyncio/tasks.py", line 490, in wait_for
    return fut.result()
asyncio.exceptions.CancelledError

The above exception was the direct cause of the following exception:

Traceback (most recent call last):
  File "/mnt/storage/nobackup/nmb1063/mamba/envs/fegrow/lib/python3.9/site-packages/distributed/comm/core.py", line 328, in connect
    handshake = await asyncio.wait_for(comm.read(), time_left())
  File "/mnt/storage/nobackup/nmb1063/mamba/envs/fegrow/lib/python3.9/asyncio/tasks.py", line 492, in wait_for
    raise exceptions.TimeoutError() from exc
asyncio.exceptions.TimeoutError

The above exception was the direct cause of the following exception:

Traceback (most recent call last):
  File "/mnt/storage/nobackup/nmb1063/mamba/envs/fegrow/lib/python3.9/site-packages/distributed/worker.py", line 2081, in gather_dep
    response = await get_data_from_worker(
  File "/mnt/storage/nobackup/nmb1063/mamba/envs/fegrow/lib/python3.9/site-packages/distributed/worker.py", line 2900, in get_data_from_worker
    comm = await rpc.connect(worker)
  File "/mnt/storage/nobackup/nmb1063/mamba/envs/fegrow/lib/python3.9/site-packages/distributed/core.py", line 1468, in connect
    return await connect_attempt
  File "/mnt/storage/nobackup/nmb1063/mamba/envs/fegrow/lib/python3.9/site-packages/distributed/core.py", line 1389, in _connect
    comm = await connect(
  File "/mnt/storage/nobackup/nmb1063/mamba/envs/fegrow/lib/python3.9/site-packages/distributed/comm/core.py", line 333, in connect
    raise OSError(
OSError: Timed out during handshake while connecting to tcp://10.3.89.95:33957 after 30 s
/mnt/storage/nobackup/nmb1063/mamba/envs/fegrow/lib/python3.9/site-packages/parmed/structure.py:1775: UnitStrippedWarning: The unit of the quantity is stripped when downcasting to ndarray.
  coords = np.array(value, dtype=np.float64, copy=False, subok=True)
/mnt/storage/nobackup/nmb1063/mamba/envs/fegrow/lib/python3.9/site-packages/parmed/structure.py:1775: UnitStrippedWarning: The unit of the quantity is stripped when downcasting to ndarray.
  coords = np.array(value, dtype=np.float64, copy=False, subok=True)
TIME Completed the molecule generation in 83.2s.
TIME Completed the molecule generation in 116.8s.
TIME changed dir: 0.0s
TIME changed dir: 0.0s
Generated 8 conformers. 
Removed 5 conformers. 
Generated 17 conformers. 
Removed 10 conformers. 
using ani2x
/mnt/storage/nobackup/nmb1063/mamba/envs/fegrow/lib/python3.9/site-packages/torchani/resources/
failed to equip `nnpops` with error: No module named 'NNPOps'
using ani2x
/mnt/storage/nobackup/nmb1063/mamba/envs/fegrow/lib/python3.9/site-packages/torchani/resources/
Optimising conformer:   0%|                               | 0/3 [00:00<?, ?it/s]Optimising conformer:  33%|███████▋               | 1/3 [00:03<00:06,  3.24s/it]failed to equip `nnpops` with error: No module named 'NNPOps'

Optimising conformer:   0%|                               | 0/7 [00:00<?, ?it/s][AOptimising conformer:  67%|███████████████▎       | 2/3 [00:05<00:02,  2.42s/it]Optimising conformer: 100%|███████████████████████| 3/3 [00:07<00:00,  2.40s/it]Optimising conformer: 100%|███████████████████████| 3/3 [00:07<00:00,  2.49s/it]

Optimising conformer:  14%|███▎                   | 1/7 [00:05<00:31,  5.20s/it][A
Optimising conformer:  29%|██████▌                | 2/7 [00:07<00:18,  3.66s/it][A
Optimising conformer:  43%|█████████▊             | 3/7 [00:11<00:14,  3.73s/it][A
Optimising conformer:  57%|█████████████▏         | 4/7 [00:15<00:11,  3.68s/it][A
Optimising conformer:  71%|████████████████▍      | 5/7 [00:18<00:07,  3.65s/it][A
Optimising conformer:  86%|███████████████████▋   | 6/7 [00:21<00:03,  3.50s/it][A
Optimising conformer: 100%|███████████████████████| 7/7 [00:25<00:00,  3.36s/it][AOptimising conformer: 100%|███████████████████████| 7/7 [00:25<00:00,  3.58s/it]
2024-01-19 08:03:39,336 - distributed.worker - ERROR - Worker stream died during communication: tcp://10.3.89.124:40469
Traceback (most recent call last):
  File "/mnt/storage/nobackup/nmb1063/mamba/envs/fegrow/lib/python3.9/site-packages/distributed/comm/tcp.py", line 225, in read
    frames_nbytes = await stream.read_bytes(fmt_size)
asyncio.exceptions.CancelledError

During handling of the above exception, another exception occurred:

Traceback (most recent call last):
  File "/mnt/storage/nobackup/nmb1063/mamba/envs/fegrow/lib/python3.9/asyncio/tasks.py", line 490, in wait_for
    return fut.result()
asyncio.exceptions.CancelledError

The above exception was the direct cause of the following exception:

Traceback (most recent call last):
  File "/mnt/storage/nobackup/nmb1063/mamba/envs/fegrow/lib/python3.9/site-packages/distributed/comm/core.py", line 328, in connect
    handshake = await asyncio.wait_for(comm.read(), time_left())
  File "/mnt/storage/nobackup/nmb1063/mamba/envs/fegrow/lib/python3.9/asyncio/tasks.py", line 492, in wait_for
    raise exceptions.TimeoutError() from exc
asyncio.exceptions.TimeoutError

The above exception was the direct cause of the following exception:

Traceback (most recent call last):
  File "/mnt/storage/nobackup/nmb1063/mamba/envs/fegrow/lib/python3.9/site-packages/distributed/worker.py", line 2081, in gather_dep
    response = await get_data_from_worker(
  File "/mnt/storage/nobackup/nmb1063/mamba/envs/fegrow/lib/python3.9/site-packages/distributed/worker.py", line 2900, in get_data_from_worker
    comm = await rpc.connect(worker)
  File "/mnt/storage/nobackup/nmb1063/mamba/envs/fegrow/lib/python3.9/site-packages/distributed/core.py", line 1468, in connect
    return await connect_attempt
  File "/mnt/storage/nobackup/nmb1063/mamba/envs/fegrow/lib/python3.9/site-packages/distributed/core.py", line 1389, in _connect
    comm = await connect(
  File "/mnt/storage/nobackup/nmb1063/mamba/envs/fegrow/lib/python3.9/site-packages/distributed/comm/core.py", line 333, in connect
    raise OSError(
OSError: Timed out during handshake while connecting to tcp://10.3.89.124:40469 after 30 s
2024-01-19 08:03:39,345 - distributed.worker - ERROR - Worker stream died during communication: tcp://10.3.89.124:44379
Traceback (most recent call last):
  File "/mnt/storage/nobackup/nmb1063/mamba/envs/fegrow/lib/python3.9/site-packages/distributed/comm/tcp.py", line 225, in read
    frames_nbytes = await stream.read_bytes(fmt_size)
asyncio.exceptions.CancelledError

During handling of the above exception, another exception occurred:

Traceback (most recent call last):
  File "/mnt/storage/nobackup/nmb1063/mamba/envs/fegrow/lib/python3.9/asyncio/tasks.py", line 490, in wait_for
    return fut.result()
asyncio.exceptions.CancelledError

The above exception was the direct cause of the following exception:

Traceback (most recent call last):
  File "/mnt/storage/nobackup/nmb1063/mamba/envs/fegrow/lib/python3.9/site-packages/distributed/comm/core.py", line 328, in connect
    handshake = await asyncio.wait_for(comm.read(), time_left())
  File "/mnt/storage/nobackup/nmb1063/mamba/envs/fegrow/lib/python3.9/asyncio/tasks.py", line 492, in wait_for
    raise exceptions.TimeoutError() from exc
asyncio.exceptions.TimeoutError

The above exception was the direct cause of the following exception:

Traceback (most recent call last):
  File "/mnt/storage/nobackup/nmb1063/mamba/envs/fegrow/lib/python3.9/site-packages/distributed/worker.py", line 2081, in gather_dep
    response = await get_data_from_worker(
  File "/mnt/storage/nobackup/nmb1063/mamba/envs/fegrow/lib/python3.9/site-packages/distributed/worker.py", line 2900, in get_data_from_worker
    comm = await rpc.connect(worker)
  File "/mnt/storage/nobackup/nmb1063/mamba/envs/fegrow/lib/python3.9/site-packages/distributed/core.py", line 1468, in connect
    return await connect_attempt
  File "/mnt/storage/nobackup/nmb1063/mamba/envs/fegrow/lib/python3.9/site-packages/distributed/core.py", line 1389, in _connect
    comm = await connect(
  File "/mnt/storage/nobackup/nmb1063/mamba/envs/fegrow/lib/python3.9/site-packages/distributed/comm/core.py", line 333, in connect
    raise OSError(
OSError: Timed out during handshake while connecting to tcp://10.3.89.124:44379 after 30 s
/mnt/storage/nobackup/nmb1063/mamba/envs/fegrow/lib/python3.9/site-packages/parmed/structure.py:1775: UnitStrippedWarning: The unit of the quantity is stripped when downcasting to ndarray.
  coords = np.array(value, dtype=np.float64, copy=False, subok=True)
/mnt/storage/nobackup/nmb1063/mamba/envs/fegrow/lib/python3.9/site-packages/parmed/structure.py:1775: UnitStrippedWarning: The unit of the quantity is stripped when downcasting to ndarray.
  coords = np.array(value, dtype=np.float64, copy=False, subok=True)
TIME Completed the molecule generation in 76.9s.
TIME Completed the molecule generation in 109.5s.
TIME changed dir: 0.0s
TIME changed dir: 0.0s
Generated 6 conformers. 
Removed 2 conformers. 
Generated 44 conformers. 
Removed 40 conformers. 
using ani2x
/mnt/storage/nobackup/nmb1063/mamba/envs/fegrow/lib/python3.9/site-packages/torchani/resources/
failed to equip `nnpops` with error: No module named 'NNPOps'
Optimising conformer:   0%|                               | 0/4 [00:00<?, ?it/s]Optimising conformer:  25%|█████▊                 | 1/4 [00:04<00:12,  4.30s/it]Optimising conformer:  50%|███████████▌           | 2/4 [00:09<00:09,  4.59s/it]Optimising conformer:  75%|█████████████████▎     | 3/4 [00:12<00:03,  3.91s/it]Optimising conformer: 100%|███████████████████████| 4/4 [00:15<00:00,  3.70s/it]Optimising conformer: 100%|███████████████████████| 4/4 [00:15<00:00,  3.89s/it]
TIME Completed the molecule generation in 50.9s.
using ani2x
/mnt/storage/nobackup/nmb1063/mamba/envs/fegrow/lib/python3.9/site-packages/torchani/resources/
failed to equip `nnpops` with error: No module named 'NNPOps'
Optimising conformer:   0%|                               | 0/4 [00:00<?, ?it/s]Optimising conformer:  25%|█████▊                 | 1/4 [00:03<00:10,  3.38s/it]Optimising conformer:  50%|███████████▌           | 2/4 [00:05<00:05,  2.92s/it]Optimising conformer:  75%|█████████████████▎     | 3/4 [00:08<00:02,  2.59s/it]Optimising conformer: 100%|███████████████████████| 4/4 [00:11<00:00,  2.72s/it]Optimising conformer: 100%|███████████████████████| 4/4 [00:11<00:00,  2.78s/it]
2024-01-19 09:24:31,380 - distributed.worker - ERROR - Failed to communicate with scheduler during heartbeat.
Traceback (most recent call last):
  File "/mnt/storage/nobackup/nmb1063/mamba/envs/fegrow/lib/python3.9/site-packages/tornado/iostream.py", line 861, in _read_to_buffer
    bytes_read = self.read_from_fd(buf)
  File "/mnt/storage/nobackup/nmb1063/mamba/envs/fegrow/lib/python3.9/site-packages/tornado/iostream.py", line 1116, in read_from_fd
    return self.socket.recv_into(buf, len(buf))
TimeoutError: [Errno 110] Connection timed out

The above exception was the direct cause of the following exception:

Traceback (most recent call last):
  File "/mnt/storage/nobackup/nmb1063/mamba/envs/fegrow/lib/python3.9/site-packages/distributed/worker.py", line 1237, in heartbeat
    response = await retry_operation(
  File "/mnt/storage/nobackup/nmb1063/mamba/envs/fegrow/lib/python3.9/site-packages/distributed/utils_comm.py", line 434, in retry_operation
    return await retry(
  File "/mnt/storage/nobackup/nmb1063/mamba/envs/fegrow/lib/python3.9/site-packages/distributed/utils_comm.py", line 413, in retry
    return await coro()
  File "/mnt/storage/nobackup/nmb1063/mamba/envs/fegrow/lib/python3.9/site-packages/distributed/core.py", line 1227, in send_recv_from_rpc
    return await send_recv(comm=comm, op=key, **kwargs)
  File "/mnt/storage/nobackup/nmb1063/mamba/envs/fegrow/lib/python3.9/site-packages/distributed/core.py", line 986, in send_recv
    response = await comm.read(deserializers=deserializers)
  File "/mnt/storage/nobackup/nmb1063/mamba/envs/fegrow/lib/python3.9/site-packages/distributed/comm/tcp.py", line 241, in read
    convert_stream_closed_error(self, e)
  File "/mnt/storage/nobackup/nmb1063/mamba/envs/fegrow/lib/python3.9/site-packages/distributed/comm/tcp.py", line 142, in convert_stream_closed_error
    raise CommClosedError(f"in {obj}: {exc.__class__.__name__}: {exc}") from exc
distributed.comm.core.CommClosedError: in <TCP (closed) ConnectionPool.heartbeat_worker local=tcp://10.3.89.176:48512 remote=tcp://10.3.88.12:42763>: TimeoutError: [Errno 110] Connection timed out
2024-01-19 09:24:31,443 - distributed.worker - ERROR - Failed to communicate with scheduler during heartbeat.
Traceback (most recent call last):
  File "/mnt/storage/nobackup/nmb1063/mamba/envs/fegrow/lib/python3.9/site-packages/tornado/iostream.py", line 861, in _read_to_buffer
    bytes_read = self.read_from_fd(buf)
  File "/mnt/storage/nobackup/nmb1063/mamba/envs/fegrow/lib/python3.9/site-packages/tornado/iostream.py", line 1116, in read_from_fd
    return self.socket.recv_into(buf, len(buf))
TimeoutError: [Errno 110] Connection timed out

The above exception was the direct cause of the following exception:

Traceback (most recent call last):
  File "/mnt/storage/nobackup/nmb1063/mamba/envs/fegrow/lib/python3.9/site-packages/distributed/worker.py", line 1237, in heartbeat
    response = await retry_operation(
  File "/mnt/storage/nobackup/nmb1063/mamba/envs/fegrow/lib/python3.9/site-packages/distributed/utils_comm.py", line 434, in retry_operation
    return await retry(
  File "/mnt/storage/nobackup/nmb1063/mamba/envs/fegrow/lib/python3.9/site-packages/distributed/utils_comm.py", line 413, in retry
    return await coro()
  File "/mnt/storage/nobackup/nmb1063/mamba/envs/fegrow/lib/python3.9/site-packages/distributed/core.py", line 1227, in send_recv_from_rpc
    return await send_recv(comm=comm, op=key, **kwargs)
  File "/mnt/storage/nobackup/nmb1063/mamba/envs/fegrow/lib/python3.9/site-packages/distributed/core.py", line 986, in send_recv
    response = await comm.read(deserializers=deserializers)
  File "/mnt/storage/nobackup/nmb1063/mamba/envs/fegrow/lib/python3.9/site-packages/distributed/comm/tcp.py", line 241, in read
    convert_stream_closed_error(self, e)
  File "/mnt/storage/nobackup/nmb1063/mamba/envs/fegrow/lib/python3.9/site-packages/distributed/comm/tcp.py", line 142, in convert_stream_closed_error
    raise CommClosedError(f"in {obj}: {exc.__class__.__name__}: {exc}") from exc
distributed.comm.core.CommClosedError: in <TCP (closed) ConnectionPool.heartbeat_worker local=tcp://10.3.89.176:48514 remote=tcp://10.3.88.12:42763>: TimeoutError: [Errno 110] Connection timed out
2024-01-19 09:24:39,827 - distributed.core - INFO - Connection to tcp://10.3.88.12:42763 has been closed.
2024-01-19 09:24:39,827 - distributed.core - INFO - Connection to tcp://10.3.88.12:42763 has been closed.
2024-01-19 09:24:39,829 - distributed.worker - INFO - Stopping worker at tcp://10.3.89.176:38728. Reason: worker-handle-scheduler-connection-broken
2024-01-19 09:24:39,829 - distributed.worker - INFO - Stopping worker at tcp://10.3.89.176:41159. Reason: worker-handle-scheduler-connection-broken
2024-01-19 09:24:39,842 - distributed.nanny - INFO - Closing Nanny gracefully at 'tcp://10.3.89.176:45582'. Reason: worker-handle-scheduler-connection-broken
2024-01-19 09:24:39,844 - distributed.nanny - INFO - Closing Nanny gracefully at 'tcp://10.3.89.176:43557'. Reason: worker-handle-scheduler-connection-broken
2024-01-19 09:24:39,863 - distributed.worker - ERROR - Failed to communicate with scheduler during heartbeat.
Traceback (most recent call last):
  File "/mnt/storage/nobackup/nmb1063/mamba/envs/fegrow/lib/python3.9/site-packages/distributed/core.py", line 1389, in _connect
    comm = await connect(
  File "/mnt/storage/nobackup/nmb1063/mamba/envs/fegrow/lib/python3.9/site-packages/distributed/comm/core.py", line 291, in connect
    comm = await asyncio.wait_for(
  File "/mnt/storage/nobackup/nmb1063/mamba/envs/fegrow/lib/python3.9/asyncio/tasks.py", line 466, in wait_for
    await waiter
asyncio.exceptions.CancelledError

During handling of the above exception, another exception occurred:

Traceback (most recent call last):
  File "/mnt/storage/nobackup/nmb1063/mamba/envs/fegrow/lib/python3.9/site-packages/distributed/worker.py", line 1237, in heartbeat
    response = await retry_operation(
  File "/mnt/storage/nobackup/nmb1063/mamba/envs/fegrow/lib/python3.9/site-packages/distributed/utils_comm.py", line 434, in retry_operation
    return await retry(
  File "/mnt/storage/nobackup/nmb1063/mamba/envs/fegrow/lib/python3.9/site-packages/distributed/utils_comm.py", line 413, in retry
    return await coro()
  File "/mnt/storage/nobackup/nmb1063/mamba/envs/fegrow/lib/python3.9/site-packages/distributed/core.py", line 1224, in send_recv_from_rpc
    comm = await self.pool.connect(self.addr)
  File "/mnt/storage/nobackup/nmb1063/mamba/envs/fegrow/lib/python3.9/site-packages/distributed/core.py", line 1468, in connect
    return await connect_attempt
  File "/mnt/storage/nobackup/nmb1063/mamba/envs/fegrow/lib/python3.9/site-packages/distributed/core.py", line 1412, in _connect
    raise CommClosedError(reason)
distributed.comm.core.CommClosedError: ConnectionPool closing.
2024-01-19 09:24:39,869 - distributed.nanny - INFO - Worker closed
2024-01-19 09:24:39,858 - distributed.worker - ERROR - Failed to communicate with scheduler during heartbeat.
Traceback (most recent call last):
  File "/mnt/storage/nobackup/nmb1063/mamba/envs/fegrow/lib/python3.9/site-packages/distributed/core.py", line 1389, in _connect
    comm = await connect(
  File "/mnt/storage/nobackup/nmb1063/mamba/envs/fegrow/lib/python3.9/site-packages/distributed/comm/core.py", line 291, in connect
    comm = await asyncio.wait_for(
  File "/mnt/storage/nobackup/nmb1063/mamba/envs/fegrow/lib/python3.9/asyncio/tasks.py", line 466, in wait_for
    await waiter
asyncio.exceptions.CancelledError

During handling of the above exception, another exception occurred:

Traceback (most recent call last):
  File "/mnt/storage/nobackup/nmb1063/mamba/envs/fegrow/lib/python3.9/site-packages/distributed/worker.py", line 1237, in heartbeat
    response = await retry_operation(
  File "/mnt/storage/nobackup/nmb1063/mamba/envs/fegrow/lib/python3.9/site-packages/distributed/utils_comm.py", line 434, in retry_operation
    return await retry(
  File "/mnt/storage/nobackup/nmb1063/mamba/envs/fegrow/lib/python3.9/site-packages/distributed/utils_comm.py", line 413, in retry
    return await coro()
  File "/mnt/storage/nobackup/nmb1063/mamba/envs/fegrow/lib/python3.9/site-packages/distributed/core.py", line 1224, in send_recv_from_rpc
    comm = await self.pool.connect(self.addr)
  File "/mnt/storage/nobackup/nmb1063/mamba/envs/fegrow/lib/python3.9/site-packages/distributed/core.py", line 1468, in connect
    return await connect_attempt
  File "/mnt/storage/nobackup/nmb1063/mamba/envs/fegrow/lib/python3.9/site-packages/distributed/core.py", line 1412, in _connect
    raise CommClosedError(reason)
distributed.comm.core.CommClosedError: ConnectionPool closing.
2024-01-19 09:24:39,876 - distributed.nanny - INFO - Worker closed
2024-01-19 09:24:41,885 - distributed.nanny - ERROR - Worker process died unexpectedly
TIME Completed the molecule generation in 107.6s.
2024-01-19 09:24:42,818 - distributed.nanny - INFO - Closing Nanny at 'tcp://10.3.89.176:43557'. Reason: nanny-close-gracefully
2024-01-19 09:24:45,261 - distributed.nanny - INFO - Closing Nanny at 'tcp://10.3.89.176:45582'. Reason: nanny-close-gracefully
2024-01-19 09:24:45,264 - distributed.dask_worker - INFO - End worker
